2017-12-24 00:46:51 WARNING (MainThread) [homeassistant.setup] Setup of sensor is taking over 10 seconds.
2017-12-24 00:46:52 WARNING (MainThread) [homeassistant.setup] Setup of camera is taking over 10 seconds.
2017-12-24 00:46:52 WARNING (MainThread) [homeassistant.setup] Setup of media_player is taking over 10 seconds.
2017-12-24 00:46:54 WARNING (MainThread) [homeassistant.setup] Setup of light is taking over 10 seconds.
2017-12-24 00:46:54 WARNING (MainThread) [homeassistant.setup] Setup of switch is taking over 10 seconds.
2017-12-24 00:47:02 WARNING (MainThread) [homeassistant.setup] Setup of tts is taking over 10 seconds.
2017-12-24 00:47:09 WARNING (MainThread) [homeassistant.components.media_player] Setup of platform cast is taking over 10 seconds.
2017-12-24 00:47:20 WARNING (MainThread) [homeassistant.components.switch] Setup of platform broadlink is taking over 10 seconds.
2017-12-24 00:48:10 ERROR (MainThread) [homeassistant.components.switch] Setup of platform broadlink is taking longer than 60 seconds. Startup will proceed without waiting any longer.
2017-12-24 00:48:10 ERROR (SyncWorker_12) [homeassistant.components.switch.broadlink] Failed to connect to device
2017-12-24 00:49:24 WARNING (MainThread) [haffmpeg.tools] Timeout reading image.
2017-12-24 00:49:29 WARNING (MainThread) [haffmpeg.tools] Timeout reading image.
2017-12-24 00:49:39 WARNING (MainThread) [haffmpeg.tools] Timeout reading image.
2017-12-24 00:49:49 WARNING (MainThread) [haffmpeg.tools] Timeout reading image.
2017-12-24 00:49:59 WARNING (MainThread) [haffmpeg.tools] Timeout reading image.
2017-12-24 00:50:09 WARNING (MainThread) [haffmpeg.tools] Timeout reading image.
2017-12-24 00:50:19 WARNING (MainThread) [haffmpeg.tools] Timeout reading image.
2017-12-24 00:50:29 WARNING (MainThread) [haffmpeg.tools] Timeout reading image.
2017-12-24 00:50:39 WARNING (MainThread) [haffmpeg.tools] Timeout reading image.
2017-12-24 00:50:49 WARNING (MainThread) [haffmpeg.tools] Timeout reading image.
2017-12-24 00:50:50 ERROR (MainThread) [homeassistant.helpers.entity] Update for media_player.spotify fails
Traceback (most recent call last):
  File "/usr/lib/python3.6/site-packages/urllib3/connection.py", line 141, in _new_conn
    (self.host, self.port), self.timeout, **extra_kw)
  File "/usr/lib/python3.6/site-packages/urllib3/util/connection.py", line 60, in create_connection
    for res in socket.getaddrinfo(host, port, family, socket.SOCK_STREAM):
  File "/usr/lib/python3.6/socket.py", line 745, in getaddrinfo
    for res in _socket.getaddrinfo(host, port, family, type, proto, flags):
socket.gaierror: [Errno -3] Try again

During handling of the above exception, another exception occurred:

Traceback (most recent call last):
  File "/usr/lib/python3.6/site-packages/urllib3/connectionpool.py", line 601, in urlopen
    chunked=chunked)
  File "/usr/lib/python3.6/site-packages/urllib3/connectionpool.py", line 346, in _make_request
    self._validate_conn(conn)
  File "/usr/lib/python3.6/site-packages/urllib3/connectionpool.py", line 850, in _validate_conn
    conn.connect()
  File "/usr/lib/python3.6/site-packages/urllib3/connection.py", line 284, in connect
    conn = self._new_conn()
  File "/usr/lib/python3.6/site-packages/urllib3/connection.py", line 150, in _new_conn
    self, "Failed to establish a new connection: %s" % e)
urllib3.exceptions.NewConnectionError: <urllib3.connection.VerifiedHTTPSConnection object at 0x72b65590>: Failed to establish a new connection: [Errno -3] Try again

During handling of the above exception, another exception occurred:

Traceback (most recent call last):
  File "/usr/lib/python3.6/site-packages/requests/adapters.py", line 440, in send
    timeout=timeout
  File "/usr/lib/python3.6/site-packages/urllib3/connectionpool.py", line 639, in urlopen
    _stacktrace=sys.exc_info()[2])
  File "/usr/lib/python3.6/site-packages/urllib3/util/retry.py", line 388, in increment
    raise MaxRetryError(_pool, url, error or ResponseError(cause))
urllib3.exceptions.MaxRetryError: HTTPSConnectionPool(host='api.spotify.com', port=443): Max retries exceeded with url: /v1/me/player/devices (Caused by NewConnectionError('<urllib3.connection.VerifiedHTTPSConnection object at 0x72b65590>: Failed to establish a new connection: [Errno -3] Try again',))

During handling of the above exception, another exception occurred:

Traceback (most recent call last):
  File "/usr/lib/python3.6/site-packages/homeassistant/helpers/entity.py", line 199, in async_update_ha_state
    yield from self.async_device_update()
  File "/usr/lib/python3.6/site-packages/homeassistant/helpers/entity.py", line 306, in async_device_update
    yield from self.hass.async_add_job(self.update)
  File "/usr/lib/python3.6/asyncio/futures.py", line 332, in __iter__
    yield self  # This tells Task to wait for completion.
  File "/usr/lib/python3.6/asyncio/tasks.py", line 250, in _wakeup
    future.result()
  File "/usr/lib/python3.6/asyncio/futures.py", line 245, in result
    raise self._exception
  File "/usr/lib/python3.6/concurrent/futures/thread.py", line 56, in run
    result = self.fn(*self.args, **self.kwargs)
  File "/usr/lib/python3.6/site-packages/homeassistant/components/media_player/spotify.py", line 172, in update
    player_devices = self._player.devices()
  File "/usr/lib/python3.6/site-packages/spotipy/client.py", line 848, in devices
    return self._get("me/player/devices")
  File "/usr/lib/python3.6/site-packages/spotipy/client.py", line 148, in _get
    return self._internal_call('GET', url, payload, kwargs)
  File "/usr/lib/python3.6/site-packages/spotipy/client.py", line 110, in _internal_call
    r = self._session.request(method, url, headers=headers, proxies=self.proxies, **args)
  File "/usr/lib/python3.6/site-packages/requests/sessions.py", line 508, in request
    resp = self.send(prep, **send_kwargs)
  File "/usr/lib/python3.6/site-packages/requests/sessions.py", line 618, in send
    r = adapter.send(request, **kwargs)
  File "/usr/lib/python3.6/site-packages/requests/adapters.py", line 508, in send
    raise ConnectionError(e, request=request)
requests.exceptions.ConnectionError: HTTPSConnectionPool(host='api.spotify.com', port=443): Max retries exceeded with url: /v1/me/player/devices (Caused by NewConnectionError('<urllib3.connection.VerifiedHTTPSConnection object at 0x72b65590>: Failed to establish a new connection: [Errno -3] Try again',))
2017-12-24 00:50:59 WARNING (MainThread) [haffmpeg.tools] Timeout reading image.
2017-12-24 00:51:09 WARNING (MainThread) [haffmpeg.tools] Timeout reading image.
2017-12-24 00:51:19 WARNING (MainThread) [haffmpeg.tools] Timeout reading image.
2017-12-24 00:51:39 WARNING (MainThread) [haffmpeg.tools] Timeout reading image.
2017-12-24 00:51:59 WARNING (MainThread) [haffmpeg.tools] Timeout reading image.
2017-12-24 00:52:09 WARNING (MainThread) [haffmpeg.tools] Timeout reading image.
2017-12-24 00:52:19 WARNING (MainThread) [haffmpeg.tools] Timeout reading image.
2017-12-24 00:52:29 WARNING (MainThread) [haffmpeg.tools] Timeout reading image.
2017-12-24 00:52:39 WARNING (MainThread) [haffmpeg.tools] Timeout reading image.
2017-12-24 00:52:48 WARNING (MainThread) [haffmpeg.tools] Timeout reading image.
2017-12-24 00:52:49 WARNING (MainThread) [haffmpeg.tools] Timeout reading image.
2017-12-24 00:52:54 ERROR (MainThread) [homeassistant.helpers.entity] Update for media_player.spotify fails
Traceback (most recent call last):
  File "/usr/lib/python3.6/site-packages/urllib3/connection.py", line 141, in _new_conn
    (self.host, self.port), self.timeout, **extra_kw)
  File "/usr/lib/python3.6/site-packages/urllib3/util/connection.py", line 60, in create_connection
    for res in socket.getaddrinfo(host, port, family, socket.SOCK_STREAM):
  File "/usr/lib/python3.6/socket.py", line 745, in getaddrinfo
    for res in _socket.getaddrinfo(host, port, family, type, proto, flags):
socket.gaierror: [Errno -3] Try again

During handling of the above exception, another exception occurred:

Traceback (most recent call last):
  File "/usr/lib/python3.6/site-packages/urllib3/connectionpool.py", line 601, in urlopen
    chunked=chunked)
  File "/usr/lib/python3.6/site-packages/urllib3/connectionpool.py", line 346, in _make_request
    self._validate_conn(conn)
  File "/usr/lib/python3.6/site-packages/urllib3/connectionpool.py", line 850, in _validate_conn
    conn.connect()
  File "/usr/lib/python3.6/site-packages/urllib3/connection.py", line 284, in connect
    conn = self._new_conn()
  File "/usr/lib/python3.6/site-packages/urllib3/connection.py", line 150, in _new_conn
    self, "Failed to establish a new connection: %s" % e)
urllib3.exceptions.NewConnectionError: <urllib3.connection.VerifiedHTTPSConnection object at 0x6f0b2cf0>: Failed to establish a new connection: [Errno -3] Try again

During handling of the above exception, another exception occurred:

Traceback (most recent call last):
  File "/usr/lib/python3.6/site-packages/requests/adapters.py", line 440, in send
    timeout=timeout
  File "/usr/lib/python3.6/site-packages/urllib3/connectionpool.py", line 639, in urlopen
    _stacktrace=sys.exc_info()[2])
  File "/usr/lib/python3.6/site-packages/urllib3/util/retry.py", line 388, in increment
    raise MaxRetryError(_pool, url, error or ResponseError(cause))
urllib3.exceptions.MaxRetryError: HTTPSConnectionPool(host='api.spotify.com', port=443): Max retries exceeded with url: /v1/me/player/devices (Caused by NewConnectionError('<urllib3.connection.VerifiedHTTPSConnection object at 0x6f0b2cf0>: Failed to establish a new connection: [Errno -3] Try again',))

During handling of the above exception, another exception occurred:

Traceback (most recent call last):
  File "/usr/lib/python3.6/site-packages/homeassistant/helpers/entity.py", line 199, in async_update_ha_state
    yield from self.async_device_update()
  File "/usr/lib/python3.6/site-packages/homeassistant/helpers/entity.py", line 306, in async_device_update
    yield from self.hass.async_add_job(self.update)
  File "/usr/lib/python3.6/asyncio/futures.py", line 332, in __iter__
    yield self  # This tells Task to wait for completion.
  File "/usr/lib/python3.6/asyncio/tasks.py", line 250, in _wakeup
    future.result()
  File "/usr/lib/python3.6/asyncio/futures.py", line 245, in result
    raise self._exception
  File "/usr/lib/python3.6/concurrent/futures/thread.py", line 56, in run
    result = self.fn(*self.args, **self.kwargs)
  File "/usr/lib/python3.6/site-packages/homeassistant/components/media_player/spotify.py", line 172, in update
    player_devices = self._player.devices()
  File "/usr/lib/python3.6/site-packages/spotipy/client.py", line 848, in devices
    return self._get("me/player/devices")
  File "/usr/lib/python3.6/site-packages/spotipy/client.py", line 148, in _get
    return self._internal_call('GET', url, payload, kwargs)
  File "/usr/lib/python3.6/site-packages/spotipy/client.py", line 110, in _internal_call
    r = self._session.request(method, url, headers=headers, proxies=self.proxies, **args)
  File "/usr/lib/python3.6/site-packages/requests/sessions.py", line 508, in request
    resp = self.send(prep, **send_kwargs)
  File "/usr/lib/python3.6/site-packages/requests/sessions.py", line 618, in send
    r = adapter.send(request, **kwargs)
  File "/usr/lib/python3.6/site-packages/requests/adapters.py", line 508, in send
    raise ConnectionError(e, request=request)
requests.exceptions.ConnectionError: HTTPSConnectionPool(host='api.spotify.com', port=443): Max retries exceeded with url: /v1/me/player/devices (Caused by NewConnectionError('<urllib3.connection.VerifiedHTTPSConnection object at 0x6f0b2cf0>: Failed to establish a new connection: [Errno -3] Try again',))
2017-12-24 00:52:59 WARNING (MainThread) [haffmpeg.tools] Timeout reading image.
2017-12-24 00:53:09 WARNING (MainThread) [haffmpeg.tools] Timeout reading image.
2017-12-24 00:53:19 WARNING (MainThread) [haffmpeg.tools] Timeout reading image.
2017-12-24 00:53:29 WARNING (MainThread) [haffmpeg.tools] Timeout reading image.
2017-12-24 00:53:40 WARNING (MainThread) [haffmpeg.tools] Timeout reading image.
2017-12-24 00:53:49 WARNING (MainThread) [haffmpeg.tools] Timeout reading image.
2017-12-24 00:53:59 WARNING (MainThread) [haffmpeg.tools] Timeout reading image.
2017-12-24 00:54:09 WARNING (MainThread) [haffmpeg.tools] Timeout reading image.
2017-12-24 00:54:19 WARNING (MainThread) [haffmpeg.tools] Timeout reading image.
2017-12-24 00:54:29 WARNING (MainThread) [haffmpeg.tools] Timeout reading image.
2017-12-24 00:54:39 WARNING (MainThread) [haffmpeg.tools] Timeout reading image.
2017-12-24 00:54:49 WARNING (MainThread) [haffmpeg.tools] Timeout reading image.
2017-12-24 00:54:59 WARNING (MainThread) [haffmpeg.tools] Timeout reading image.
2017-12-24 00:55:09 WARNING (MainThread) [haffmpeg.tools] Timeout reading image.
2017-12-24 00:55:19 WARNING (MainThread) [haffmpeg.tools] Timeout reading image.
2017-12-24 00:55:29 WARNING (MainThread) [haffmpeg.tools] Timeout reading image.
2017-12-24 00:55:39 WARNING (MainThread) [haffmpeg.tools] Timeout reading image.
2017-12-24 00:55:49 WARNING (MainThread) [haffmpeg.tools] Timeout reading image.
2017-12-24 00:55:59 WARNING (MainThread) [haffmpeg.tools] Timeout reading image.
2017-12-24 00:56:09 WARNING (MainThread) [haffmpeg.tools] Timeout reading image.
2017-12-24 00:56:19 WARNING (MainThread) [haffmpeg.tools] Timeout reading image.
2017-12-24 00:56:29 WARNING (MainThread) [haffmpeg.tools] Timeout reading image.
2017-12-24 00:56:39 WARNING (MainThread) [haffmpeg.tools] Timeout reading image.
2017-12-24 00:56:58 WARNING (MainThread) [haffmpeg.tools] Timeout reading image.
2017-12-24 00:56:59 WARNING (MainThread) [haffmpeg.tools] Timeout reading image.
2017-12-24 00:57:07 WARNING (MainThread) [haffmpeg.tools] Timeout reading image.
2017-12-24 00:57:16 WARNING (MainThread) [haffmpeg.tools] Timeout reading image.
2017-12-24 00:57:18 WARNING (MainThread) [haffmpeg.tools] Timeout reading image.
2017-12-24 00:57:24 WARNING (MainThread) [haffmpeg.tools] Timeout reading image.
2017-12-24 00:57:30 WARNING (MainThread) [haffmpeg.core] Timeout while waiting of FFmpeg
2017-12-24 00:57:37 WARNING (MainThread) [haffmpeg.tools] Timeout reading image.
2017-12-24 00:59:42 WARNING (MainThread) [homeassistant.helpers.entity] Update of media_player.spotify is taking over 10 seconds
2017-12-24 01:01:07 WARNING (SyncWorker_12) [homeassistant.components.sensor.google_wifi] Unable to fetch data from Google Wifi
2017-12-24 01:12:51 ERROR (MainThread) [homeassistant.core] Error doing job: Fatal error on transport TCPTransport (error status in uv_stream_t.read callback)
OSError: [Errno 113] Host is unreachable
2017-12-24 01:43:37 WARNING (MainThread) [homeassistant.helpers.entity] Update of media_player.spotify is taking over 10 seconds
2017-12-24 02:15:01 ERROR (MainThread) [homeassistant.helpers.entity] Update for media_player.spotify fails
Traceback (most recent call last):
  File "/usr/lib/python3.6/site-packages/urllib3/connection.py", line 141, in _new_conn
    (self.host, self.port), self.timeout, **extra_kw)
  File "/usr/lib/python3.6/site-packages/urllib3/util/connection.py", line 60, in create_connection
    for res in socket.getaddrinfo(host, port, family, socket.SOCK_STREAM):
  File "/usr/lib/python3.6/socket.py", line 745, in getaddrinfo
    for res in _socket.getaddrinfo(host, port, family, type, proto, flags):
socket.gaierror: [Errno -3] Try again

During handling of the above exception, another exception occurred:

Traceback (most recent call last):
  File "/usr/lib/python3.6/site-packages/urllib3/connectionpool.py", line 601, in urlopen
    chunked=chunked)
  File "/usr/lib/python3.6/site-packages/urllib3/connectionpool.py", line 346, in _make_request
    self._validate_conn(conn)
  File "/usr/lib/python3.6/site-packages/urllib3/connectionpool.py", line 850, in _validate_conn
    conn.connect()
  File "/usr/lib/python3.6/site-packages/urllib3/connection.py", line 284, in connect
    conn = self._new_conn()
  File "/usr/lib/python3.6/site-packages/urllib3/connection.py", line 150, in _new_conn
    self, "Failed to establish a new connection: %s" % e)
urllib3.exceptions.NewConnectionError: <urllib3.connection.VerifiedHTTPSConnection object at 0x726feb10>: Failed to establish a new connection: [Errno -3] Try again

During handling of the above exception, another exception occurred:

Traceback (most recent call last):
  File "/usr/lib/python3.6/site-packages/requests/adapters.py", line 440, in send
    timeout=timeout
  File "/usr/lib/python3.6/site-packages/urllib3/connectionpool.py", line 639, in urlopen
    _stacktrace=sys.exc_info()[2])
  File "/usr/lib/python3.6/site-packages/urllib3/util/retry.py", line 388, in increment
    raise MaxRetryError(_pool, url, error or ResponseError(cause))
urllib3.exceptions.MaxRetryError: HTTPSConnectionPool(host='api.spotify.com', port=443): Max retries exceeded with url: /v1/me/player/devices (Caused by NewConnectionError('<urllib3.connection.VerifiedHTTPSConnection object at 0x726feb10>: Failed to establish a new connection: [Errno -3] Try again',))

During handling of the above exception, another exception occurred:

Traceback (most recent call last):
  File "/usr/lib/python3.6/site-packages/homeassistant/helpers/entity.py", line 199, in async_update_ha_state
    yield from self.async_device_update()
  File "/usr/lib/python3.6/site-packages/homeassistant/helpers/entity.py", line 306, in async_device_update
    yield from self.hass.async_add_job(self.update)
  File "/usr/lib/python3.6/asyncio/futures.py", line 332, in __iter__
    yield self  # This tells Task to wait for completion.
  File "/usr/lib/python3.6/asyncio/tasks.py", line 250, in _wakeup
    future.result()
  File "/usr/lib/python3.6/asyncio/futures.py", line 245, in result
    raise self._exception
  File "/usr/lib/python3.6/concurrent/futures/thread.py", line 56, in run
    result = self.fn(*self.args, **self.kwargs)
  File "/usr/lib/python3.6/site-packages/homeassistant/components/media_player/spotify.py", line 172, in update
    player_devices = self._player.devices()
  File "/usr/lib/python3.6/site-packages/spotipy/client.py", line 848, in devices
    return self._get("me/player/devices")
  File "/usr/lib/python3.6/site-packages/spotipy/client.py", line 148, in _get
    return self._internal_call('GET', url, payload, kwargs)
  File "/usr/lib/python3.6/site-packages/spotipy/client.py", line 110, in _internal_call
    r = self._session.request(method, url, headers=headers, proxies=self.proxies, **args)
  File "/usr/lib/python3.6/site-packages/requests/sessions.py", line 508, in request
    resp = self.send(prep, **send_kwargs)
  File "/usr/lib/python3.6/site-packages/requests/sessions.py", line 618, in send
    r = adapter.send(request, **kwargs)
  File "/usr/lib/python3.6/site-packages/requests/adapters.py", line 508, in send
    raise ConnectionError(e, request=request)
requests.exceptions.ConnectionError: HTTPSConnectionPool(host='api.spotify.com', port=443): Max retries exceeded with url: /v1/me/player/devices (Caused by NewConnectionError('<urllib3.connection.VerifiedHTTPSConnection object at 0x726feb10>: Failed to establish a new connection: [Errno -3] Try again',))
2017-12-24 02:46:02 ERROR (MainThread) [homeassistant.helpers.entity] Update for media_player.spotify fails
Traceback (most recent call last):
  File "/usr/lib/python3.6/site-packages/urllib3/connection.py", line 141, in _new_conn
    (self.host, self.port), self.timeout, **extra_kw)
  File "/usr/lib/python3.6/site-packages/urllib3/util/connection.py", line 60, in create_connection
    for res in socket.getaddrinfo(host, port, family, socket.SOCK_STREAM):
  File "/usr/lib/python3.6/socket.py", line 745, in getaddrinfo
    for res in _socket.getaddrinfo(host, port, family, type, proto, flags):
socket.gaierror: [Errno -3] Try again

During handling of the above exception, another exception occurred:

Traceback (most recent call last):
  File "/usr/lib/python3.6/site-packages/urllib3/connectionpool.py", line 601, in urlopen
    chunked=chunked)
  File "/usr/lib/python3.6/site-packages/urllib3/connectionpool.py", line 346, in _make_request
    self._validate_conn(conn)
  File "/usr/lib/python3.6/site-packages/urllib3/connectionpool.py", line 850, in _validate_conn
    conn.connect()
  File "/usr/lib/python3.6/site-packages/urllib3/connection.py", line 284, in connect
    conn = self._new_conn()
  File "/usr/lib/python3.6/site-packages/urllib3/connection.py", line 150, in _new_conn
    self, "Failed to establish a new connection: %s" % e)
urllib3.exceptions.NewConnectionError: <urllib3.connection.VerifiedHTTPSConnection object at 0x726ea970>: Failed to establish a new connection: [Errno -3] Try again

During handling of the above exception, another exception occurred:

Traceback (most recent call last):
  File "/usr/lib/python3.6/site-packages/requests/adapters.py", line 440, in send
    timeout=timeout
  File "/usr/lib/python3.6/site-packages/urllib3/connectionpool.py", line 639, in urlopen
    _stacktrace=sys.exc_info()[2])
  File "/usr/lib/python3.6/site-packages/urllib3/util/retry.py", line 388, in increment
    raise MaxRetryError(_pool, url, error or ResponseError(cause))
urllib3.exceptions.MaxRetryError: HTTPSConnectionPool(host='api.spotify.com', port=443): Max retries exceeded with url: /v1/me/player (Caused by NewConnectionError('<urllib3.connection.VerifiedHTTPSConnection object at 0x726ea970>: Failed to establish a new connection: [Errno -3] Try again',))

During handling of the above exception, another exception occurred:

Traceback (most recent call last):
  File "/usr/lib/python3.6/site-packages/homeassistant/helpers/entity.py", line 199, in async_update_ha_state
    yield from self.async_device_update()
  File "/usr/lib/python3.6/site-packages/homeassistant/helpers/entity.py", line 306, in async_device_update
    yield from self.hass.async_add_job(self.update)
  File "/usr/lib/python3.6/asyncio/futures.py", line 332, in __iter__
    yield self  # This tells Task to wait for completion.
  File "/usr/lib/python3.6/asyncio/tasks.py", line 250, in _wakeup
    future.result()
  File "/usr/lib/python3.6/asyncio/futures.py", line 245, in result
    raise self._exception
  File "/usr/lib/python3.6/concurrent/futures/thread.py", line 56, in run
    result = self.fn(*self.args, **self.kwargs)
  File "/usr/lib/python3.6/site-packages/homeassistant/components/media_player/spotify.py", line 186, in update
    current = self._player.current_playback()
  File "/usr/lib/python3.6/site-packages/spotipy/client.py", line 856, in current_playback
    return self._get("me/player", market = market)
  File "/usr/lib/python3.6/site-packages/spotipy/client.py", line 148, in _get
    return self._internal_call('GET', url, payload, kwargs)
  File "/usr/lib/python3.6/site-packages/spotipy/client.py", line 110, in _internal_call
    r = self._session.request(method, url, headers=headers, proxies=self.proxies, **args)
  File "/usr/lib/python3.6/site-packages/requests/sessions.py", line 508, in request
    resp = self.send(prep, **send_kwargs)
  File "/usr/lib/python3.6/site-packages/requests/sessions.py", line 618, in send
    r = adapter.send(request, **kwargs)
  File "/usr/lib/python3.6/site-packages/requests/adapters.py", line 508, in send
    raise ConnectionError(e, request=request)
requests.exceptions.ConnectionError: HTTPSConnectionPool(host='api.spotify.com', port=443): Max retries exceeded with url: /v1/me/player (Caused by NewConnectionError('<urllib3.connection.VerifiedHTTPSConnection object at 0x726ea970>: Failed to establish a new connection: [Errno -3] Try again',))
2017-12-24 03:08:15 ERROR (MainThread) [homeassistant.helpers.entity] Update for media_player.spotify fails
Traceback (most recent call last):
  File "/usr/lib/python3.6/site-packages/urllib3/connection.py", line 141, in _new_conn
    (self.host, self.port), self.timeout, **extra_kw)
  File "/usr/lib/python3.6/site-packages/urllib3/util/connection.py", line 60, in create_connection
    for res in socket.getaddrinfo(host, port, family, socket.SOCK_STREAM):
  File "/usr/lib/python3.6/socket.py", line 745, in getaddrinfo
    for res in _socket.getaddrinfo(host, port, family, type, proto, flags):
socket.gaierror: [Errno -3] Try again

During handling of the above exception, another exception occurred:

Traceback (most recent call last):
  File "/usr/lib/python3.6/site-packages/urllib3/connectionpool.py", line 601, in urlopen
    chunked=chunked)
  File "/usr/lib/python3.6/site-packages/urllib3/connectionpool.py", line 346, in _make_request
    self._validate_conn(conn)
  File "/usr/lib/python3.6/site-packages/urllib3/connectionpool.py", line 850, in _validate_conn
    conn.connect()
  File "/usr/lib/python3.6/site-packages/urllib3/connection.py", line 284, in connect
    conn = self._new_conn()
  File "/usr/lib/python3.6/site-packages/urllib3/connection.py", line 150, in _new_conn
    self, "Failed to establish a new connection: %s" % e)
urllib3.exceptions.NewConnectionError: <urllib3.connection.VerifiedHTTPSConnection object at 0x6f0bec10>: Failed to establish a new connection: [Errno -3] Try again

During handling of the above exception, another exception occurred:

Traceback (most recent call last):
  File "/usr/lib/python3.6/site-packages/requests/adapters.py", line 440, in send
    timeout=timeout
  File "/usr/lib/python3.6/site-packages/urllib3/connectionpool.py", line 639, in urlopen
    _stacktrace=sys.exc_info()[2])
  File "/usr/lib/python3.6/site-packages/urllib3/util/retry.py", line 388, in increment
    raise MaxRetryError(_pool, url, error or ResponseError(cause))
urllib3.exceptions.MaxRetryError: HTTPSConnectionPool(host='api.spotify.com', port=443): Max retries exceeded with url: /v1/me/player (Caused by NewConnectionError('<urllib3.connection.VerifiedHTTPSConnection object at 0x6f0bec10>: Failed to establish a new connection: [Errno -3] Try again',))

During handling of the above exception, another exception occurred:

Traceback (most recent call last):
  File "/usr/lib/python3.6/site-packages/homeassistant/helpers/entity.py", line 199, in async_update_ha_state
    yield from self.async_device_update()
  File "/usr/lib/python3.6/site-packages/homeassistant/helpers/entity.py", line 306, in async_device_update
    yield from self.hass.async_add_job(self.update)
  File "/usr/lib/python3.6/asyncio/futures.py", line 332, in __iter__
    yield self  # This tells Task to wait for completion.
  File "/usr/lib/python3.6/asyncio/tasks.py", line 250, in _wakeup
    future.result()
  File "/usr/lib/python3.6/asyncio/futures.py", line 245, in result
    raise self._exception
  File "/usr/lib/python3.6/concurrent/futures/thread.py", line 56, in run
    result = self.fn(*self.args, **self.kwargs)
  File "/usr/lib/python3.6/site-packages/homeassistant/components/media_player/spotify.py", line 186, in update
    current = self._player.current_playback()
  File "/usr/lib/python3.6/site-packages/spotipy/client.py", line 856, in current_playback
    return self._get("me/player", market = market)
  File "/usr/lib/python3.6/site-packages/spotipy/client.py", line 148, in _get
    return self._internal_call('GET', url, payload, kwargs)
  File "/usr/lib/python3.6/site-packages/spotipy/client.py", line 110, in _internal_call
    r = self._session.request(method, url, headers=headers, proxies=self.proxies, **args)
  File "/usr/lib/python3.6/site-packages/requests/sessions.py", line 508, in request
    resp = self.send(prep, **send_kwargs)
  File "/usr/lib/python3.6/site-packages/requests/sessions.py", line 618, in send
    r = adapter.send(request, **kwargs)
  File "/usr/lib/python3.6/site-packages/requests/adapters.py", line 508, in send
    raise ConnectionError(e, request=request)
requests.exceptions.ConnectionError: HTTPSConnectionPool(host='api.spotify.com', port=443): Max retries exceeded with url: /v1/me/player (Caused by NewConnectionError('<urllib3.connection.VerifiedHTTPSConnection object at 0x6f0bec10>: Failed to establish a new connection: [Errno -3] Try again',))
2017-12-24 03:17:01 ERROR (MainThread) [homeassistant.helpers.entity] Update for media_player.spotify fails
Traceback (most recent call last):
  File "/usr/lib/python3.6/site-packages/urllib3/connection.py", line 141, in _new_conn
    (self.host, self.port), self.timeout, **extra_kw)
  File "/usr/lib/python3.6/site-packages/urllib3/util/connection.py", line 60, in create_connection
    for res in socket.getaddrinfo(host, port, family, socket.SOCK_STREAM):
  File "/usr/lib/python3.6/socket.py", line 745, in getaddrinfo
    for res in _socket.getaddrinfo(host, port, family, type, proto, flags):
socket.gaierror: [Errno -3] Try again

During handling of the above exception, another exception occurred:

Traceback (most recent call last):
  File "/usr/lib/python3.6/site-packages/urllib3/connectionpool.py", line 601, in urlopen
    chunked=chunked)
  File "/usr/lib/python3.6/site-packages/urllib3/connectionpool.py", line 346, in _make_request
    self._validate_conn(conn)
  File "/usr/lib/python3.6/site-packages/urllib3/connectionpool.py", line 850, in _validate_conn
    conn.connect()
  File "/usr/lib/python3.6/site-packages/urllib3/connection.py", line 284, in connect
    conn = self._new_conn()
  File "/usr/lib/python3.6/site-packages/urllib3/connection.py", line 150, in _new_conn
    self, "Failed to establish a new connection: %s" % e)
urllib3.exceptions.NewConnectionError: <urllib3.connection.VerifiedHTTPSConnection object at 0x72ee5dd0>: Failed to establish a new connection: [Errno -3] Try again

During handling of the above exception, another exception occurred:

Traceback (most recent call last):
  File "/usr/lib/python3.6/site-packages/requests/adapters.py", line 440, in send
    timeout=timeout
  File "/usr/lib/python3.6/site-packages/urllib3/connectionpool.py", line 639, in urlopen
    _stacktrace=sys.exc_info()[2])
  File "/usr/lib/python3.6/site-packages/urllib3/util/retry.py", line 388, in increment
    raise MaxRetryError(_pool, url, error or ResponseError(cause))
urllib3.exceptions.MaxRetryError: HTTPSConnectionPool(host='api.spotify.com', port=443): Max retries exceeded with url: /v1/me/player (Caused by NewConnectionError('<urllib3.connection.VerifiedHTTPSConnection object at 0x72ee5dd0>: Failed to establish a new connection: [Errno -3] Try again',))

During handling of the above exception, another exception occurred:

Traceback (most recent call last):
  File "/usr/lib/python3.6/site-packages/homeassistant/helpers/entity.py", line 199, in async_update_ha_state
    yield from self.async_device_update()
  File "/usr/lib/python3.6/site-packages/homeassistant/helpers/entity.py", line 306, in async_device_update
    yield from self.hass.async_add_job(self.update)
  File "/usr/lib/python3.6/asyncio/futures.py", line 332, in __iter__
    yield self  # This tells Task to wait for completion.
  File "/usr/lib/python3.6/asyncio/tasks.py", line 250, in _wakeup
    future.result()
  File "/usr/lib/python3.6/asyncio/futures.py", line 245, in result
    raise self._exception
  File "/usr/lib/python3.6/concurrent/futures/thread.py", line 56, in run
    result = self.fn(*self.args, **self.kwargs)
  File "/usr/lib/python3.6/site-packages/homeassistant/components/media_player/spotify.py", line 186, in update
    current = self._player.current_playback()
  File "/usr/lib/python3.6/site-packages/spotipy/client.py", line 856, in current_playback
    return self._get("me/player", market = market)
  File "/usr/lib/python3.6/site-packages/spotipy/client.py", line 148, in _get
    return self._internal_call('GET', url, payload, kwargs)
  File "/usr/lib/python3.6/site-packages/spotipy/client.py", line 110, in _internal_call
    r = self._session.request(method, url, headers=headers, proxies=self.proxies, **args)
  File "/usr/lib/python3.6/site-packages/requests/sessions.py", line 508, in request
    resp = self.send(prep, **send_kwargs)
  File "/usr/lib/python3.6/site-packages/requests/sessions.py", line 618, in send
    r = adapter.send(request, **kwargs)
  File "/usr/lib/python3.6/site-packages/requests/adapters.py", line 508, in send
    raise ConnectionError(e, request=request)
requests.exceptions.ConnectionError: HTTPSConnectionPool(host='api.spotify.com', port=443): Max retries exceeded with url: /v1/me/player (Caused by NewConnectionError('<urllib3.connection.VerifiedHTTPSConnection object at 0x72ee5dd0>: Failed to establish a new connection: [Errno -3] Try again',))
2017-12-24 03:23:44 ERROR (MainThread) [homeassistant.helpers.entity] Update for media_player.spotify fails
Traceback (most recent call last):
  File "/usr/lib/python3.6/site-packages/urllib3/connection.py", line 141, in _new_conn
    (self.host, self.port), self.timeout, **extra_kw)
  File "/usr/lib/python3.6/site-packages/urllib3/util/connection.py", line 60, in create_connection
    for res in socket.getaddrinfo(host, port, family, socket.SOCK_STREAM):
  File "/usr/lib/python3.6/socket.py", line 745, in getaddrinfo
    for res in _socket.getaddrinfo(host, port, family, type, proto, flags):
socket.gaierror: [Errno -3] Try again

During handling of the above exception, another exception occurred:

Traceback (most recent call last):
  File "/usr/lib/python3.6/site-packages/urllib3/connectionpool.py", line 601, in urlopen
    chunked=chunked)
  File "/usr/lib/python3.6/site-packages/urllib3/connectionpool.py", line 346, in _make_request
    self._validate_conn(conn)
  File "/usr/lib/python3.6/site-packages/urllib3/connectionpool.py", line 850, in _validate_conn
    conn.connect()
  File "/usr/lib/python3.6/site-packages/urllib3/connection.py", line 284, in connect
    conn = self._new_conn()
  File "/usr/lib/python3.6/site-packages/urllib3/connection.py", line 150, in _new_conn
    self, "Failed to establish a new connection: %s" % e)
urllib3.exceptions.NewConnectionError: <urllib3.connection.VerifiedHTTPSConnection object at 0x6f0c6350>: Failed to establish a new connection: [Errno -3] Try again

During handling of the above exception, another exception occurred:

Traceback (most recent call last):
  File "/usr/lib/python3.6/site-packages/requests/adapters.py", line 440, in send
    timeout=timeout
  File "/usr/lib/python3.6/site-packages/urllib3/connectionpool.py", line 639, in urlopen
    _stacktrace=sys.exc_info()[2])
  File "/usr/lib/python3.6/site-packages/urllib3/util/retry.py", line 388, in increment
    raise MaxRetryError(_pool, url, error or ResponseError(cause))
urllib3.exceptions.MaxRetryError: HTTPSConnectionPool(host='api.spotify.com', port=443): Max retries exceeded with url: /v1/me/player (Caused by NewConnectionError('<urllib3.connection.VerifiedHTTPSConnection object at 0x6f0c6350>: Failed to establish a new connection: [Errno -3] Try again',))

During handling of the above exception, another exception occurred:

Traceback (most recent call last):
  File "/usr/lib/python3.6/site-packages/homeassistant/helpers/entity.py", line 199, in async_update_ha_state
    yield from self.async_device_update()
  File "/usr/lib/python3.6/site-packages/homeassistant/helpers/entity.py", line 306, in async_device_update
    yield from self.hass.async_add_job(self.update)
  File "/usr/lib/python3.6/asyncio/futures.py", line 332, in __iter__
    yield self  # This tells Task to wait for completion.
  File "/usr/lib/python3.6/asyncio/tasks.py", line 250, in _wakeup
    future.result()
  File "/usr/lib/python3.6/asyncio/futures.py", line 245, in result
    raise self._exception
  File "/usr/lib/python3.6/concurrent/futures/thread.py", line 56, in run
    result = self.fn(*self.args, **self.kwargs)
  File "/usr/lib/python3.6/site-packages/homeassistant/components/media_player/spotify.py", line 186, in update
    current = self._player.current_playback()
  File "/usr/lib/python3.6/site-packages/spotipy/client.py", line 856, in current_playback
    return self._get("me/player", market = market)
  File "/usr/lib/python3.6/site-packages/spotipy/client.py", line 148, in _get
    return self._internal_call('GET', url, payload, kwargs)
  File "/usr/lib/python3.6/site-packages/spotipy/client.py", line 110, in _internal_call
    r = self._session.request(method, url, headers=headers, proxies=self.proxies, **args)
  File "/usr/lib/python3.6/site-packages/requests/sessions.py", line 508, in request
    resp = self.send(prep, **send_kwargs)
  File "/usr/lib/python3.6/site-packages/requests/sessions.py", line 618, in send
    r = adapter.send(request, **kwargs)
  File "/usr/lib/python3.6/site-packages/requests/adapters.py", line 508, in send
    raise ConnectionError(e, request=request)
requests.exceptions.ConnectionError: HTTPSConnectionPool(host='api.spotify.com', port=443): Max retries exceeded with url: /v1/me/player (Caused by NewConnectionError('<urllib3.connection.VerifiedHTTPSConnection object at 0x6f0c6350>: Failed to establish a new connection: [Errno -3] Try again',))
2017-12-24 03:34:04 ERROR (MainThread) [homeassistant.helpers.entity] Update for media_player.spotify fails
Traceback (most recent call last):
  File "/usr/lib/python3.6/site-packages/urllib3/connection.py", line 141, in _new_conn
    (self.host, self.port), self.timeout, **extra_kw)
  File "/usr/lib/python3.6/site-packages/urllib3/util/connection.py", line 60, in create_connection
    for res in socket.getaddrinfo(host, port, family, socket.SOCK_STREAM):
  File "/usr/lib/python3.6/socket.py", line 745, in getaddrinfo
    for res in _socket.getaddrinfo(host, port, family, type, proto, flags):
socket.gaierror: [Errno -3] Try again

During handling of the above exception, another exception occurred:

Traceback (most recent call last):
  File "/usr/lib/python3.6/site-packages/urllib3/connectionpool.py", line 601, in urlopen
    chunked=chunked)
  File "/usr/lib/python3.6/site-packages/urllib3/connectionpool.py", line 346, in _make_request
    self._validate_conn(conn)
  File "/usr/lib/python3.6/site-packages/urllib3/connectionpool.py", line 850, in _validate_conn
    conn.connect()
  File "/usr/lib/python3.6/site-packages/urllib3/connection.py", line 284, in connect
    conn = self._new_conn()
  File "/usr/lib/python3.6/site-packages/urllib3/connection.py", line 150, in _new_conn
    self, "Failed to establish a new connection: %s" % e)
urllib3.exceptions.NewConnectionError: <urllib3.connection.VerifiedHTTPSConnection object at 0x6f0babb0>: Failed to establish a new connection: [Errno -3] Try again

During handling of the above exception, another exception occurred:

Traceback (most recent call last):
  File "/usr/lib/python3.6/site-packages/requests/adapters.py", line 440, in send
    timeout=timeout
  File "/usr/lib/python3.6/site-packages/urllib3/connectionpool.py", line 639, in urlopen
    _stacktrace=sys.exc_info()[2])
  File "/usr/lib/python3.6/site-packages/urllib3/util/retry.py", line 388, in increment
    raise MaxRetryError(_pool, url, error or ResponseError(cause))
urllib3.exceptions.MaxRetryError: HTTPSConnectionPool(host='api.spotify.com', port=443): Max retries exceeded with url: /v1/me/player (Caused by NewConnectionError('<urllib3.connection.VerifiedHTTPSConnection object at 0x6f0babb0>: Failed to establish a new connection: [Errno -3] Try again',))

During handling of the above exception, another exception occurred:

Traceback (most recent call last):
  File "/usr/lib/python3.6/site-packages/homeassistant/helpers/entity.py", line 199, in async_update_ha_state
    yield from self.async_device_update()
  File "/usr/lib/python3.6/site-packages/homeassistant/helpers/entity.py", line 306, in async_device_update
    yield from self.hass.async_add_job(self.update)
  File "/usr/lib/python3.6/asyncio/futures.py", line 332, in __iter__
    yield self  # This tells Task to wait for completion.
  File "/usr/lib/python3.6/asyncio/tasks.py", line 250, in _wakeup
    future.result()
  File "/usr/lib/python3.6/asyncio/futures.py", line 245, in result
    raise self._exception
  File "/usr/lib/python3.6/concurrent/futures/thread.py", line 56, in run
    result = self.fn(*self.args, **self.kwargs)
  File "/usr/lib/python3.6/site-packages/homeassistant/components/media_player/spotify.py", line 186, in update
    current = self._player.current_playback()
  File "/usr/lib/python3.6/site-packages/spotipy/client.py", line 856, in current_playback
    return self._get("me/player", market = market)
  File "/usr/lib/python3.6/site-packages/spotipy/client.py", line 148, in _get
    return self._internal_call('GET', url, payload, kwargs)
  File "/usr/lib/python3.6/site-packages/spotipy/client.py", line 110, in _internal_call
    r = self._session.request(method, url, headers=headers, proxies=self.proxies, **args)
  File "/usr/lib/python3.6/site-packages/requests/sessions.py", line 508, in request
    resp = self.send(prep, **send_kwargs)
  File "/usr/lib/python3.6/site-packages/requests/sessions.py", line 618, in send
    r = adapter.send(request, **kwargs)
  File "/usr/lib/python3.6/site-packages/requests/adapters.py", line 508, in send
    raise ConnectionError(e, request=request)
requests.exceptions.ConnectionError: HTTPSConnectionPool(host='api.spotify.com', port=443): Max retries exceeded with url: /v1/me/player (Caused by NewConnectionError('<urllib3.connection.VerifiedHTTPSConnection object at 0x6f0babb0>: Failed to establish a new connection: [Errno -3] Try again',))
2017-12-24 04:07:07 ERROR (MainThread) [homeassistant.helpers.entity] Update for media_player.spotify fails
Traceback (most recent call last):
  File "/usr/lib/python3.6/site-packages/urllib3/connection.py", line 141, in _new_conn
    (self.host, self.port), self.timeout, **extra_kw)
  File "/usr/lib/python3.6/site-packages/urllib3/util/connection.py", line 60, in create_connection
    for res in socket.getaddrinfo(host, port, family, socket.SOCK_STREAM):
  File "/usr/lib/python3.6/socket.py", line 745, in getaddrinfo
    for res in _socket.getaddrinfo(host, port, family, type, proto, flags):
socket.gaierror: [Errno -3] Try again

During handling of the above exception, another exception occurred:

Traceback (most recent call last):
  File "/usr/lib/python3.6/site-packages/urllib3/connectionpool.py", line 601, in urlopen
    chunked=chunked)
  File "/usr/lib/python3.6/site-packages/urllib3/connectionpool.py", line 346, in _make_request
    self._validate_conn(conn)
  File "/usr/lib/python3.6/site-packages/urllib3/connectionpool.py", line 850, in _validate_conn
    conn.connect()
  File "/usr/lib/python3.6/site-packages/urllib3/connection.py", line 284, in connect
    conn = self._new_conn()
  File "/usr/lib/python3.6/site-packages/urllib3/connection.py", line 150, in _new_conn
    self, "Failed to establish a new connection: %s" % e)
urllib3.exceptions.NewConnectionError: <urllib3.connection.VerifiedHTTPSConnection object at 0x72688150>: Failed to establish a new connection: [Errno -3] Try again

During handling of the above exception, another exception occurred:

Traceback (most recent call last):
  File "/usr/lib/python3.6/site-packages/requests/adapters.py", line 440, in send
    timeout=timeout
  File "/usr/lib/python3.6/site-packages/urllib3/connectionpool.py", line 639, in urlopen
    _stacktrace=sys.exc_info()[2])
  File "/usr/lib/python3.6/site-packages/urllib3/util/retry.py", line 388, in increment
    raise MaxRetryError(_pool, url, error or ResponseError(cause))
urllib3.exceptions.MaxRetryError: HTTPSConnectionPool(host='api.spotify.com', port=443): Max retries exceeded with url: /v1/me/player/devices (Caused by NewConnectionError('<urllib3.connection.VerifiedHTTPSConnection object at 0x72688150>: Failed to establish a new connection: [Errno -3] Try again',))

During handling of the above exception, another exception occurred:

Traceback (most recent call last):
  File "/usr/lib/python3.6/site-packages/homeassistant/helpers/entity.py", line 199, in async_update_ha_state
    yield from self.async_device_update()
  File "/usr/lib/python3.6/site-packages/homeassistant/helpers/entity.py", line 306, in async_device_update
    yield from self.hass.async_add_job(self.update)
  File "/usr/lib/python3.6/asyncio/futures.py", line 332, in __iter__
    yield self  # This tells Task to wait for completion.
  File "/usr/lib/python3.6/asyncio/tasks.py", line 250, in _wakeup
    future.result()
  File "/usr/lib/python3.6/asyncio/futures.py", line 245, in result
    raise self._exception
  File "/usr/lib/python3.6/concurrent/futures/thread.py", line 56, in run
    result = self.fn(*self.args, **self.kwargs)
  File "/usr/lib/python3.6/site-packages/homeassistant/components/media_player/spotify.py", line 172, in update
    player_devices = self._player.devices()
  File "/usr/lib/python3.6/site-packages/spotipy/client.py", line 848, in devices
    return self._get("me/player/devices")
  File "/usr/lib/python3.6/site-packages/spotipy/client.py", line 148, in _get
    return self._internal_call('GET', url, payload, kwargs)
  File "/usr/lib/python3.6/site-packages/spotipy/client.py", line 110, in _internal_call
    r = self._session.request(method, url, headers=headers, proxies=self.proxies, **args)
  File "/usr/lib/python3.6/site-packages/requests/sessions.py", line 508, in request
    resp = self.send(prep, **send_kwargs)
  File "/usr/lib/python3.6/site-packages/requests/sessions.py", line 618, in send
    r = adapter.send(request, **kwargs)
  File "/usr/lib/python3.6/site-packages/requests/adapters.py", line 508, in send
    raise ConnectionError(e, request=request)
requests.exceptions.ConnectionError: HTTPSConnectionPool(host='api.spotify.com', port=443): Max retries exceeded with url: /v1/me/player/devices (Caused by NewConnectionError('<urllib3.connection.VerifiedHTTPSConnection object at 0x72688150>: Failed to establish a new connection: [Errno -3] Try again',))
2017-12-24 04:30:53 WARNING (Thread-2) [pychromecast.socket_client] Heartbeat timeout, resetting connection
2017-12-24 04:30:54 ERROR (Thread-2) [pychromecast.socket_client] Failed to connect, retrying in 5.0s
2017-12-24 04:33:28 ERROR (MainThread) [homeassistant.helpers.entity] Update for media_player.spotify fails
Traceback (most recent call last):
  File "/usr/lib/python3.6/site-packages/urllib3/connection.py", line 141, in _new_conn
    (self.host, self.port), self.timeout, **extra_kw)
  File "/usr/lib/python3.6/site-packages/urllib3/util/connection.py", line 60, in create_connection
    for res in socket.getaddrinfo(host, port, family, socket.SOCK_STREAM):
  File "/usr/lib/python3.6/socket.py", line 745, in getaddrinfo
    for res in _socket.getaddrinfo(host, port, family, type, proto, flags):
socket.gaierror: [Errno -3] Try again

During handling of the above exception, another exception occurred:

Traceback (most recent call last):
  File "/usr/lib/python3.6/site-packages/urllib3/connectionpool.py", line 601, in urlopen
    chunked=chunked)
  File "/usr/lib/python3.6/site-packages/urllib3/connectionpool.py", line 346, in _make_request
    self._validate_conn(conn)
  File "/usr/lib/python3.6/site-packages/urllib3/connectionpool.py", line 850, in _validate_conn
    conn.connect()
  File "/usr/lib/python3.6/site-packages/urllib3/connection.py", line 284, in connect
    conn = self._new_conn()
  File "/usr/lib/python3.6/site-packages/urllib3/connection.py", line 150, in _new_conn
    self, "Failed to establish a new connection: %s" % e)
urllib3.exceptions.NewConnectionError: <urllib3.connection.VerifiedHTTPSConnection object at 0x726cc350>: Failed to establish a new connection: [Errno -3] Try again

During handling of the above exception, another exception occurred:

Traceback (most recent call last):
  File "/usr/lib/python3.6/site-packages/requests/adapters.py", line 440, in send
    timeout=timeout
  File "/usr/lib/python3.6/site-packages/urllib3/connectionpool.py", line 639, in urlopen
    _stacktrace=sys.exc_info()[2])
  File "/usr/lib/python3.6/site-packages/urllib3/util/retry.py", line 388, in increment
    raise MaxRetryError(_pool, url, error or ResponseError(cause))
urllib3.exceptions.MaxRetryError: HTTPSConnectionPool(host='api.spotify.com', port=443): Max retries exceeded with url: /v1/me/player (Caused by NewConnectionError('<urllib3.connection.VerifiedHTTPSConnection object at 0x726cc350>: Failed to establish a new connection: [Errno -3] Try again',))

During handling of the above exception, another exception occurred:

Traceback (most recent call last):
  File "/usr/lib/python3.6/site-packages/homeassistant/helpers/entity.py", line 199, in async_update_ha_state
    yield from self.async_device_update()
  File "/usr/lib/python3.6/site-packages/homeassistant/helpers/entity.py", line 306, in async_device_update
    yield from self.hass.async_add_job(self.update)
  File "/usr/lib/python3.6/asyncio/futures.py", line 332, in __iter__
    yield self  # This tells Task to wait for completion.
  File "/usr/lib/python3.6/asyncio/tasks.py", line 250, in _wakeup
    future.result()
  File "/usr/lib/python3.6/asyncio/futures.py", line 245, in result
    raise self._exception
  File "/usr/lib/python3.6/concurrent/futures/thread.py", line 56, in run
    result = self.fn(*self.args, **self.kwargs)
  File "/usr/lib/python3.6/site-packages/homeassistant/components/media_player/spotify.py", line 186, in update
    current = self._player.current_playback()
  File "/usr/lib/python3.6/site-packages/spotipy/client.py", line 856, in current_playback
    return self._get("me/player", market = market)
  File "/usr/lib/python3.6/site-packages/spotipy/client.py", line 148, in _get
    return self._internal_call('GET', url, payload, kwargs)
  File "/usr/lib/python3.6/site-packages/spotipy/client.py", line 110, in _internal_call
    r = self._session.request(method, url, headers=headers, proxies=self.proxies, **args)
  File "/usr/lib/python3.6/site-packages/requests/sessions.py", line 508, in request
    resp = self.send(prep, **send_kwargs)
  File "/usr/lib/python3.6/site-packages/requests/sessions.py", line 618, in send
    r = adapter.send(request, **kwargs)
  File "/usr/lib/python3.6/site-packages/requests/adapters.py", line 508, in send
    raise ConnectionError(e, request=request)
requests.exceptions.ConnectionError: HTTPSConnectionPool(host='api.spotify.com', port=443): Max retries exceeded with url: /v1/me/player (Caused by NewConnectionError('<urllib3.connection.VerifiedHTTPSConnection object at 0x726cc350>: Failed to establish a new connection: [Errno -3] Try again',))
2017-12-24 04:46:52 ERROR (MainThread) [homeassistant.helpers.entity] Update for media_player.spotify fails
Traceback (most recent call last):
  File "/usr/lib/python3.6/site-packages/urllib3/connection.py", line 141, in _new_conn
    (self.host, self.port), self.timeout, **extra_kw)
  File "/usr/lib/python3.6/site-packages/urllib3/util/connection.py", line 60, in create_connection
    for res in socket.getaddrinfo(host, port, family, socket.SOCK_STREAM):
  File "/usr/lib/python3.6/socket.py", line 745, in getaddrinfo
    for res in _socket.getaddrinfo(host, port, family, type, proto, flags):
socket.gaierror: [Errno -3] Try again

During handling of the above exception, another exception occurred:

Traceback (most recent call last):
  File "/usr/lib/python3.6/site-packages/urllib3/connectionpool.py", line 601, in urlopen
    chunked=chunked)
  File "/usr/lib/python3.6/site-packages/urllib3/connectionpool.py", line 346, in _make_request
    self._validate_conn(conn)
  File "/usr/lib/python3.6/site-packages/urllib3/connectionpool.py", line 850, in _validate_conn
    conn.connect()
  File "/usr/lib/python3.6/site-packages/urllib3/connection.py", line 284, in connect
    conn = self._new_conn()
  File "/usr/lib/python3.6/site-packages/urllib3/connection.py", line 150, in _new_conn
    self, "Failed to establish a new connection: %s" % e)
urllib3.exceptions.NewConnectionError: <urllib3.connection.VerifiedHTTPSConnection object at 0x6f0ba650>: Failed to establish a new connection: [Errno -3] Try again

During handling of the above exception, another exception occurred:

Traceback (most recent call last):
  File "/usr/lib/python3.6/site-packages/requests/adapters.py", line 440, in send
    timeout=timeout
  File "/usr/lib/python3.6/site-packages/urllib3/connectionpool.py", line 639, in urlopen
    _stacktrace=sys.exc_info()[2])
  File "/usr/lib/python3.6/site-packages/urllib3/util/retry.py", line 388, in increment
    raise MaxRetryError(_pool, url, error or ResponseError(cause))
urllib3.exceptions.MaxRetryError: HTTPSConnectionPool(host='api.spotify.com', port=443): Max retries exceeded with url: /v1/me/player/devices (Caused by NewConnectionError('<urllib3.connection.VerifiedHTTPSConnection object at 0x6f0ba650>: Failed to establish a new connection: [Errno -3] Try again',))

During handling of the above exception, another exception occurred:

Traceback (most recent call last):
  File "/usr/lib/python3.6/site-packages/homeassistant/helpers/entity.py", line 199, in async_update_ha_state
    yield from self.async_device_update()
  File "/usr/lib/python3.6/site-packages/homeassistant/helpers/entity.py", line 306, in async_device_update
    yield from self.hass.async_add_job(self.update)
  File "/usr/lib/python3.6/asyncio/futures.py", line 332, in __iter__
    yield self  # This tells Task to wait for completion.
  File "/usr/lib/python3.6/asyncio/tasks.py", line 250, in _wakeup
    future.result()
  File "/usr/lib/python3.6/asyncio/futures.py", line 245, in result
    raise self._exception
  File "/usr/lib/python3.6/concurrent/futures/thread.py", line 56, in run
    result = self.fn(*self.args, **self.kwargs)
  File "/usr/lib/python3.6/site-packages/homeassistant/components/media_player/spotify.py", line 172, in update
    player_devices = self._player.devices()
  File "/usr/lib/python3.6/site-packages/spotipy/client.py", line 848, in devices
    return self._get("me/player/devices")
  File "/usr/lib/python3.6/site-packages/spotipy/client.py", line 148, in _get
    return self._internal_call('GET', url, payload, kwargs)
  File "/usr/lib/python3.6/site-packages/spotipy/client.py", line 110, in _internal_call
    r = self._session.request(method, url, headers=headers, proxies=self.proxies, **args)
  File "/usr/lib/python3.6/site-packages/requests/sessions.py", line 508, in request
    resp = self.send(prep, **send_kwargs)
  File "/usr/lib/python3.6/site-packages/requests/sessions.py", line 618, in send
    r = adapter.send(request, **kwargs)
  File "/usr/lib/python3.6/site-packages/requests/adapters.py", line 508, in send
    raise ConnectionError(e, request=request)
requests.exceptions.ConnectionError: HTTPSConnectionPool(host='api.spotify.com', port=443): Max retries exceeded with url: /v1/me/player/devices (Caused by NewConnectionError('<urllib3.connection.VerifiedHTTPSConnection object at 0x6f0ba650>: Failed to establish a new connection: [Errno -3] Try again',))
2017-12-24 04:51:32 ERROR (MainThread) [homeassistant.helpers.entity] Update for media_player.spotify fails
Traceback (most recent call last):
  File "/usr/lib/python3.6/site-packages/urllib3/connection.py", line 141, in _new_conn
    (self.host, self.port), self.timeout, **extra_kw)
  File "/usr/lib/python3.6/site-packages/urllib3/util/connection.py", line 60, in create_connection
    for res in socket.getaddrinfo(host, port, family, socket.SOCK_STREAM):
  File "/usr/lib/python3.6/socket.py", line 745, in getaddrinfo
    for res in _socket.getaddrinfo(host, port, family, type, proto, flags):
socket.gaierror: [Errno -3] Try again

During handling of the above exception, another exception occurred:

Traceback (most recent call last):
  File "/usr/lib/python3.6/site-packages/urllib3/connectionpool.py", line 601, in urlopen
    chunked=chunked)
  File "/usr/lib/python3.6/site-packages/urllib3/connectionpool.py", line 346, in _make_request
    self._validate_conn(conn)
  File "/usr/lib/python3.6/site-packages/urllib3/connectionpool.py", line 850, in _validate_conn
    conn.connect()
  File "/usr/lib/python3.6/site-packages/urllib3/connection.py", line 284, in connect
    conn = self._new_conn()
  File "/usr/lib/python3.6/site-packages/urllib3/connection.py", line 150, in _new_conn
    self, "Failed to establish a new connection: %s" % e)
urllib3.exceptions.NewConnectionError: <urllib3.connection.VerifiedHTTPSConnection object at 0x726a7e10>: Failed to establish a new connection: [Errno -3] Try again

During handling of the above exception, another exception occurred:

Traceback (most recent call last):
  File "/usr/lib/python3.6/site-packages/requests/adapters.py", line 440, in send
    timeout=timeout
  File "/usr/lib/python3.6/site-packages/urllib3/connectionpool.py", line 639, in urlopen
    _stacktrace=sys.exc_info()[2])
  File "/usr/lib/python3.6/site-packages/urllib3/util/retry.py", line 388, in increment
    raise MaxRetryError(_pool, url, error or ResponseError(cause))
urllib3.exceptions.MaxRetryError: HTTPSConnectionPool(host='api.spotify.com', port=443): Max retries exceeded with url: /v1/me/player (Caused by NewConnectionError('<urllib3.connection.VerifiedHTTPSConnection object at 0x726a7e10>: Failed to establish a new connection: [Errno -3] Try again',))

During handling of the above exception, another exception occurred:

Traceback (most recent call last):
  File "/usr/lib/python3.6/site-packages/homeassistant/helpers/entity.py", line 199, in async_update_ha_state
    yield from self.async_device_update()
  File "/usr/lib/python3.6/site-packages/homeassistant/helpers/entity.py", line 306, in async_device_update
    yield from self.hass.async_add_job(self.update)
  File "/usr/lib/python3.6/asyncio/futures.py", line 332, in __iter__
    yield self  # This tells Task to wait for completion.
  File "/usr/lib/python3.6/asyncio/tasks.py", line 250, in _wakeup
    future.result()
  File "/usr/lib/python3.6/asyncio/futures.py", line 245, in result
    raise self._exception
  File "/usr/lib/python3.6/concurrent/futures/thread.py", line 56, in run
    result = self.fn(*self.args, **self.kwargs)
  File "/usr/lib/python3.6/site-packages/homeassistant/components/media_player/spotify.py", line 186, in update
    current = self._player.current_playback()
  File "/usr/lib/python3.6/site-packages/spotipy/client.py", line 856, in current_playback
    return self._get("me/player", market = market)
  File "/usr/lib/python3.6/site-packages/spotipy/client.py", line 148, in _get
    return self._internal_call('GET', url, payload, kwargs)
  File "/usr/lib/python3.6/site-packages/spotipy/client.py", line 110, in _internal_call
    r = self._session.request(method, url, headers=headers, proxies=self.proxies, **args)
  File "/usr/lib/python3.6/site-packages/requests/sessions.py", line 508, in request
    resp = self.send(prep, **send_kwargs)
  File "/usr/lib/python3.6/site-packages/requests/sessions.py", line 618, in send
    r = adapter.send(request, **kwargs)
  File "/usr/lib/python3.6/site-packages/requests/adapters.py", line 508, in send
    raise ConnectionError(e, request=request)
requests.exceptions.ConnectionError: HTTPSConnectionPool(host='api.spotify.com', port=443): Max retries exceeded with url: /v1/me/player (Caused by NewConnectionError('<urllib3.connection.VerifiedHTTPSConnection object at 0x726a7e10>: Failed to establish a new connection: [Errno -3] Try again',))
2017-12-24 05:10:39 ERROR (MainThread) [homeassistant.helpers.entity] Update for media_player.spotify fails
Traceback (most recent call last):
  File "/usr/lib/python3.6/site-packages/urllib3/connection.py", line 141, in _new_conn
    (self.host, self.port), self.timeout, **extra_kw)
  File "/usr/lib/python3.6/site-packages/urllib3/util/connection.py", line 60, in create_connection
    for res in socket.getaddrinfo(host, port, family, socket.SOCK_STREAM):
  File "/usr/lib/python3.6/socket.py", line 745, in getaddrinfo
    for res in _socket.getaddrinfo(host, port, family, type, proto, flags):
socket.gaierror: [Errno -3] Try again

During handling of the above exception, another exception occurred:

Traceback (most recent call last):
  File "/usr/lib/python3.6/site-packages/urllib3/connectionpool.py", line 601, in urlopen
    chunked=chunked)
  File "/usr/lib/python3.6/site-packages/urllib3/connectionpool.py", line 346, in _make_request
    self._validate_conn(conn)
  File "/usr/lib/python3.6/site-packages/urllib3/connectionpool.py", line 850, in _validate_conn
    conn.connect()
  File "/usr/lib/python3.6/site-packages/urllib3/connection.py", line 284, in connect
    conn = self._new_conn()
  File "/usr/lib/python3.6/site-packages/urllib3/connection.py", line 150, in _new_conn
    self, "Failed to establish a new connection: %s" % e)
urllib3.exceptions.NewConnectionError: <urllib3.connection.VerifiedHTTPSConnection object at 0x726927f0>: Failed to establish a new connection: [Errno -3] Try again

During handling of the above exception, another exception occurred:

Traceback (most recent call last):
  File "/usr/lib/python3.6/site-packages/requests/adapters.py", line 440, in send
    timeout=timeout
  File "/usr/lib/python3.6/site-packages/urllib3/connectionpool.py", line 639, in urlopen
    _stacktrace=sys.exc_info()[2])
  File "/usr/lib/python3.6/site-packages/urllib3/util/retry.py", line 388, in increment
    raise MaxRetryError(_pool, url, error or ResponseError(cause))
urllib3.exceptions.MaxRetryError: HTTPSConnectionPool(host='api.spotify.com', port=443): Max retries exceeded with url: /v1/me/player (Caused by NewConnectionError('<urllib3.connection.VerifiedHTTPSConnection object at 0x726927f0>: Failed to establish a new connection: [Errno -3] Try again',))

During handling of the above exception, another exception occurred:

Traceback (most recent call last):
  File "/usr/lib/python3.6/site-packages/homeassistant/helpers/entity.py", line 199, in async_update_ha_state
    yield from self.async_device_update()
  File "/usr/lib/python3.6/site-packages/homeassistant/helpers/entity.py", line 306, in async_device_update
    yield from self.hass.async_add_job(self.update)
  File "/usr/lib/python3.6/asyncio/futures.py", line 332, in __iter__
    yield self  # This tells Task to wait for completion.
  File "/usr/lib/python3.6/asyncio/tasks.py", line 250, in _wakeup
    future.result()
  File "/usr/lib/python3.6/asyncio/futures.py", line 245, in result
    raise self._exception
  File "/usr/lib/python3.6/concurrent/futures/thread.py", line 56, in run
    result = self.fn(*self.args, **self.kwargs)
  File "/usr/lib/python3.6/site-packages/homeassistant/components/media_player/spotify.py", line 186, in update
    current = self._player.current_playback()
  File "/usr/lib/python3.6/site-packages/spotipy/client.py", line 856, in current_playback
    return self._get("me/player", market = market)
  File "/usr/lib/python3.6/site-packages/spotipy/client.py", line 148, in _get
    return self._internal_call('GET', url, payload, kwargs)
  File "/usr/lib/python3.6/site-packages/spotipy/client.py", line 110, in _internal_call
    r = self._session.request(method, url, headers=headers, proxies=self.proxies, **args)
  File "/usr/lib/python3.6/site-packages/requests/sessions.py", line 508, in request
    resp = self.send(prep, **send_kwargs)
  File "/usr/lib/python3.6/site-packages/requests/sessions.py", line 618, in send
    r = adapter.send(request, **kwargs)
  File "/usr/lib/python3.6/site-packages/requests/adapters.py", line 508, in send
    raise ConnectionError(e, request=request)
requests.exceptions.ConnectionError: HTTPSConnectionPool(host='api.spotify.com', port=443): Max retries exceeded with url: /v1/me/player (Caused by NewConnectionError('<urllib3.connection.VerifiedHTTPSConnection object at 0x726927f0>: Failed to establish a new connection: [Errno -3] Try again',))
2017-12-24 05:36:27 ERROR (MainThread) [homeassistant.helpers.entity] Update for media_player.spotify fails
Traceback (most recent call last):
  File "/usr/lib/python3.6/site-packages/urllib3/connection.py", line 141, in _new_conn
    (self.host, self.port), self.timeout, **extra_kw)
  File "/usr/lib/python3.6/site-packages/urllib3/util/connection.py", line 60, in create_connection
    for res in socket.getaddrinfo(host, port, family, socket.SOCK_STREAM):
  File "/usr/lib/python3.6/socket.py", line 745, in getaddrinfo
    for res in _socket.getaddrinfo(host, port, family, type, proto, flags):
socket.gaierror: [Errno -3] Try again

During handling of the above exception, another exception occurred:

Traceback (most recent call last):
  File "/usr/lib/python3.6/site-packages/urllib3/connectionpool.py", line 601, in urlopen
    chunked=chunked)
  File "/usr/lib/python3.6/site-packages/urllib3/connectionpool.py", line 346, in _make_request
    self._validate_conn(conn)
  File "/usr/lib/python3.6/site-packages/urllib3/connectionpool.py", line 850, in _validate_conn
    conn.connect()
  File "/usr/lib/python3.6/site-packages/urllib3/connection.py", line 284, in connect
    conn = self._new_conn()
  File "/usr/lib/python3.6/site-packages/urllib3/connection.py", line 150, in _new_conn
    self, "Failed to establish a new connection: %s" % e)
urllib3.exceptions.NewConnectionError: <urllib3.connection.VerifiedHTTPSConnection object at 0x7264df30>: Failed to establish a new connection: [Errno -3] Try again

During handling of the above exception, another exception occurred:

Traceback (most recent call last):
  File "/usr/lib/python3.6/site-packages/requests/adapters.py", line 440, in send
    timeout=timeout
  File "/usr/lib/python3.6/site-packages/urllib3/connectionpool.py", line 639, in urlopen
    _stacktrace=sys.exc_info()[2])
  File "/usr/lib/python3.6/site-packages/urllib3/util/retry.py", line 388, in increment
    raise MaxRetryError(_pool, url, error or ResponseError(cause))
urllib3.exceptions.MaxRetryError: HTTPSConnectionPool(host='api.spotify.com', port=443): Max retries exceeded with url: /v1/me/player/devices (Caused by NewConnectionError('<urllib3.connection.VerifiedHTTPSConnection object at 0x7264df30>: Failed to establish a new connection: [Errno -3] Try again',))

During handling of the above exception, another exception occurred:

Traceback (most recent call last):
  File "/usr/lib/python3.6/site-packages/homeassistant/helpers/entity.py", line 199, in async_update_ha_state
    yield from self.async_device_update()
  File "/usr/lib/python3.6/site-packages/homeassistant/helpers/entity.py", line 306, in async_device_update
    yield from self.hass.async_add_job(self.update)
  File "/usr/lib/python3.6/asyncio/futures.py", line 332, in __iter__
    yield self  # This tells Task to wait for completion.
  File "/usr/lib/python3.6/asyncio/tasks.py", line 250, in _wakeup
    future.result()
  File "/usr/lib/python3.6/asyncio/futures.py", line 245, in result
    raise self._exception
  File "/usr/lib/python3.6/concurrent/futures/thread.py", line 56, in run
    result = self.fn(*self.args, **self.kwargs)
  File "/usr/lib/python3.6/site-packages/homeassistant/components/media_player/spotify.py", line 172, in update
    player_devices = self._player.devices()
  File "/usr/lib/python3.6/site-packages/spotipy/client.py", line 848, in devices
    return self._get("me/player/devices")
  File "/usr/lib/python3.6/site-packages/spotipy/client.py", line 148, in _get
    return self._internal_call('GET', url, payload, kwargs)
  File "/usr/lib/python3.6/site-packages/spotipy/client.py", line 110, in _internal_call
    r = self._session.request(method, url, headers=headers, proxies=self.proxies, **args)
  File "/usr/lib/python3.6/site-packages/requests/sessions.py", line 508, in request
    resp = self.send(prep, **send_kwargs)
  File "/usr/lib/python3.6/site-packages/requests/sessions.py", line 618, in send
    r = adapter.send(request, **kwargs)
  File "/usr/lib/python3.6/site-packages/requests/adapters.py", line 508, in send
    raise ConnectionError(e, request=request)
requests.exceptions.ConnectionError: HTTPSConnectionPool(host='api.spotify.com', port=443): Max retries exceeded with url: /v1/me/player/devices (Caused by NewConnectionError('<urllib3.connection.VerifiedHTTPSConnection object at 0x7264df30>: Failed to establish a new connection: [Errno -3] Try again',))
2017-12-24 05:51:57 ERROR (MainThread) [homeassistant.helpers.entity] Update for media_player.spotify fails
Traceback (most recent call last):
  File "/usr/lib/python3.6/site-packages/urllib3/connection.py", line 141, in _new_conn
    (self.host, self.port), self.timeout, **extra_kw)
  File "/usr/lib/python3.6/site-packages/urllib3/util/connection.py", line 60, in create_connection
    for res in socket.getaddrinfo(host, port, family, socket.SOCK_STREAM):
  File "/usr/lib/python3.6/socket.py", line 745, in getaddrinfo
    for res in _socket.getaddrinfo(host, port, family, type, proto, flags):
socket.gaierror: [Errno -3] Try again

During handling of the above exception, another exception occurred:

Traceback (most recent call last):
  File "/usr/lib/python3.6/site-packages/urllib3/connectionpool.py", line 601, in urlopen
    chunked=chunked)
  File "/usr/lib/python3.6/site-packages/urllib3/connectionpool.py", line 346, in _make_request
    self._validate_conn(conn)
  File "/usr/lib/python3.6/site-packages/urllib3/connectionpool.py", line 850, in _validate_conn
    conn.connect()
  File "/usr/lib/python3.6/site-packages/urllib3/connection.py", line 284, in connect
    conn = self._new_conn()
  File "/usr/lib/python3.6/site-packages/urllib3/connection.py", line 150, in _new_conn
    self, "Failed to establish a new connection: %s" % e)
urllib3.exceptions.NewConnectionError: <urllib3.connection.VerifiedHTTPSConnection object at 0x726854d0>: Failed to establish a new connection: [Errno -3] Try again

During handling of the above exception, another exception occurred:

Traceback (most recent call last):
  File "/usr/lib/python3.6/site-packages/requests/adapters.py", line 440, in send
    timeout=timeout
  File "/usr/lib/python3.6/site-packages/urllib3/connectionpool.py", line 639, in urlopen
    _stacktrace=sys.exc_info()[2])
  File "/usr/lib/python3.6/site-packages/urllib3/util/retry.py", line 388, in increment
    raise MaxRetryError(_pool, url, error or ResponseError(cause))
urllib3.exceptions.MaxRetryError: HTTPSConnectionPool(host='api.spotify.com', port=443): Max retries exceeded with url: /v1/me/player/devices (Caused by NewConnectionError('<urllib3.connection.VerifiedHTTPSConnection object at 0x726854d0>: Failed to establish a new connection: [Errno -3] Try again',))

During handling of the above exception, another exception occurred:

Traceback (most recent call last):
  File "/usr/lib/python3.6/site-packages/homeassistant/helpers/entity.py", line 199, in async_update_ha_state
    yield from self.async_device_update()
  File "/usr/lib/python3.6/site-packages/homeassistant/helpers/entity.py", line 306, in async_device_update
    yield from self.hass.async_add_job(self.update)
  File "/usr/lib/python3.6/asyncio/futures.py", line 332, in __iter__
    yield self  # This tells Task to wait for completion.
  File "/usr/lib/python3.6/asyncio/tasks.py", line 250, in _wakeup
    future.result()
  File "/usr/lib/python3.6/asyncio/futures.py", line 245, in result
    raise self._exception
  File "/usr/lib/python3.6/concurrent/futures/thread.py", line 56, in run
    result = self.fn(*self.args, **self.kwargs)
  File "/usr/lib/python3.6/site-packages/homeassistant/components/media_player/spotify.py", line 172, in update
    player_devices = self._player.devices()
  File "/usr/lib/python3.6/site-packages/spotipy/client.py", line 848, in devices
    return self._get("me/player/devices")
  File "/usr/lib/python3.6/site-packages/spotipy/client.py", line 148, in _get
    return self._internal_call('GET', url, payload, kwargs)
  File "/usr/lib/python3.6/site-packages/spotipy/client.py", line 110, in _internal_call
    r = self._session.request(method, url, headers=headers, proxies=self.proxies, **args)
  File "/usr/lib/python3.6/site-packages/requests/sessions.py", line 508, in request
    resp = self.send(prep, **send_kwargs)
  File "/usr/lib/python3.6/site-packages/requests/sessions.py", line 618, in send
    r = adapter.send(request, **kwargs)
  File "/usr/lib/python3.6/site-packages/requests/adapters.py", line 508, in send
    raise ConnectionError(e, request=request)
requests.exceptions.ConnectionError: HTTPSConnectionPool(host='api.spotify.com', port=443): Max retries exceeded with url: /v1/me/player/devices (Caused by NewConnectionError('<urllib3.connection.VerifiedHTTPSConnection object at 0x726854d0>: Failed to establish a new connection: [Errno -3] Try again',))
2017-12-24 06:00:07 ERROR (SyncWorker_0) [homeassistant.components.sensor.speedtest] Error executing speedtest: Command '['/usr/bin/python3', '/usr/lib/python3.6/site-packages/speedtest.py', '--simple']' returned non-zero exit status 1.
2017-12-24 06:19:51 ERROR (MainThread) [homeassistant.helpers.entity] Update for media_player.spotify fails
Traceback (most recent call last):
  File "/usr/lib/python3.6/site-packages/urllib3/connection.py", line 141, in _new_conn
    (self.host, self.port), self.timeout, **extra_kw)
  File "/usr/lib/python3.6/site-packages/urllib3/util/connection.py", line 60, in create_connection
    for res in socket.getaddrinfo(host, port, family, socket.SOCK_STREAM):
  File "/usr/lib/python3.6/socket.py", line 745, in getaddrinfo
    for res in _socket.getaddrinfo(host, port, family, type, proto, flags):
socket.gaierror: [Errno -3] Try again

During handling of the above exception, another exception occurred:

Traceback (most recent call last):
  File "/usr/lib/python3.6/site-packages/urllib3/connectionpool.py", line 601, in urlopen
    chunked=chunked)
  File "/usr/lib/python3.6/site-packages/urllib3/connectionpool.py", line 346, in _make_request
    self._validate_conn(conn)
  File "/usr/lib/python3.6/site-packages/urllib3/connectionpool.py", line 850, in _validate_conn
    conn.connect()
  File "/usr/lib/python3.6/site-packages/urllib3/connection.py", line 284, in connect
    conn = self._new_conn()
  File "/usr/lib/python3.6/site-packages/urllib3/connection.py", line 150, in _new_conn
    self, "Failed to establish a new connection: %s" % e)
urllib3.exceptions.NewConnectionError: <urllib3.connection.VerifiedHTTPSConnection object at 0x726480b0>: Failed to establish a new connection: [Errno -3] Try again

During handling of the above exception, another exception occurred:

Traceback (most recent call last):
  File "/usr/lib/python3.6/site-packages/requests/adapters.py", line 440, in send
    timeout=timeout
  File "/usr/lib/python3.6/site-packages/urllib3/connectionpool.py", line 639, in urlopen
    _stacktrace=sys.exc_info()[2])
  File "/usr/lib/python3.6/site-packages/urllib3/util/retry.py", line 388, in increment
    raise MaxRetryError(_pool, url, error or ResponseError(cause))
urllib3.exceptions.MaxRetryError: HTTPSConnectionPool(host='api.spotify.com', port=443): Max retries exceeded with url: /v1/me/player/devices (Caused by NewConnectionError('<urllib3.connection.VerifiedHTTPSConnection object at 0x726480b0>: Failed to establish a new connection: [Errno -3] Try again',))

During handling of the above exception, another exception occurred:

Traceback (most recent call last):
  File "/usr/lib/python3.6/site-packages/homeassistant/helpers/entity.py", line 199, in async_update_ha_state
    yield from self.async_device_update()
  File "/usr/lib/python3.6/site-packages/homeassistant/helpers/entity.py", line 306, in async_device_update
    yield from self.hass.async_add_job(self.update)
  File "/usr/lib/python3.6/asyncio/futures.py", line 332, in __iter__
    yield self  # This tells Task to wait for completion.
  File "/usr/lib/python3.6/asyncio/tasks.py", line 250, in _wakeup
    future.result()
  File "/usr/lib/python3.6/asyncio/futures.py", line 245, in result
    raise self._exception
  File "/usr/lib/python3.6/concurrent/futures/thread.py", line 56, in run
    result = self.fn(*self.args, **self.kwargs)
  File "/usr/lib/python3.6/site-packages/homeassistant/components/media_player/spotify.py", line 172, in update
    player_devices = self._player.devices()
  File "/usr/lib/python3.6/site-packages/spotipy/client.py", line 848, in devices
    return self._get("me/player/devices")
  File "/usr/lib/python3.6/site-packages/spotipy/client.py", line 148, in _get
    return self._internal_call('GET', url, payload, kwargs)
  File "/usr/lib/python3.6/site-packages/spotipy/client.py", line 110, in _internal_call
    r = self._session.request(method, url, headers=headers, proxies=self.proxies, **args)
  File "/usr/lib/python3.6/site-packages/requests/sessions.py", line 508, in request
    resp = self.send(prep, **send_kwargs)
  File "/usr/lib/python3.6/site-packages/requests/sessions.py", line 618, in send
    r = adapter.send(request, **kwargs)
  File "/usr/lib/python3.6/site-packages/requests/adapters.py", line 508, in send
    raise ConnectionError(e, request=request)
requests.exceptions.ConnectionError: HTTPSConnectionPool(host='api.spotify.com', port=443): Max retries exceeded with url: /v1/me/player/devices (Caused by NewConnectionError('<urllib3.connection.VerifiedHTTPSConnection object at 0x726480b0>: Failed to establish a new connection: [Errno -3] Try again',))
2017-12-24 06:47:14 ERROR (MainThread) [homeassistant.helpers.entity] Update for media_player.spotify fails
Traceback (most recent call last):
  File "/usr/lib/python3.6/site-packages/urllib3/connection.py", line 141, in _new_conn
    (self.host, self.port), self.timeout, **extra_kw)
  File "/usr/lib/python3.6/site-packages/urllib3/util/connection.py", line 60, in create_connection
    for res in socket.getaddrinfo(host, port, family, socket.SOCK_STREAM):
  File "/usr/lib/python3.6/socket.py", line 745, in getaddrinfo
    for res in _socket.getaddrinfo(host, port, family, type, proto, flags):
socket.gaierror: [Errno -3] Try again

During handling of the above exception, another exception occurred:

Traceback (most recent call last):
  File "/usr/lib/python3.6/site-packages/urllib3/connectionpool.py", line 601, in urlopen
    chunked=chunked)
  File "/usr/lib/python3.6/site-packages/urllib3/connectionpool.py", line 346, in _make_request
    self._validate_conn(conn)
  File "/usr/lib/python3.6/site-packages/urllib3/connectionpool.py", line 850, in _validate_conn
    conn.connect()
  File "/usr/lib/python3.6/site-packages/urllib3/connection.py", line 284, in connect
    conn = self._new_conn()
  File "/usr/lib/python3.6/site-packages/urllib3/connection.py", line 150, in _new_conn
    self, "Failed to establish a new connection: %s" % e)
urllib3.exceptions.NewConnectionError: <urllib3.connection.VerifiedHTTPSConnection object at 0x72648f50>: Failed to establish a new connection: [Errno -3] Try again

During handling of the above exception, another exception occurred:

Traceback (most recent call last):
  File "/usr/lib/python3.6/site-packages/requests/adapters.py", line 440, in send
    timeout=timeout
  File "/usr/lib/python3.6/site-packages/urllib3/connectionpool.py", line 639, in urlopen
    _stacktrace=sys.exc_info()[2])
  File "/usr/lib/python3.6/site-packages/urllib3/util/retry.py", line 388, in increment
    raise MaxRetryError(_pool, url, error or ResponseError(cause))
urllib3.exceptions.MaxRetryError: HTTPSConnectionPool(host='api.spotify.com', port=443): Max retries exceeded with url: /v1/me/player/devices (Caused by NewConnectionError('<urllib3.connection.VerifiedHTTPSConnection object at 0x72648f50>: Failed to establish a new connection: [Errno -3] Try again',))

During handling of the above exception, another exception occurred:

Traceback (most recent call last):
  File "/usr/lib/python3.6/site-packages/homeassistant/helpers/entity.py", line 199, in async_update_ha_state
    yield from self.async_device_update()
  File "/usr/lib/python3.6/site-packages/homeassistant/helpers/entity.py", line 306, in async_device_update
    yield from self.hass.async_add_job(self.update)
  File "/usr/lib/python3.6/asyncio/futures.py", line 332, in __iter__
    yield self  # This tells Task to wait for completion.
  File "/usr/lib/python3.6/asyncio/tasks.py", line 250, in _wakeup
    future.result()
  File "/usr/lib/python3.6/asyncio/futures.py", line 245, in result
    raise self._exception
  File "/usr/lib/python3.6/concurrent/futures/thread.py", line 56, in run
    result = self.fn(*self.args, **self.kwargs)
  File "/usr/lib/python3.6/site-packages/homeassistant/components/media_player/spotify.py", line 172, in update
    player_devices = self._player.devices()
  File "/usr/lib/python3.6/site-packages/spotipy/client.py", line 848, in devices
    return self._get("me/player/devices")
  File "/usr/lib/python3.6/site-packages/spotipy/client.py", line 148, in _get
    return self._internal_call('GET', url, payload, kwargs)
  File "/usr/lib/python3.6/site-packages/spotipy/client.py", line 110, in _internal_call
    r = self._session.request(method, url, headers=headers, proxies=self.proxies, **args)
  File "/usr/lib/python3.6/site-packages/requests/sessions.py", line 508, in request
    resp = self.send(prep, **send_kwargs)
  File "/usr/lib/python3.6/site-packages/requests/sessions.py", line 618, in send
    r = adapter.send(request, **kwargs)
  File "/usr/lib/python3.6/site-packages/requests/adapters.py", line 508, in send
    raise ConnectionError(e, request=request)
requests.exceptions.ConnectionError: HTTPSConnectionPool(host='api.spotify.com', port=443): Max retries exceeded with url: /v1/me/player/devices (Caused by NewConnectionError('<urllib3.connection.VerifiedHTTPSConnection object at 0x72648f50>: Failed to establish a new connection: [Errno -3] Try again',))
2017-12-24 06:49:18 ERROR (MainThread) [homeassistant.helpers.entity] Update for media_player.spotify fails
Traceback (most recent call last):
  File "/usr/lib/python3.6/site-packages/urllib3/connection.py", line 141, in _new_conn
    (self.host, self.port), self.timeout, **extra_kw)
  File "/usr/lib/python3.6/site-packages/urllib3/util/connection.py", line 60, in create_connection
    for res in socket.getaddrinfo(host, port, family, socket.SOCK_STREAM):
  File "/usr/lib/python3.6/socket.py", line 745, in getaddrinfo
    for res in _socket.getaddrinfo(host, port, family, type, proto, flags):
socket.gaierror: [Errno -3] Try again

During handling of the above exception, another exception occurred:

Traceback (most recent call last):
  File "/usr/lib/python3.6/site-packages/urllib3/connectionpool.py", line 601, in urlopen
    chunked=chunked)
  File "/usr/lib/python3.6/site-packages/urllib3/connectionpool.py", line 346, in _make_request
    self._validate_conn(conn)
  File "/usr/lib/python3.6/site-packages/urllib3/connectionpool.py", line 850, in _validate_conn
    conn.connect()
  File "/usr/lib/python3.6/site-packages/urllib3/connection.py", line 284, in connect
    conn = self._new_conn()
  File "/usr/lib/python3.6/site-packages/urllib3/connection.py", line 150, in _new_conn
    self, "Failed to establish a new connection: %s" % e)
urllib3.exceptions.NewConnectionError: <urllib3.connection.VerifiedHTTPSConnection object at 0x72640410>: Failed to establish a new connection: [Errno -3] Try again

During handling of the above exception, another exception occurred:

Traceback (most recent call last):
  File "/usr/lib/python3.6/site-packages/requests/adapters.py", line 440, in send
    timeout=timeout
  File "/usr/lib/python3.6/site-packages/urllib3/connectionpool.py", line 639, in urlopen
    _stacktrace=sys.exc_info()[2])
  File "/usr/lib/python3.6/site-packages/urllib3/util/retry.py", line 388, in increment
    raise MaxRetryError(_pool, url, error or ResponseError(cause))
urllib3.exceptions.MaxRetryError: HTTPSConnectionPool(host='api.spotify.com', port=443): Max retries exceeded with url: /v1/me/player/devices (Caused by NewConnectionError('<urllib3.connection.VerifiedHTTPSConnection object at 0x72640410>: Failed to establish a new connection: [Errno -3] Try again',))

During handling of the above exception, another exception occurred:

Traceback (most recent call last):
  File "/usr/lib/python3.6/site-packages/homeassistant/helpers/entity.py", line 199, in async_update_ha_state
    yield from self.async_device_update()
  File "/usr/lib/python3.6/site-packages/homeassistant/helpers/entity.py", line 306, in async_device_update
    yield from self.hass.async_add_job(self.update)
  File "/usr/lib/python3.6/asyncio/futures.py", line 332, in __iter__
    yield self  # This tells Task to wait for completion.
  File "/usr/lib/python3.6/asyncio/tasks.py", line 250, in _wakeup
    future.result()
  File "/usr/lib/python3.6/asyncio/futures.py", line 245, in result
    raise self._exception
  File "/usr/lib/python3.6/concurrent/futures/thread.py", line 56, in run
    result = self.fn(*self.args, **self.kwargs)
  File "/usr/lib/python3.6/site-packages/homeassistant/components/media_player/spotify.py", line 172, in update
    player_devices = self._player.devices()
  File "/usr/lib/python3.6/site-packages/spotipy/client.py", line 848, in devices
    return self._get("me/player/devices")
  File "/usr/lib/python3.6/site-packages/spotipy/client.py", line 148, in _get
    return self._internal_call('GET', url, payload, kwargs)
  File "/usr/lib/python3.6/site-packages/spotipy/client.py", line 110, in _internal_call
    r = self._session.request(method, url, headers=headers, proxies=self.proxies, **args)
  File "/usr/lib/python3.6/site-packages/requests/sessions.py", line 508, in request
    resp = self.send(prep, **send_kwargs)
  File "/usr/lib/python3.6/site-packages/requests/sessions.py", line 618, in send
    r = adapter.send(request, **kwargs)
  File "/usr/lib/python3.6/site-packages/requests/adapters.py", line 508, in send
    raise ConnectionError(e, request=request)
requests.exceptions.ConnectionError: HTTPSConnectionPool(host='api.spotify.com', port=443): Max retries exceeded with url: /v1/me/player/devices (Caused by NewConnectionError('<urllib3.connection.VerifiedHTTPSConnection object at 0x72640410>: Failed to establish a new connection: [Errno -3] Try again',))
2017-12-24 07:19:02 ERROR (SyncWorker_19) [homeassistant.components.sensor.wunderground] Error fetching WUnderground data: ConnectionError(MaxRetryError("HTTPConnectionPool(host='api.wunderground.com', port=80): Max retries exceeded with url: /api/af39e8e94f6eae72/forecast/conditions/lang:EN/q/-25.451,-49.343.json (Caused by NewConnectionError('<urllib3.connection.HTTPConnection object at 0x72685290>: Failed to establish a new connection: [Errno -3] Try again',))",),)
2017-12-24 07:29:06 ERROR (MainThread) [homeassistant.helpers.entity] Update for media_player.spotify fails
Traceback (most recent call last):
  File "/usr/lib/python3.6/site-packages/urllib3/connection.py", line 141, in _new_conn
    (self.host, self.port), self.timeout, **extra_kw)
  File "/usr/lib/python3.6/site-packages/urllib3/util/connection.py", line 60, in create_connection
    for res in socket.getaddrinfo(host, port, family, socket.SOCK_STREAM):
  File "/usr/lib/python3.6/socket.py", line 745, in getaddrinfo
    for res in _socket.getaddrinfo(host, port, family, type, proto, flags):
socket.gaierror: [Errno -3] Try again

During handling of the above exception, another exception occurred:

Traceback (most recent call last):
  File "/usr/lib/python3.6/site-packages/urllib3/connectionpool.py", line 601, in urlopen
    chunked=chunked)
  File "/usr/lib/python3.6/site-packages/urllib3/connectionpool.py", line 346, in _make_request
    self._validate_conn(conn)
  File "/usr/lib/python3.6/site-packages/urllib3/connectionpool.py", line 850, in _validate_conn
    conn.connect()
  File "/usr/lib/python3.6/site-packages/urllib3/connection.py", line 284, in connect
    conn = self._new_conn()
  File "/usr/lib/python3.6/site-packages/urllib3/connection.py", line 150, in _new_conn
    self, "Failed to establish a new connection: %s" % e)
urllib3.exceptions.NewConnectionError: <urllib3.connection.VerifiedHTTPSConnection object at 0x726738b0>: Failed to establish a new connection: [Errno -3] Try again

During handling of the above exception, another exception occurred:

Traceback (most recent call last):
  File "/usr/lib/python3.6/site-packages/requests/adapters.py", line 440, in send
    timeout=timeout
  File "/usr/lib/python3.6/site-packages/urllib3/connectionpool.py", line 639, in urlopen
    _stacktrace=sys.exc_info()[2])
  File "/usr/lib/python3.6/site-packages/urllib3/util/retry.py", line 388, in increment
    raise MaxRetryError(_pool, url, error or ResponseError(cause))
urllib3.exceptions.MaxRetryError: HTTPSConnectionPool(host='api.spotify.com', port=443): Max retries exceeded with url: /v1/me/player (Caused by NewConnectionError('<urllib3.connection.VerifiedHTTPSConnection object at 0x726738b0>: Failed to establish a new connection: [Errno -3] Try again',))

During handling of the above exception, another exception occurred:

Traceback (most recent call last):
  File "/usr/lib/python3.6/site-packages/homeassistant/helpers/entity.py", line 199, in async_update_ha_state
    yield from self.async_device_update()
  File "/usr/lib/python3.6/site-packages/homeassistant/helpers/entity.py", line 306, in async_device_update
    yield from self.hass.async_add_job(self.update)
  File "/usr/lib/python3.6/asyncio/futures.py", line 332, in __iter__
    yield self  # This tells Task to wait for completion.
  File "/usr/lib/python3.6/asyncio/tasks.py", line 250, in _wakeup
    future.result()
  File "/usr/lib/python3.6/asyncio/futures.py", line 245, in result
    raise self._exception
  File "/usr/lib/python3.6/concurrent/futures/thread.py", line 56, in run
    result = self.fn(*self.args, **self.kwargs)
  File "/usr/lib/python3.6/site-packages/homeassistant/components/media_player/spotify.py", line 186, in update
    current = self._player.current_playback()
  File "/usr/lib/python3.6/site-packages/spotipy/client.py", line 856, in current_playback
    return self._get("me/player", market = market)
  File "/usr/lib/python3.6/site-packages/spotipy/client.py", line 148, in _get
    return self._internal_call('GET', url, payload, kwargs)
  File "/usr/lib/python3.6/site-packages/spotipy/client.py", line 110, in _internal_call
    r = self._session.request(method, url, headers=headers, proxies=self.proxies, **args)
  File "/usr/lib/python3.6/site-packages/requests/sessions.py", line 508, in request
    resp = self.send(prep, **send_kwargs)
  File "/usr/lib/python3.6/site-packages/requests/sessions.py", line 618, in send
    r = adapter.send(request, **kwargs)
  File "/usr/lib/python3.6/site-packages/requests/adapters.py", line 508, in send
    raise ConnectionError(e, request=request)
requests.exceptions.ConnectionError: HTTPSConnectionPool(host='api.spotify.com', port=443): Max retries exceeded with url: /v1/me/player (Caused by NewConnectionError('<urllib3.connection.VerifiedHTTPSConnection object at 0x726738b0>: Failed to establish a new connection: [Errno -3] Try again',))
2017-12-24 07:53:23 ERROR (MainThread) [homeassistant.helpers.entity] Update for media_player.spotify fails
Traceback (most recent call last):
  File "/usr/lib/python3.6/site-packages/urllib3/connection.py", line 141, in _new_conn
    (self.host, self.port), self.timeout, **extra_kw)
  File "/usr/lib/python3.6/site-packages/urllib3/util/connection.py", line 60, in create_connection
    for res in socket.getaddrinfo(host, port, family, socket.SOCK_STREAM):
  File "/usr/lib/python3.6/socket.py", line 745, in getaddrinfo
    for res in _socket.getaddrinfo(host, port, family, type, proto, flags):
socket.gaierror: [Errno -3] Try again

During handling of the above exception, another exception occurred:

Traceback (most recent call last):
  File "/usr/lib/python3.6/site-packages/urllib3/connectionpool.py", line 601, in urlopen
    chunked=chunked)
  File "/usr/lib/python3.6/site-packages/urllib3/connectionpool.py", line 346, in _make_request
    self._validate_conn(conn)
  File "/usr/lib/python3.6/site-packages/urllib3/connectionpool.py", line 850, in _validate_conn
    conn.connect()
  File "/usr/lib/python3.6/site-packages/urllib3/connection.py", line 284, in connect
    conn = self._new_conn()
  File "/usr/lib/python3.6/site-packages/urllib3/connection.py", line 150, in _new_conn
    self, "Failed to establish a new connection: %s" % e)
urllib3.exceptions.NewConnectionError: <urllib3.connection.VerifiedHTTPSConnection object at 0x72669e50>: Failed to establish a new connection: [Errno -3] Try again

During handling of the above exception, another exception occurred:

Traceback (most recent call last):
  File "/usr/lib/python3.6/site-packages/requests/adapters.py", line 440, in send
    timeout=timeout
  File "/usr/lib/python3.6/site-packages/urllib3/connectionpool.py", line 639, in urlopen
    _stacktrace=sys.exc_info()[2])
  File "/usr/lib/python3.6/site-packages/urllib3/util/retry.py", line 388, in increment
    raise MaxRetryError(_pool, url, error or ResponseError(cause))
urllib3.exceptions.MaxRetryError: HTTPSConnectionPool(host='api.spotify.com', port=443): Max retries exceeded with url: /v1/me/player (Caused by NewConnectionError('<urllib3.connection.VerifiedHTTPSConnection object at 0x72669e50>: Failed to establish a new connection: [Errno -3] Try again',))

During handling of the above exception, another exception occurred:

Traceback (most recent call last):
  File "/usr/lib/python3.6/site-packages/homeassistant/helpers/entity.py", line 199, in async_update_ha_state
    yield from self.async_device_update()
  File "/usr/lib/python3.6/site-packages/homeassistant/helpers/entity.py", line 306, in async_device_update
    yield from self.hass.async_add_job(self.update)
  File "/usr/lib/python3.6/asyncio/futures.py", line 332, in __iter__
    yield self  # This tells Task to wait for completion.
  File "/usr/lib/python3.6/asyncio/tasks.py", line 250, in _wakeup
    future.result()
  File "/usr/lib/python3.6/asyncio/futures.py", line 245, in result
    raise self._exception
  File "/usr/lib/python3.6/concurrent/futures/thread.py", line 56, in run
    result = self.fn(*self.args, **self.kwargs)
  File "/usr/lib/python3.6/site-packages/homeassistant/components/media_player/spotify.py", line 186, in update
    current = self._player.current_playback()
  File "/usr/lib/python3.6/site-packages/spotipy/client.py", line 856, in current_playback
    return self._get("me/player", market = market)
  File "/usr/lib/python3.6/site-packages/spotipy/client.py", line 148, in _get
    return self._internal_call('GET', url, payload, kwargs)
  File "/usr/lib/python3.6/site-packages/spotipy/client.py", line 110, in _internal_call
    r = self._session.request(method, url, headers=headers, proxies=self.proxies, **args)
  File "/usr/lib/python3.6/site-packages/requests/sessions.py", line 508, in request
    resp = self.send(prep, **send_kwargs)
  File "/usr/lib/python3.6/site-packages/requests/sessions.py", line 618, in send
    r = adapter.send(request, **kwargs)
  File "/usr/lib/python3.6/site-packages/requests/adapters.py", line 508, in send
    raise ConnectionError(e, request=request)
requests.exceptions.ConnectionError: HTTPSConnectionPool(host='api.spotify.com', port=443): Max retries exceeded with url: /v1/me/player (Caused by NewConnectionError('<urllib3.connection.VerifiedHTTPSConnection object at 0x72669e50>: Failed to establish a new connection: [Errno -3] Try again',))
2017-12-24 08:00:05 ERROR (MainThread) [homeassistant.helpers.entity] Update for media_player.spotify fails
Traceback (most recent call last):
  File "/usr/lib/python3.6/site-packages/urllib3/connection.py", line 141, in _new_conn
    (self.host, self.port), self.timeout, **extra_kw)
  File "/usr/lib/python3.6/site-packages/urllib3/util/connection.py", line 60, in create_connection
    for res in socket.getaddrinfo(host, port, family, socket.SOCK_STREAM):
  File "/usr/lib/python3.6/socket.py", line 745, in getaddrinfo
    for res in _socket.getaddrinfo(host, port, family, type, proto, flags):
socket.gaierror: [Errno -3] Try again

During handling of the above exception, another exception occurred:

Traceback (most recent call last):
  File "/usr/lib/python3.6/site-packages/urllib3/connectionpool.py", line 601, in urlopen
    chunked=chunked)
  File "/usr/lib/python3.6/site-packages/urllib3/connectionpool.py", line 346, in _make_request
    self._validate_conn(conn)
  File "/usr/lib/python3.6/site-packages/urllib3/connectionpool.py", line 850, in _validate_conn
    conn.connect()
  File "/usr/lib/python3.6/site-packages/urllib3/connection.py", line 284, in connect
    conn = self._new_conn()
  File "/usr/lib/python3.6/site-packages/urllib3/connection.py", line 150, in _new_conn
    self, "Failed to establish a new connection: %s" % e)
urllib3.exceptions.NewConnectionError: <urllib3.connection.VerifiedHTTPSConnection object at 0x726692f0>: Failed to establish a new connection: [Errno -3] Try again

During handling of the above exception, another exception occurred:

Traceback (most recent call last):
  File "/usr/lib/python3.6/site-packages/requests/adapters.py", line 440, in send
    timeout=timeout
  File "/usr/lib/python3.6/site-packages/urllib3/connectionpool.py", line 639, in urlopen
    _stacktrace=sys.exc_info()[2])
  File "/usr/lib/python3.6/site-packages/urllib3/util/retry.py", line 388, in increment
    raise MaxRetryError(_pool, url, error or ResponseError(cause))
urllib3.exceptions.MaxRetryError: HTTPSConnectionPool(host='api.spotify.com', port=443): Max retries exceeded with url: /v1/me/player/devices (Caused by NewConnectionError('<urllib3.connection.VerifiedHTTPSConnection object at 0x726692f0>: Failed to establish a new connection: [Errno -3] Try again',))

During handling of the above exception, another exception occurred:

Traceback (most recent call last):
  File "/usr/lib/python3.6/site-packages/homeassistant/helpers/entity.py", line 199, in async_update_ha_state
    yield from self.async_device_update()
  File "/usr/lib/python3.6/site-packages/homeassistant/helpers/entity.py", line 306, in async_device_update
    yield from self.hass.async_add_job(self.update)
  File "/usr/lib/python3.6/asyncio/futures.py", line 332, in __iter__
    yield self  # This tells Task to wait for completion.
  File "/usr/lib/python3.6/asyncio/tasks.py", line 250, in _wakeup
    future.result()
  File "/usr/lib/python3.6/asyncio/futures.py", line 245, in result
    raise self._exception
  File "/usr/lib/python3.6/concurrent/futures/thread.py", line 56, in run
    result = self.fn(*self.args, **self.kwargs)
  File "/usr/lib/python3.6/site-packages/homeassistant/components/media_player/spotify.py", line 172, in update
    player_devices = self._player.devices()
  File "/usr/lib/python3.6/site-packages/spotipy/client.py", line 848, in devices
    return self._get("me/player/devices")
  File "/usr/lib/python3.6/site-packages/spotipy/client.py", line 148, in _get
    return self._internal_call('GET', url, payload, kwargs)
  File "/usr/lib/python3.6/site-packages/spotipy/client.py", line 110, in _internal_call
    r = self._session.request(method, url, headers=headers, proxies=self.proxies, **args)
  File "/usr/lib/python3.6/site-packages/requests/sessions.py", line 508, in request
    resp = self.send(prep, **send_kwargs)
  File "/usr/lib/python3.6/site-packages/requests/sessions.py", line 618, in send
    r = adapter.send(request, **kwargs)
  File "/usr/lib/python3.6/site-packages/requests/adapters.py", line 508, in send
    raise ConnectionError(e, request=request)
requests.exceptions.ConnectionError: HTTPSConnectionPool(host='api.spotify.com', port=443): Max retries exceeded with url: /v1/me/player/devices (Caused by NewConnectionError('<urllib3.connection.VerifiedHTTPSConnection object at 0x726692f0>: Failed to establish a new connection: [Errno -3] Try again',))
2017-12-24 08:03:43 ERROR (MainThread) [homeassistant.helpers.entity] Update for media_player.spotify fails
Traceback (most recent call last):
  File "/usr/lib/python3.6/site-packages/urllib3/connection.py", line 141, in _new_conn
    (self.host, self.port), self.timeout, **extra_kw)
  File "/usr/lib/python3.6/site-packages/urllib3/util/connection.py", line 60, in create_connection
    for res in socket.getaddrinfo(host, port, family, socket.SOCK_STREAM):
  File "/usr/lib/python3.6/socket.py", line 745, in getaddrinfo
    for res in _socket.getaddrinfo(host, port, family, type, proto, flags):
socket.gaierror: [Errno -3] Try again

During handling of the above exception, another exception occurred:

Traceback (most recent call last):
  File "/usr/lib/python3.6/site-packages/urllib3/connectionpool.py", line 601, in urlopen
    chunked=chunked)
  File "/usr/lib/python3.6/site-packages/urllib3/connectionpool.py", line 346, in _make_request
    self._validate_conn(conn)
  File "/usr/lib/python3.6/site-packages/urllib3/connectionpool.py", line 850, in _validate_conn
    conn.connect()
  File "/usr/lib/python3.6/site-packages/urllib3/connection.py", line 284, in connect
    conn = self._new_conn()
  File "/usr/lib/python3.6/site-packages/urllib3/connection.py", line 150, in _new_conn
    self, "Failed to establish a new connection: %s" % e)
urllib3.exceptions.NewConnectionError: <urllib3.connection.VerifiedHTTPSConnection object at 0x72673b30>: Failed to establish a new connection: [Errno -3] Try again

During handling of the above exception, another exception occurred:

Traceback (most recent call last):
  File "/usr/lib/python3.6/site-packages/requests/adapters.py", line 440, in send
    timeout=timeout
  File "/usr/lib/python3.6/site-packages/urllib3/connectionpool.py", line 639, in urlopen
    _stacktrace=sys.exc_info()[2])
  File "/usr/lib/python3.6/site-packages/urllib3/util/retry.py", line 388, in increment
    raise MaxRetryError(_pool, url, error or ResponseError(cause))
urllib3.exceptions.MaxRetryError: HTTPSConnectionPool(host='api.spotify.com', port=443): Max retries exceeded with url: /v1/me/player (Caused by NewConnectionError('<urllib3.connection.VerifiedHTTPSConnection object at 0x72673b30>: Failed to establish a new connection: [Errno -3] Try again',))

During handling of the above exception, another exception occurred:

Traceback (most recent call last):
  File "/usr/lib/python3.6/site-packages/homeassistant/helpers/entity.py", line 199, in async_update_ha_state
    yield from self.async_device_update()
  File "/usr/lib/python3.6/site-packages/homeassistant/helpers/entity.py", line 306, in async_device_update
    yield from self.hass.async_add_job(self.update)
  File "/usr/lib/python3.6/asyncio/futures.py", line 332, in __iter__
    yield self  # This tells Task to wait for completion.
  File "/usr/lib/python3.6/asyncio/tasks.py", line 250, in _wakeup
    future.result()
  File "/usr/lib/python3.6/asyncio/futures.py", line 245, in result
    raise self._exception
  File "/usr/lib/python3.6/concurrent/futures/thread.py", line 56, in run
    result = self.fn(*self.args, **self.kwargs)
  File "/usr/lib/python3.6/site-packages/homeassistant/components/media_player/spotify.py", line 186, in update
    current = self._player.current_playback()
  File "/usr/lib/python3.6/site-packages/spotipy/client.py", line 856, in current_playback
    return self._get("me/player", market = market)
  File "/usr/lib/python3.6/site-packages/spotipy/client.py", line 148, in _get
    return self._internal_call('GET', url, payload, kwargs)
  File "/usr/lib/python3.6/site-packages/spotipy/client.py", line 110, in _internal_call
    r = self._session.request(method, url, headers=headers, proxies=self.proxies, **args)
  File "/usr/lib/python3.6/site-packages/requests/sessions.py", line 508, in request
    resp = self.send(prep, **send_kwargs)
  File "/usr/lib/python3.6/site-packages/requests/sessions.py", line 618, in send
    r = adapter.send(request, **kwargs)
  File "/usr/lib/python3.6/site-packages/requests/adapters.py", line 508, in send
    raise ConnectionError(e, request=request)
requests.exceptions.ConnectionError: HTTPSConnectionPool(host='api.spotify.com', port=443): Max retries exceeded with url: /v1/me/player (Caused by NewConnectionError('<urllib3.connection.VerifiedHTTPSConnection object at 0x72673b30>: Failed to establish a new connection: [Errno -3] Try again',))
2017-12-24 08:27:28 ERROR (MainThread) [homeassistant.helpers.entity] Update for media_player.spotify fails
Traceback (most recent call last):
  File "/usr/lib/python3.6/site-packages/urllib3/connection.py", line 141, in _new_conn
    (self.host, self.port), self.timeout, **extra_kw)
  File "/usr/lib/python3.6/site-packages/urllib3/util/connection.py", line 60, in create_connection
    for res in socket.getaddrinfo(host, port, family, socket.SOCK_STREAM):
  File "/usr/lib/python3.6/socket.py", line 745, in getaddrinfo
    for res in _socket.getaddrinfo(host, port, family, type, proto, flags):
socket.gaierror: [Errno -3] Try again

During handling of the above exception, another exception occurred:

Traceback (most recent call last):
  File "/usr/lib/python3.6/site-packages/urllib3/connectionpool.py", line 601, in urlopen
    chunked=chunked)
  File "/usr/lib/python3.6/site-packages/urllib3/connectionpool.py", line 346, in _make_request
    self._validate_conn(conn)
  File "/usr/lib/python3.6/site-packages/urllib3/connectionpool.py", line 850, in _validate_conn
    conn.connect()
  File "/usr/lib/python3.6/site-packages/urllib3/connection.py", line 284, in connect
    conn = self._new_conn()
  File "/usr/lib/python3.6/site-packages/urllib3/connection.py", line 150, in _new_conn
    self, "Failed to establish a new connection: %s" % e)
urllib3.exceptions.NewConnectionError: <urllib3.connection.VerifiedHTTPSConnection object at 0x726ca550>: Failed to establish a new connection: [Errno -3] Try again

During handling of the above exception, another exception occurred:

Traceback (most recent call last):
  File "/usr/lib/python3.6/site-packages/requests/adapters.py", line 440, in send
    timeout=timeout
  File "/usr/lib/python3.6/site-packages/urllib3/connectionpool.py", line 639, in urlopen
    _stacktrace=sys.exc_info()[2])
  File "/usr/lib/python3.6/site-packages/urllib3/util/retry.py", line 388, in increment
    raise MaxRetryError(_pool, url, error or ResponseError(cause))
urllib3.exceptions.MaxRetryError: HTTPSConnectionPool(host='api.spotify.com', port=443): Max retries exceeded with url: /v1/me/player/devices (Caused by NewConnectionError('<urllib3.connection.VerifiedHTTPSConnection object at 0x726ca550>: Failed to establish a new connection: [Errno -3] Try again',))

During handling of the above exception, another exception occurred:

Traceback (most recent call last):
  File "/usr/lib/python3.6/site-packages/homeassistant/helpers/entity.py", line 199, in async_update_ha_state
    yield from self.async_device_update()
  File "/usr/lib/python3.6/site-packages/homeassistant/helpers/entity.py", line 306, in async_device_update
    yield from self.hass.async_add_job(self.update)
  File "/usr/lib/python3.6/asyncio/futures.py", line 332, in __iter__
    yield self  # This tells Task to wait for completion.
  File "/usr/lib/python3.6/asyncio/tasks.py", line 250, in _wakeup
    future.result()
  File "/usr/lib/python3.6/asyncio/futures.py", line 245, in result
    raise self._exception
  File "/usr/lib/python3.6/concurrent/futures/thread.py", line 56, in run
    result = self.fn(*self.args, **self.kwargs)
  File "/usr/lib/python3.6/site-packages/homeassistant/components/media_player/spotify.py", line 172, in update
    player_devices = self._player.devices()
  File "/usr/lib/python3.6/site-packages/spotipy/client.py", line 848, in devices
    return self._get("me/player/devices")
  File "/usr/lib/python3.6/site-packages/spotipy/client.py", line 148, in _get
    return self._internal_call('GET', url, payload, kwargs)
  File "/usr/lib/python3.6/site-packages/spotipy/client.py", line 110, in _internal_call
    r = self._session.request(method, url, headers=headers, proxies=self.proxies, **args)
  File "/usr/lib/python3.6/site-packages/requests/sessions.py", line 508, in request
    resp = self.send(prep, **send_kwargs)
  File "/usr/lib/python3.6/site-packages/requests/sessions.py", line 618, in send
    r = adapter.send(request, **kwargs)
  File "/usr/lib/python3.6/site-packages/requests/adapters.py", line 508, in send
    raise ConnectionError(e, request=request)
requests.exceptions.ConnectionError: HTTPSConnectionPool(host='api.spotify.com', port=443): Max retries exceeded with url: /v1/me/player/devices (Caused by NewConnectionError('<urllib3.connection.VerifiedHTTPSConnection object at 0x726ca550>: Failed to establish a new connection: [Errno -3] Try again',))
2017-12-24 08:32:43 WARNING (MainThread) [haffmpeg.tools] Timeout reading image.
2017-12-24 08:33:02 WARNING (MainThread) [haffmpeg.tools] Timeout reading image.
2017-12-24 08:34:11 ERROR (MainThread) [homeassistant.helpers.entity] Update for media_player.spotify fails
Traceback (most recent call last):
  File "/usr/lib/python3.6/site-packages/urllib3/connection.py", line 141, in _new_conn
    (self.host, self.port), self.timeout, **extra_kw)
  File "/usr/lib/python3.6/site-packages/urllib3/util/connection.py", line 60, in create_connection
    for res in socket.getaddrinfo(host, port, family, socket.SOCK_STREAM):
  File "/usr/lib/python3.6/socket.py", line 745, in getaddrinfo
    for res in _socket.getaddrinfo(host, port, family, type, proto, flags):
socket.gaierror: [Errno -3] Try again

During handling of the above exception, another exception occurred:

Traceback (most recent call last):
  File "/usr/lib/python3.6/site-packages/urllib3/connectionpool.py", line 601, in urlopen
    chunked=chunked)
  File "/usr/lib/python3.6/site-packages/urllib3/connectionpool.py", line 346, in _make_request
    self._validate_conn(conn)
  File "/usr/lib/python3.6/site-packages/urllib3/connectionpool.py", line 850, in _validate_conn
    conn.connect()
  File "/usr/lib/python3.6/site-packages/urllib3/connection.py", line 284, in connect
    conn = self._new_conn()
  File "/usr/lib/python3.6/site-packages/urllib3/connection.py", line 150, in _new_conn
    self, "Failed to establish a new connection: %s" % e)
urllib3.exceptions.NewConnectionError: <urllib3.connection.VerifiedHTTPSConnection object at 0x72616170>: Failed to establish a new connection: [Errno -3] Try again

During handling of the above exception, another exception occurred:

Traceback (most recent call last):
  File "/usr/lib/python3.6/site-packages/requests/adapters.py", line 440, in send
    timeout=timeout
  File "/usr/lib/python3.6/site-packages/urllib3/connectionpool.py", line 639, in urlopen
    _stacktrace=sys.exc_info()[2])
  File "/usr/lib/python3.6/site-packages/urllib3/util/retry.py", line 388, in increment
    raise MaxRetryError(_pool, url, error or ResponseError(cause))
urllib3.exceptions.MaxRetryError: HTTPSConnectionPool(host='api.spotify.com', port=443): Max retries exceeded with url: /v1/me/player/devices (Caused by NewConnectionError('<urllib3.connection.VerifiedHTTPSConnection object at 0x72616170>: Failed to establish a new connection: [Errno -3] Try again',))

During handling of the above exception, another exception occurred:

Traceback (most recent call last):
  File "/usr/lib/python3.6/site-packages/homeassistant/helpers/entity.py", line 199, in async_update_ha_state
    yield from self.async_device_update()
  File "/usr/lib/python3.6/site-packages/homeassistant/helpers/entity.py", line 306, in async_device_update
    yield from self.hass.async_add_job(self.update)
  File "/usr/lib/python3.6/asyncio/futures.py", line 332, in __iter__
    yield self  # This tells Task to wait for completion.
  File "/usr/lib/python3.6/asyncio/tasks.py", line 250, in _wakeup
    future.result()
  File "/usr/lib/python3.6/asyncio/futures.py", line 245, in result
    raise self._exception
  File "/usr/lib/python3.6/concurrent/futures/thread.py", line 56, in run
    result = self.fn(*self.args, **self.kwargs)
  File "/usr/lib/python3.6/site-packages/homeassistant/components/media_player/spotify.py", line 172, in update
    player_devices = self._player.devices()
  File "/usr/lib/python3.6/site-packages/spotipy/client.py", line 848, in devices
    return self._get("me/player/devices")
  File "/usr/lib/python3.6/site-packages/spotipy/client.py", line 148, in _get
    return self._internal_call('GET', url, payload, kwargs)
  File "/usr/lib/python3.6/site-packages/spotipy/client.py", line 110, in _internal_call
    r = self._session.request(method, url, headers=headers, proxies=self.proxies, **args)
  File "/usr/lib/python3.6/site-packages/requests/sessions.py", line 508, in request
    resp = self.send(prep, **send_kwargs)
  File "/usr/lib/python3.6/site-packages/requests/sessions.py", line 618, in send
    r = adapter.send(request, **kwargs)
  File "/usr/lib/python3.6/site-packages/requests/adapters.py", line 508, in send
    raise ConnectionError(e, request=request)
requests.exceptions.ConnectionError: HTTPSConnectionPool(host='api.spotify.com', port=443): Max retries exceeded with url: /v1/me/player/devices (Caused by NewConnectionError('<urllib3.connection.VerifiedHTTPSConnection object at 0x72616170>: Failed to establish a new connection: [Errno -3] Try again',))
2017-12-24 08:38:20 ERROR (MainThread) [homeassistant.helpers.entity] Update for media_player.spotify fails
Traceback (most recent call last):
  File "/usr/lib/python3.6/site-packages/urllib3/connection.py", line 141, in _new_conn
    (self.host, self.port), self.timeout, **extra_kw)
  File "/usr/lib/python3.6/site-packages/urllib3/util/connection.py", line 60, in create_connection
    for res in socket.getaddrinfo(host, port, family, socket.SOCK_STREAM):
  File "/usr/lib/python3.6/socket.py", line 745, in getaddrinfo
    for res in _socket.getaddrinfo(host, port, family, type, proto, flags):
socket.gaierror: [Errno -3] Try again

During handling of the above exception, another exception occurred:

Traceback (most recent call last):
  File "/usr/lib/python3.6/site-packages/urllib3/connectionpool.py", line 601, in urlopen
    chunked=chunked)
  File "/usr/lib/python3.6/site-packages/urllib3/connectionpool.py", line 346, in _make_request
    self._validate_conn(conn)
  File "/usr/lib/python3.6/site-packages/urllib3/connectionpool.py", line 850, in _validate_conn
    conn.connect()
  File "/usr/lib/python3.6/site-packages/urllib3/connection.py", line 284, in connect
    conn = self._new_conn()
  File "/usr/lib/python3.6/site-packages/urllib3/connection.py", line 150, in _new_conn
    self, "Failed to establish a new connection: %s" % e)
urllib3.exceptions.NewConnectionError: <urllib3.connection.VerifiedHTTPSConnection object at 0x726fe2b0>: Failed to establish a new connection: [Errno -3] Try again

During handling of the above exception, another exception occurred:

Traceback (most recent call last):
  File "/usr/lib/python3.6/site-packages/requests/adapters.py", line 440, in send
    timeout=timeout
  File "/usr/lib/python3.6/site-packages/urllib3/connectionpool.py", line 639, in urlopen
    _stacktrace=sys.exc_info()[2])
  File "/usr/lib/python3.6/site-packages/urllib3/util/retry.py", line 388, in increment
    raise MaxRetryError(_pool, url, error or ResponseError(cause))
urllib3.exceptions.MaxRetryError: HTTPSConnectionPool(host='api.spotify.com', port=443): Max retries exceeded with url: /v1/me/player (Caused by NewConnectionError('<urllib3.connection.VerifiedHTTPSConnection object at 0x726fe2b0>: Failed to establish a new connection: [Errno -3] Try again',))

During handling of the above exception, another exception occurred:

Traceback (most recent call last):
  File "/usr/lib/python3.6/site-packages/homeassistant/helpers/entity.py", line 199, in async_update_ha_state
    yield from self.async_device_update()
  File "/usr/lib/python3.6/site-packages/homeassistant/helpers/entity.py", line 306, in async_device_update
    yield from self.hass.async_add_job(self.update)
  File "/usr/lib/python3.6/asyncio/futures.py", line 332, in __iter__
    yield self  # This tells Task to wait for completion.
  File "/usr/lib/python3.6/asyncio/tasks.py", line 250, in _wakeup
    future.result()
  File "/usr/lib/python3.6/asyncio/futures.py", line 245, in result
    raise self._exception
  File "/usr/lib/python3.6/concurrent/futures/thread.py", line 56, in run
    result = self.fn(*self.args, **self.kwargs)
  File "/usr/lib/python3.6/site-packages/homeassistant/components/media_player/spotify.py", line 186, in update
    current = self._player.current_playback()
  File "/usr/lib/python3.6/site-packages/spotipy/client.py", line 856, in current_playback
    return self._get("me/player", market = market)
  File "/usr/lib/python3.6/site-packages/spotipy/client.py", line 148, in _get
    return self._internal_call('GET', url, payload, kwargs)
  File "/usr/lib/python3.6/site-packages/spotipy/client.py", line 110, in _internal_call
    r = self._session.request(method, url, headers=headers, proxies=self.proxies, **args)
  File "/usr/lib/python3.6/site-packages/requests/sessions.py", line 508, in request
    resp = self.send(prep, **send_kwargs)
  File "/usr/lib/python3.6/site-packages/requests/sessions.py", line 618, in send
    r = adapter.send(request, **kwargs)
  File "/usr/lib/python3.6/site-packages/requests/adapters.py", line 508, in send
    raise ConnectionError(e, request=request)
requests.exceptions.ConnectionError: HTTPSConnectionPool(host='api.spotify.com', port=443): Max retries exceeded with url: /v1/me/player (Caused by NewConnectionError('<urllib3.connection.VerifiedHTTPSConnection object at 0x726fe2b0>: Failed to establish a new connection: [Errno -3] Try again',))
2017-12-24 08:49:10 ERROR (MainThread) [homeassistant.helpers.entity] Update for media_player.spotify fails
Traceback (most recent call last):
  File "/usr/lib/python3.6/site-packages/urllib3/connection.py", line 141, in _new_conn
    (self.host, self.port), self.timeout, **extra_kw)
  File "/usr/lib/python3.6/site-packages/urllib3/util/connection.py", line 60, in create_connection
    for res in socket.getaddrinfo(host, port, family, socket.SOCK_STREAM):
  File "/usr/lib/python3.6/socket.py", line 745, in getaddrinfo
    for res in _socket.getaddrinfo(host, port, family, type, proto, flags):
socket.gaierror: [Errno -3] Try again

During handling of the above exception, another exception occurred:

Traceback (most recent call last):
  File "/usr/lib/python3.6/site-packages/urllib3/connectionpool.py", line 601, in urlopen
    chunked=chunked)
  File "/usr/lib/python3.6/site-packages/urllib3/connectionpool.py", line 346, in _make_request
    self._validate_conn(conn)
  File "/usr/lib/python3.6/site-packages/urllib3/connectionpool.py", line 850, in _validate_conn
    conn.connect()
  File "/usr/lib/python3.6/site-packages/urllib3/connection.py", line 284, in connect
    conn = self._new_conn()
  File "/usr/lib/python3.6/site-packages/urllib3/connection.py", line 150, in _new_conn
    self, "Failed to establish a new connection: %s" % e)
urllib3.exceptions.NewConnectionError: <urllib3.connection.VerifiedHTTPSConnection object at 0x6fe738b0>: Failed to establish a new connection: [Errno -3] Try again

During handling of the above exception, another exception occurred:

Traceback (most recent call last):
  File "/usr/lib/python3.6/site-packages/requests/adapters.py", line 440, in send
    timeout=timeout
  File "/usr/lib/python3.6/site-packages/urllib3/connectionpool.py", line 639, in urlopen
    _stacktrace=sys.exc_info()[2])
  File "/usr/lib/python3.6/site-packages/urllib3/util/retry.py", line 388, in increment
    raise MaxRetryError(_pool, url, error or ResponseError(cause))
urllib3.exceptions.MaxRetryError: HTTPSConnectionPool(host='api.spotify.com', port=443): Max retries exceeded with url: /v1/me/player/devices (Caused by NewConnectionError('<urllib3.connection.VerifiedHTTPSConnection object at 0x6fe738b0>: Failed to establish a new connection: [Errno -3] Try again',))

During handling of the above exception, another exception occurred:

Traceback (most recent call last):
  File "/usr/lib/python3.6/site-packages/homeassistant/helpers/entity.py", line 199, in async_update_ha_state
    yield from self.async_device_update()
  File "/usr/lib/python3.6/site-packages/homeassistant/helpers/entity.py", line 306, in async_device_update
    yield from self.hass.async_add_job(self.update)
  File "/usr/lib/python3.6/asyncio/futures.py", line 332, in __iter__
    yield self  # This tells Task to wait for completion.
  File "/usr/lib/python3.6/asyncio/tasks.py", line 250, in _wakeup
    future.result()
  File "/usr/lib/python3.6/asyncio/futures.py", line 245, in result
    raise self._exception
  File "/usr/lib/python3.6/concurrent/futures/thread.py", line 56, in run
    result = self.fn(*self.args, **self.kwargs)
  File "/usr/lib/python3.6/site-packages/homeassistant/components/media_player/spotify.py", line 172, in update
    player_devices = self._player.devices()
  File "/usr/lib/python3.6/site-packages/spotipy/client.py", line 848, in devices
    return self._get("me/player/devices")
  File "/usr/lib/python3.6/site-packages/spotipy/client.py", line 148, in _get
    return self._internal_call('GET', url, payload, kwargs)
  File "/usr/lib/python3.6/site-packages/spotipy/client.py", line 110, in _internal_call
    r = self._session.request(method, url, headers=headers, proxies=self.proxies, **args)
  File "/usr/lib/python3.6/site-packages/requests/sessions.py", line 508, in request
    resp = self.send(prep, **send_kwargs)
  File "/usr/lib/python3.6/site-packages/requests/sessions.py", line 618, in send
    r = adapter.send(request, **kwargs)
  File "/usr/lib/python3.6/site-packages/requests/adapters.py", line 508, in send
    raise ConnectionError(e, request=request)
requests.exceptions.ConnectionError: HTTPSConnectionPool(host='api.spotify.com', port=443): Max retries exceeded with url: /v1/me/player/devices (Caused by NewConnectionError('<urllib3.connection.VerifiedHTTPSConnection object at 0x6fe738b0>: Failed to establish a new connection: [Errno -3] Try again',))
2017-12-24 08:56:19 WARNING (MainThread) [haffmpeg.tools] Timeout reading image.
2017-12-24 08:56:30 WARNING (MainThread) [haffmpeg.tools] Timeout reading image.
2017-12-24 08:56:40 WARNING (MainThread) [haffmpeg.tools] Timeout reading image.
2017-12-24 08:56:50 WARNING (MainThread) [haffmpeg.tools] Timeout reading image.
2017-12-24 08:56:54 WARNING (MainThread) [haffmpeg.tools] Timeout reading image.
2017-12-24 08:57:00 WARNING (MainThread) [haffmpeg.tools] Timeout reading image.
2017-12-24 08:57:04 WARNING (MainThread) [haffmpeg.tools] Timeout reading image.
2017-12-24 08:57:10 WARNING (MainThread) [haffmpeg.tools] Timeout reading image.
2017-12-24 08:57:14 WARNING (MainThread) [haffmpeg.tools] Timeout reading image.
2017-12-24 08:57:20 WARNING (MainThread) [haffmpeg.tools] Timeout reading image.
2017-12-24 08:57:24 WARNING (MainThread) [haffmpeg.tools] Timeout reading image.
2017-12-24 08:57:30 WARNING (MainThread) [haffmpeg.tools] Timeout reading image.
2017-12-24 08:57:35 WARNING (MainThread) [haffmpeg.tools] Timeout reading image.
2017-12-24 08:57:40 WARNING (MainThread) [haffmpeg.tools] Timeout reading image.
2017-12-24 08:57:44 WARNING (MainThread) [haffmpeg.tools] Timeout reading image.
2017-12-24 08:57:50 WARNING (MainThread) [haffmpeg.tools] Timeout reading image.
2017-12-24 08:57:54 WARNING (MainThread) [haffmpeg.tools] Timeout reading image.
2017-12-24 08:58:00 WARNING (MainThread) [haffmpeg.tools] Timeout reading image.
2017-12-24 08:58:04 WARNING (MainThread) [haffmpeg.tools] Timeout reading image.
2017-12-24 08:58:10 WARNING (MainThread) [haffmpeg.tools] Timeout reading image.
2017-12-24 08:58:14 WARNING (MainThread) [haffmpeg.tools] Timeout reading image.
2017-12-24 08:58:20 WARNING (MainThread) [haffmpeg.tools] Timeout reading image.
2017-12-24 08:58:24 WARNING (MainThread) [haffmpeg.tools] Timeout reading image.
2017-12-24 08:58:30 WARNING (MainThread) [haffmpeg.tools] Timeout reading image.
2017-12-24 08:58:34 WARNING (MainThread) [haffmpeg.tools] Timeout reading image.
2017-12-24 08:58:40 WARNING (MainThread) [haffmpeg.tools] Timeout reading image.
2017-12-24 08:58:44 WARNING (MainThread) [haffmpeg.tools] Timeout reading image.
2017-12-24 08:58:50 WARNING (MainThread) [haffmpeg.tools] Timeout reading image.
2017-12-24 08:58:53 WARNING (MainThread) [haffmpeg.tools] Timeout reading image.
2017-12-24 08:59:00 WARNING (MainThread) [haffmpeg.tools] Timeout reading image.
2017-12-24 08:59:04 WARNING (MainThread) [haffmpeg.tools] Timeout reading image.
2017-12-24 08:59:10 WARNING (MainThread) [haffmpeg.tools] Timeout reading image.
2017-12-24 08:59:14 WARNING (MainThread) [haffmpeg.tools] Timeout reading image.
2017-12-24 08:59:20 WARNING (MainThread) [haffmpeg.tools] Timeout reading image.
2017-12-24 08:59:24 WARNING (MainThread) [haffmpeg.tools] Timeout reading image.
2017-12-24 08:59:30 WARNING (MainThread) [haffmpeg.tools] Timeout reading image.
2017-12-24 08:59:34 WARNING (MainThread) [haffmpeg.tools] Timeout reading image.
2017-12-24 08:59:40 WARNING (MainThread) [haffmpeg.tools] Timeout reading image.
2017-12-24 08:59:44 WARNING (MainThread) [haffmpeg.tools] Timeout reading image.
2017-12-24 08:59:50 WARNING (MainThread) [haffmpeg.tools] Timeout reading image.
2017-12-24 08:59:54 WARNING (MainThread) [haffmpeg.tools] Timeout reading image.
2017-12-24 09:00:00 WARNING (MainThread) [haffmpeg.tools] Timeout reading image.
2017-12-24 09:00:04 WARNING (MainThread) [haffmpeg.tools] Timeout reading image.
2017-12-24 09:00:12 ERROR (SyncWorker_16) [homeassistant.components.sensor.speedtest] Error executing speedtest: Command '['/usr/bin/python3', '/usr/lib/python3.6/site-packages/speedtest.py', '--simple']' returned non-zero exit status 1.
2017-12-24 09:00:14 WARNING (MainThread) [haffmpeg.tools] Timeout reading image.
2017-12-24 09:00:20 WARNING (MainThread) [haffmpeg.tools] Timeout reading image.
2017-12-24 09:00:24 WARNING (MainThread) [haffmpeg.tools] Timeout reading image.
2017-12-24 09:00:30 WARNING (MainThread) [haffmpeg.tools] Timeout reading image.
2017-12-24 09:00:34 WARNING (MainThread) [haffmpeg.tools] Timeout reading image.
2017-12-24 09:00:40 WARNING (MainThread) [haffmpeg.tools] Timeout reading image.
2017-12-24 09:00:59 WARNING (SyncWorker_4) [homeassistant.components.light.tplink] Could not read state for luz_central: Communication error
2017-12-24 09:01:01 WARNING (MainThread) [haffmpeg.tools] Timeout reading image.
2017-12-24 09:01:14 WARNING (MainThread) [haffmpeg.tools] Timeout reading image.
2017-12-24 09:01:30 WARNING (MainThread) [haffmpeg.tools] Timeout reading image.
2017-12-24 09:01:34 WARNING (MainThread) [haffmpeg.tools] Timeout reading image.
2017-12-24 09:01:44 WARNING (MainThread) [haffmpeg.tools] Timeout reading image.
2017-12-24 09:01:54 WARNING (MainThread) [haffmpeg.tools] Timeout reading image.
2017-12-24 09:02:04 WARNING (MainThread) [haffmpeg.tools] Timeout reading image.
2017-12-24 09:02:14 WARNING (MainThread) [haffmpeg.tools] Timeout reading image.
2017-12-24 09:02:24 WARNING (MainThread) [haffmpeg.tools] Timeout reading image.
2017-12-24 09:02:34 WARNING (MainThread) [haffmpeg.tools] Timeout reading image.
2017-12-24 09:02:44 WARNING (MainThread) [haffmpeg.tools] Timeout reading image.
2017-12-24 09:02:54 WARNING (MainThread) [haffmpeg.tools] Timeout reading image.
2017-12-24 09:03:04 WARNING (MainThread) [haffmpeg.tools] Timeout reading image.
2017-12-24 09:03:14 WARNING (MainThread) [haffmpeg.tools] Timeout reading image.
2017-12-24 09:03:24 WARNING (MainThread) [haffmpeg.tools] Timeout reading image.
2017-12-24 09:03:34 WARNING (MainThread) [haffmpeg.tools] Timeout reading image.
2017-12-24 09:03:44 WARNING (MainThread) [haffmpeg.tools] Timeout reading image.
2017-12-24 09:08:38 WARNING (MainThread) [haffmpeg.tools] Timeout reading image.
2017-12-24 09:08:39 WARNING (MainThread) [haffmpeg.tools] Timeout reading image.
2017-12-24 09:08:40 WARNING (MainThread) [haffmpeg.tools] Timeout reading image.
2017-12-24 09:08:50 WARNING (MainThread) [haffmpeg.tools] Timeout reading image.
2017-12-24 09:08:55 WARNING (MainThread) [haffmpeg.tools] Timeout reading image.
2017-12-24 09:09:00 WARNING (MainThread) [haffmpeg.tools] Timeout reading image.
2017-12-24 09:09:10 WARNING (MainThread) [haffmpeg.tools] Timeout reading image.
2017-12-24 09:09:20 WARNING (MainThread) [haffmpeg.tools] Timeout reading image.
2017-12-24 09:09:30 WARNING (MainThread) [haffmpeg.tools] Timeout reading image.
2017-12-24 09:09:40 WARNING (MainThread) [haffmpeg.tools] Timeout reading image.
2017-12-24 09:09:46 ERROR (MainThread) [homeassistant.helpers.entity] Update for media_player.spotify fails
Traceback (most recent call last):
  File "/usr/lib/python3.6/site-packages/urllib3/connection.py", line 141, in _new_conn
    (self.host, self.port), self.timeout, **extra_kw)
  File "/usr/lib/python3.6/site-packages/urllib3/util/connection.py", line 60, in create_connection
    for res in socket.getaddrinfo(host, port, family, socket.SOCK_STREAM):
  File "/usr/lib/python3.6/socket.py", line 745, in getaddrinfo
    for res in _socket.getaddrinfo(host, port, family, type, proto, flags):
socket.gaierror: [Errno -3] Try again

During handling of the above exception, another exception occurred:

Traceback (most recent call last):
  File "/usr/lib/python3.6/site-packages/urllib3/connectionpool.py", line 601, in urlopen
    chunked=chunked)
  File "/usr/lib/python3.6/site-packages/urllib3/connectionpool.py", line 346, in _make_request
    self._validate_conn(conn)
  File "/usr/lib/python3.6/site-packages/urllib3/connectionpool.py", line 850, in _validate_conn
    conn.connect()
  File "/usr/lib/python3.6/site-packages/urllib3/connection.py", line 284, in connect
    conn = self._new_conn()
  File "/usr/lib/python3.6/site-packages/urllib3/connection.py", line 150, in _new_conn
    self, "Failed to establish a new connection: %s" % e)
urllib3.exceptions.NewConnectionError: <urllib3.connection.VerifiedHTTPSConnection object at 0x726ca4f0>: Failed to establish a new connection: [Errno -3] Try again

During handling of the above exception, another exception occurred:

Traceback (most recent call last):
  File "/usr/lib/python3.6/site-packages/requests/adapters.py", line 440, in send
    timeout=timeout
  File "/usr/lib/python3.6/site-packages/urllib3/connectionpool.py", line 639, in urlopen
    _stacktrace=sys.exc_info()[2])
  File "/usr/lib/python3.6/site-packages/urllib3/util/retry.py", line 388, in increment
    raise MaxRetryError(_pool, url, error or ResponseError(cause))
urllib3.exceptions.MaxRetryError: HTTPSConnectionPool(host='api.spotify.com', port=443): Max retries exceeded with url: /v1/me/player/devices (Caused by NewConnectionError('<urllib3.connection.VerifiedHTTPSConnection object at 0x726ca4f0>: Failed to establish a new connection: [Errno -3] Try again',))

During handling of the above exception, another exception occurred:

Traceback (most recent call last):
  File "/usr/lib/python3.6/site-packages/homeassistant/helpers/entity.py", line 199, in async_update_ha_state
    yield from self.async_device_update()
  File "/usr/lib/python3.6/site-packages/homeassistant/helpers/entity.py", line 306, in async_device_update
    yield from self.hass.async_add_job(self.update)
  File "/usr/lib/python3.6/asyncio/futures.py", line 332, in __iter__
    yield self  # This tells Task to wait for completion.
  File "/usr/lib/python3.6/asyncio/tasks.py", line 250, in _wakeup
    future.result()
  File "/usr/lib/python3.6/asyncio/futures.py", line 245, in result
    raise self._exception
  File "/usr/lib/python3.6/concurrent/futures/thread.py", line 56, in run
    result = self.fn(*self.args, **self.kwargs)
  File "/usr/lib/python3.6/site-packages/homeassistant/components/media_player/spotify.py", line 172, in update
    player_devices = self._player.devices()
  File "/usr/lib/python3.6/site-packages/spotipy/client.py", line 848, in devices
    return self._get("me/player/devices")
  File "/usr/lib/python3.6/site-packages/spotipy/client.py", line 148, in _get
    return self._internal_call('GET', url, payload, kwargs)
  File "/usr/lib/python3.6/site-packages/spotipy/client.py", line 110, in _internal_call
    r = self._session.request(method, url, headers=headers, proxies=self.proxies, **args)
  File "/usr/lib/python3.6/site-packages/requests/sessions.py", line 508, in request
    resp = self.send(prep, **send_kwargs)
  File "/usr/lib/python3.6/site-packages/requests/sessions.py", line 618, in send
    r = adapter.send(request, **kwargs)
  File "/usr/lib/python3.6/site-packages/requests/adapters.py", line 508, in send
    raise ConnectionError(e, request=request)
requests.exceptions.ConnectionError: HTTPSConnectionPool(host='api.spotify.com', port=443): Max retries exceeded with url: /v1/me/player/devices (Caused by NewConnectionError('<urllib3.connection.VerifiedHTTPSConnection object at 0x726ca4f0>: Failed to establish a new connection: [Errno -3] Try again',))
2017-12-24 09:09:50 WARNING (MainThread) [haffmpeg.tools] Timeout reading image.
2017-12-24 09:10:00 WARNING (MainThread) [haffmpeg.tools] Timeout reading image.
2017-12-24 09:10:10 WARNING (MainThread) [haffmpeg.tools] Timeout reading image.
2017-12-24 09:10:20 WARNING (MainThread) [haffmpeg.tools] Timeout reading image.
2017-12-24 09:10:30 WARNING (MainThread) [haffmpeg.tools] Timeout reading image.
2017-12-24 09:10:40 WARNING (MainThread) [haffmpeg.tools] Timeout reading image.
2017-12-24 09:11:29 WARNING (MainThread) [haffmpeg.tools] Timeout reading image.
2017-12-24 09:11:38 WARNING (MainThread) [haffmpeg.tools] Timeout reading image.
2017-12-24 09:11:48 WARNING (MainThread) [haffmpeg.tools] Timeout reading image.
2017-12-24 09:11:58 WARNING (MainThread) [haffmpeg.tools] Timeout reading image.
2017-12-24 09:12:08 WARNING (MainThread) [haffmpeg.tools] Timeout reading image.
2017-12-24 09:12:18 WARNING (MainThread) [haffmpeg.tools] Timeout reading image.
2017-12-24 09:12:28 WARNING (MainThread) [haffmpeg.tools] Timeout reading image.
2017-12-24 09:12:38 WARNING (MainThread) [haffmpeg.tools] Timeout reading image.
2017-12-24 09:12:48 WARNING (MainThread) [haffmpeg.tools] Timeout reading image.
2017-12-24 09:12:58 WARNING (MainThread) [haffmpeg.tools] Timeout reading image.
2017-12-24 09:13:08 WARNING (MainThread) [haffmpeg.tools] Timeout reading image.
2017-12-24 09:13:18 WARNING (MainThread) [haffmpeg.tools] Timeout reading image.
2017-12-24 09:13:28 WARNING (MainThread) [haffmpeg.tools] Timeout reading image.
2017-12-24 09:13:38 WARNING (MainThread) [haffmpeg.tools] Timeout reading image.
2017-12-24 09:13:48 WARNING (MainThread) [haffmpeg.tools] Timeout reading image.
2017-12-24 09:13:56 WARNING (MainThread) [haffmpeg.tools] Timeout reading image.
2017-12-24 09:13:58 WARNING (MainThread) [haffmpeg.tools] Timeout reading image.
2017-12-24 09:14:08 WARNING (MainThread) [haffmpeg.tools] Timeout reading image.
2017-12-24 09:14:18 WARNING (MainThread) [haffmpeg.tools] Timeout reading image.
2017-12-24 09:14:28 WARNING (MainThread) [haffmpeg.tools] Timeout reading image.
2017-12-24 09:14:38 WARNING (MainThread) [haffmpeg.tools] Timeout reading image.
2017-12-24 09:14:48 WARNING (MainThread) [haffmpeg.tools] Timeout reading image.
2017-12-24 09:14:58 WARNING (MainThread) [haffmpeg.tools] Timeout reading image.
2017-12-24 09:15:08 WARNING (MainThread) [haffmpeg.tools] Timeout reading image.
2017-12-24 09:15:18 WARNING (MainThread) [haffmpeg.tools] Timeout reading image.
2017-12-24 09:15:28 WARNING (MainThread) [haffmpeg.tools] Timeout reading image.
2017-12-24 09:15:38 WARNING (MainThread) [haffmpeg.tools] Timeout reading image.
2017-12-24 09:15:48 WARNING (MainThread) [haffmpeg.tools] Timeout reading image.
2017-12-24 09:15:58 WARNING (MainThread) [haffmpeg.tools] Timeout reading image.
2017-12-24 09:16:08 WARNING (MainThread) [haffmpeg.tools] Timeout reading image.
2017-12-24 09:16:18 WARNING (MainThread) [haffmpeg.tools] Timeout reading image.
2017-12-24 09:16:28 WARNING (MainThread) [haffmpeg.tools] Timeout reading image.
2017-12-24 09:16:38 WARNING (MainThread) [haffmpeg.tools] Timeout reading image.
2017-12-24 09:16:48 WARNING (MainThread) [haffmpeg.tools] Timeout reading image.
2017-12-24 09:16:58 WARNING (MainThread) [haffmpeg.tools] Timeout reading image.
2017-12-24 09:17:08 WARNING (MainThread) [haffmpeg.tools] Timeout reading image.
2017-12-24 09:17:18 WARNING (MainThread) [haffmpeg.tools] Timeout reading image.
2017-12-24 09:17:28 WARNING (MainThread) [haffmpeg.tools] Timeout reading image.
2017-12-24 09:19:20 WARNING (MainThread) [haffmpeg.tools] Timeout reading image.
2017-12-24 09:19:20 WARNING (MainThread) [haffmpeg.tools] Timeout reading image.
2017-12-24 09:19:28 WARNING (MainThread) [haffmpeg.tools] Timeout reading image.
2017-12-24 09:19:38 WARNING (MainThread) [haffmpeg.tools] Timeout reading image.
2017-12-24 09:19:48 WARNING (MainThread) [haffmpeg.tools] Timeout reading image.
2017-12-24 09:19:58 WARNING (MainThread) [haffmpeg.tools] Timeout reading image.
2017-12-24 09:20:08 WARNING (MainThread) [haffmpeg.tools] Timeout reading image.
2017-12-24 09:20:18 WARNING (MainThread) [haffmpeg.tools] Timeout reading image.
2017-12-24 09:20:44 WARNING (MainThread) [haffmpeg.tools] Timeout reading image.
2017-12-24 09:21:15 WARNING (MainThread) [haffmpeg.tools] Timeout reading image.
2017-12-24 09:21:33 WARNING (MainThread) [haffmpeg.tools] Timeout reading image.
2017-12-24 09:21:43 WARNING (MainThread) [haffmpeg.tools] Timeout reading image.
2017-12-24 09:21:53 WARNING (MainThread) [haffmpeg.tools] Timeout reading image.
2017-12-24 09:23:33 WARNING (MainThread) [haffmpeg.tools] Timeout reading image.
2017-12-24 09:23:57 WARNING (MainThread) [haffmpeg.tools] Timeout reading image.
2017-12-24 09:24:47 WARNING (MainThread) [haffmpeg.tools] Timeout reading image.
2017-12-24 09:28:52 ERROR (MainThread) [homeassistant.helpers.entity] Update for media_player.spotify fails
Traceback (most recent call last):
  File "/usr/lib/python3.6/site-packages/urllib3/connection.py", line 141, in _new_conn
    (self.host, self.port), self.timeout, **extra_kw)
  File "/usr/lib/python3.6/site-packages/urllib3/util/connection.py", line 60, in create_connection
    for res in socket.getaddrinfo(host, port, family, socket.SOCK_STREAM):
  File "/usr/lib/python3.6/socket.py", line 745, in getaddrinfo
    for res in _socket.getaddrinfo(host, port, family, type, proto, flags):
socket.gaierror: [Errno -3] Try again

During handling of the above exception, another exception occurred:

Traceback (most recent call last):
  File "/usr/lib/python3.6/site-packages/urllib3/connectionpool.py", line 601, in urlopen
    chunked=chunked)
  File "/usr/lib/python3.6/site-packages/urllib3/connectionpool.py", line 346, in _make_request
    self._validate_conn(conn)
  File "/usr/lib/python3.6/site-packages/urllib3/connectionpool.py", line 850, in _validate_conn
    conn.connect()
  File "/usr/lib/python3.6/site-packages/urllib3/connection.py", line 284, in connect
    conn = self._new_conn()
  File "/usr/lib/python3.6/site-packages/urllib3/connection.py", line 150, in _new_conn
    self, "Failed to establish a new connection: %s" % e)
urllib3.exceptions.NewConnectionError: <urllib3.connection.VerifiedHTTPSConnection object at 0x6efabd30>: Failed to establish a new connection: [Errno -3] Try again

During handling of the above exception, another exception occurred:

Traceback (most recent call last):
  File "/usr/lib/python3.6/site-packages/requests/adapters.py", line 440, in send
    timeout=timeout
  File "/usr/lib/python3.6/site-packages/urllib3/connectionpool.py", line 639, in urlopen
    _stacktrace=sys.exc_info()[2])
  File "/usr/lib/python3.6/site-packages/urllib3/util/retry.py", line 388, in increment
    raise MaxRetryError(_pool, url, error or ResponseError(cause))
urllib3.exceptions.MaxRetryError: HTTPSConnectionPool(host='api.spotify.com', port=443): Max retries exceeded with url: /v1/me/player (Caused by NewConnectionError('<urllib3.connection.VerifiedHTTPSConnection object at 0x6efabd30>: Failed to establish a new connection: [Errno -3] Try again',))

During handling of the above exception, another exception occurred:

Traceback (most recent call last):
  File "/usr/lib/python3.6/site-packages/homeassistant/helpers/entity.py", line 199, in async_update_ha_state
    yield from self.async_device_update()
  File "/usr/lib/python3.6/site-packages/homeassistant/helpers/entity.py", line 306, in async_device_update
    yield from self.hass.async_add_job(self.update)
  File "/usr/lib/python3.6/asyncio/futures.py", line 332, in __iter__
    yield self  # This tells Task to wait for completion.
  File "/usr/lib/python3.6/asyncio/tasks.py", line 250, in _wakeup
    future.result()
  File "/usr/lib/python3.6/asyncio/futures.py", line 245, in result
    raise self._exception
  File "/usr/lib/python3.6/concurrent/futures/thread.py", line 56, in run
    result = self.fn(*self.args, **self.kwargs)
  File "/usr/lib/python3.6/site-packages/homeassistant/components/media_player/spotify.py", line 186, in update
    current = self._player.current_playback()
  File "/usr/lib/python3.6/site-packages/spotipy/client.py", line 856, in current_playback
    return self._get("me/player", market = market)
  File "/usr/lib/python3.6/site-packages/spotipy/client.py", line 148, in _get
    return self._internal_call('GET', url, payload, kwargs)
  File "/usr/lib/python3.6/site-packages/spotipy/client.py", line 110, in _internal_call
    r = self._session.request(method, url, headers=headers, proxies=self.proxies, **args)
  File "/usr/lib/python3.6/site-packages/requests/sessions.py", line 508, in request
    resp = self.send(prep, **send_kwargs)
  File "/usr/lib/python3.6/site-packages/requests/sessions.py", line 618, in send
    r = adapter.send(request, **kwargs)
  File "/usr/lib/python3.6/site-packages/requests/adapters.py", line 508, in send
    raise ConnectionError(e, request=request)
requests.exceptions.ConnectionError: HTTPSConnectionPool(host='api.spotify.com', port=443): Max retries exceeded with url: /v1/me/player (Caused by NewConnectionError('<urllib3.connection.VerifiedHTTPSConnection object at 0x6efabd30>: Failed to establish a new connection: [Errno -3] Try again',))
2017-12-24 09:49:00 ERROR (MainThread) [homeassistant.helpers.entity] Update for media_player.spotify fails
Traceback (most recent call last):
  File "/usr/lib/python3.6/site-packages/urllib3/connection.py", line 141, in _new_conn
    (self.host, self.port), self.timeout, **extra_kw)
  File "/usr/lib/python3.6/site-packages/urllib3/util/connection.py", line 60, in create_connection
    for res in socket.getaddrinfo(host, port, family, socket.SOCK_STREAM):
  File "/usr/lib/python3.6/socket.py", line 745, in getaddrinfo
    for res in _socket.getaddrinfo(host, port, family, type, proto, flags):
socket.gaierror: [Errno -3] Try again

During handling of the above exception, another exception occurred:

Traceback (most recent call last):
  File "/usr/lib/python3.6/site-packages/urllib3/connectionpool.py", line 601, in urlopen
    chunked=chunked)
  File "/usr/lib/python3.6/site-packages/urllib3/connectionpool.py", line 346, in _make_request
    self._validate_conn(conn)
  File "/usr/lib/python3.6/site-packages/urllib3/connectionpool.py", line 850, in _validate_conn
    conn.connect()
  File "/usr/lib/python3.6/site-packages/urllib3/connection.py", line 284, in connect
    conn = self._new_conn()
  File "/usr/lib/python3.6/site-packages/urllib3/connection.py", line 150, in _new_conn
    self, "Failed to establish a new connection: %s" % e)
urllib3.exceptions.NewConnectionError: <urllib3.connection.VerifiedHTTPSConnection object at 0x7269e7f0>: Failed to establish a new connection: [Errno -3] Try again

During handling of the above exception, another exception occurred:

Traceback (most recent call last):
  File "/usr/lib/python3.6/site-packages/requests/adapters.py", line 440, in send
    timeout=timeout
  File "/usr/lib/python3.6/site-packages/urllib3/connectionpool.py", line 639, in urlopen
    _stacktrace=sys.exc_info()[2])
  File "/usr/lib/python3.6/site-packages/urllib3/util/retry.py", line 388, in increment
    raise MaxRetryError(_pool, url, error or ResponseError(cause))
urllib3.exceptions.MaxRetryError: HTTPSConnectionPool(host='api.spotify.com', port=443): Max retries exceeded with url: /v1/me/player/devices (Caused by NewConnectionError('<urllib3.connection.VerifiedHTTPSConnection object at 0x7269e7f0>: Failed to establish a new connection: [Errno -3] Try again',))

During handling of the above exception, another exception occurred:

Traceback (most recent call last):
  File "/usr/lib/python3.6/site-packages/homeassistant/helpers/entity.py", line 199, in async_update_ha_state
    yield from self.async_device_update()
  File "/usr/lib/python3.6/site-packages/homeassistant/helpers/entity.py", line 306, in async_device_update
    yield from self.hass.async_add_job(self.update)
  File "/usr/lib/python3.6/asyncio/futures.py", line 332, in __iter__
    yield self  # This tells Task to wait for completion.
  File "/usr/lib/python3.6/asyncio/tasks.py", line 250, in _wakeup
    future.result()
  File "/usr/lib/python3.6/asyncio/futures.py", line 245, in result
    raise self._exception
  File "/usr/lib/python3.6/concurrent/futures/thread.py", line 56, in run
    result = self.fn(*self.args, **self.kwargs)
  File "/usr/lib/python3.6/site-packages/homeassistant/components/media_player/spotify.py", line 172, in update
    player_devices = self._player.devices()
  File "/usr/lib/python3.6/site-packages/spotipy/client.py", line 848, in devices
    return self._get("me/player/devices")
  File "/usr/lib/python3.6/site-packages/spotipy/client.py", line 148, in _get
    return self._internal_call('GET', url, payload, kwargs)
  File "/usr/lib/python3.6/site-packages/spotipy/client.py", line 110, in _internal_call
    r = self._session.request(method, url, headers=headers, proxies=self.proxies, **args)
  File "/usr/lib/python3.6/site-packages/requests/sessions.py", line 508, in request
    resp = self.send(prep, **send_kwargs)
  File "/usr/lib/python3.6/site-packages/requests/sessions.py", line 618, in send
    r = adapter.send(request, **kwargs)
  File "/usr/lib/python3.6/site-packages/requests/adapters.py", line 508, in send
    raise ConnectionError(e, request=request)
requests.exceptions.ConnectionError: HTTPSConnectionPool(host='api.spotify.com', port=443): Max retries exceeded with url: /v1/me/player/devices (Caused by NewConnectionError('<urllib3.connection.VerifiedHTTPSConnection object at 0x7269e7f0>: Failed to establish a new connection: [Errno -3] Try again',))
2017-12-24 09:54:41 ERROR (MainThread) [homeassistant.helpers.entity] Update for media_player.spotify fails
Traceback (most recent call last):
  File "/usr/lib/python3.6/site-packages/urllib3/connection.py", line 141, in _new_conn
    (self.host, self.port), self.timeout, **extra_kw)
  File "/usr/lib/python3.6/site-packages/urllib3/util/connection.py", line 60, in create_connection
    for res in socket.getaddrinfo(host, port, family, socket.SOCK_STREAM):
  File "/usr/lib/python3.6/socket.py", line 745, in getaddrinfo
    for res in _socket.getaddrinfo(host, port, family, type, proto, flags):
socket.gaierror: [Errno -3] Try again

During handling of the above exception, another exception occurred:

Traceback (most recent call last):
  File "/usr/lib/python3.6/site-packages/urllib3/connectionpool.py", line 601, in urlopen
    chunked=chunked)
  File "/usr/lib/python3.6/site-packages/urllib3/connectionpool.py", line 346, in _make_request
    self._validate_conn(conn)
  File "/usr/lib/python3.6/site-packages/urllib3/connectionpool.py", line 850, in _validate_conn
    conn.connect()
  File "/usr/lib/python3.6/site-packages/urllib3/connection.py", line 284, in connect
    conn = self._new_conn()
  File "/usr/lib/python3.6/site-packages/urllib3/connection.py", line 150, in _new_conn
    self, "Failed to establish a new connection: %s" % e)
urllib3.exceptions.NewConnectionError: <urllib3.connection.VerifiedHTTPSConnection object at 0x6fe732f0>: Failed to establish a new connection: [Errno -3] Try again

During handling of the above exception, another exception occurred:

Traceback (most recent call last):
  File "/usr/lib/python3.6/site-packages/requests/adapters.py", line 440, in send
    timeout=timeout
  File "/usr/lib/python3.6/site-packages/urllib3/connectionpool.py", line 639, in urlopen
    _stacktrace=sys.exc_info()[2])
  File "/usr/lib/python3.6/site-packages/urllib3/util/retry.py", line 388, in increment
    raise MaxRetryError(_pool, url, error or ResponseError(cause))
urllib3.exceptions.MaxRetryError: HTTPSConnectionPool(host='api.spotify.com', port=443): Max retries exceeded with url: /v1/me/player/devices (Caused by NewConnectionError('<urllib3.connection.VerifiedHTTPSConnection object at 0x6fe732f0>: Failed to establish a new connection: [Errno -3] Try again',))

During handling of the above exception, another exception occurred:

Traceback (most recent call last):
  File "/usr/lib/python3.6/site-packages/homeassistant/helpers/entity.py", line 199, in async_update_ha_state
    yield from self.async_device_update()
  File "/usr/lib/python3.6/site-packages/homeassistant/helpers/entity.py", line 306, in async_device_update
    yield from self.hass.async_add_job(self.update)
  File "/usr/lib/python3.6/asyncio/futures.py", line 332, in __iter__
    yield self  # This tells Task to wait for completion.
  File "/usr/lib/python3.6/asyncio/tasks.py", line 250, in _wakeup
    future.result()
  File "/usr/lib/python3.6/asyncio/futures.py", line 245, in result
    raise self._exception
  File "/usr/lib/python3.6/concurrent/futures/thread.py", line 56, in run
    result = self.fn(*self.args, **self.kwargs)
  File "/usr/lib/python3.6/site-packages/homeassistant/components/media_player/spotify.py", line 172, in update
    player_devices = self._player.devices()
  File "/usr/lib/python3.6/site-packages/spotipy/client.py", line 848, in devices
    return self._get("me/player/devices")
  File "/usr/lib/python3.6/site-packages/spotipy/client.py", line 148, in _get
    return self._internal_call('GET', url, payload, kwargs)
  File "/usr/lib/python3.6/site-packages/spotipy/client.py", line 110, in _internal_call
    r = self._session.request(method, url, headers=headers, proxies=self.proxies, **args)
  File "/usr/lib/python3.6/site-packages/requests/sessions.py", line 508, in request
    resp = self.send(prep, **send_kwargs)
  File "/usr/lib/python3.6/site-packages/requests/sessions.py", line 618, in send
    r = adapter.send(request, **kwargs)
  File "/usr/lib/python3.6/site-packages/requests/adapters.py", line 508, in send
    raise ConnectionError(e, request=request)
requests.exceptions.ConnectionError: HTTPSConnectionPool(host='api.spotify.com', port=443): Max retries exceeded with url: /v1/me/player/devices (Caused by NewConnectionError('<urllib3.connection.VerifiedHTTPSConnection object at 0x6fe732f0>: Failed to establish a new connection: [Errno -3] Try again',))
2017-12-24 10:00:18 WARNING (MainThread) [haffmpeg.tools] Timeout reading image.
2017-12-24 10:02:57 ERROR (MainThread) [homeassistant.helpers.entity] Update for media_player.spotify fails
Traceback (most recent call last):
  File "/usr/lib/python3.6/site-packages/urllib3/connection.py", line 141, in _new_conn
    (self.host, self.port), self.timeout, **extra_kw)
  File "/usr/lib/python3.6/site-packages/urllib3/util/connection.py", line 60, in create_connection
    for res in socket.getaddrinfo(host, port, family, socket.SOCK_STREAM):
  File "/usr/lib/python3.6/socket.py", line 745, in getaddrinfo
    for res in _socket.getaddrinfo(host, port, family, type, proto, flags):
socket.gaierror: [Errno -3] Try again

During handling of the above exception, another exception occurred:

Traceback (most recent call last):
  File "/usr/lib/python3.6/site-packages/urllib3/connectionpool.py", line 601, in urlopen
    chunked=chunked)
  File "/usr/lib/python3.6/site-packages/urllib3/connectionpool.py", line 346, in _make_request
    self._validate_conn(conn)
  File "/usr/lib/python3.6/site-packages/urllib3/connectionpool.py", line 850, in _validate_conn
    conn.connect()
  File "/usr/lib/python3.6/site-packages/urllib3/connection.py", line 284, in connect
    conn = self._new_conn()
  File "/usr/lib/python3.6/site-packages/urllib3/connection.py", line 150, in _new_conn
    self, "Failed to establish a new connection: %s" % e)
urllib3.exceptions.NewConnectionError: <urllib3.connection.VerifiedHTTPSConnection object at 0x72667930>: Failed to establish a new connection: [Errno -3] Try again

During handling of the above exception, another exception occurred:

Traceback (most recent call last):
  File "/usr/lib/python3.6/site-packages/requests/adapters.py", line 440, in send
    timeout=timeout
  File "/usr/lib/python3.6/site-packages/urllib3/connectionpool.py", line 639, in urlopen
    _stacktrace=sys.exc_info()[2])
  File "/usr/lib/python3.6/site-packages/urllib3/util/retry.py", line 388, in increment
    raise MaxRetryError(_pool, url, error or ResponseError(cause))
urllib3.exceptions.MaxRetryError: HTTPSConnectionPool(host='api.spotify.com', port=443): Max retries exceeded with url: /v1/me/player/devices (Caused by NewConnectionError('<urllib3.connection.VerifiedHTTPSConnection object at 0x72667930>: Failed to establish a new connection: [Errno -3] Try again',))

During handling of the above exception, another exception occurred:

Traceback (most recent call last):
  File "/usr/lib/python3.6/site-packages/homeassistant/helpers/entity.py", line 199, in async_update_ha_state
    yield from self.async_device_update()
  File "/usr/lib/python3.6/site-packages/homeassistant/helpers/entity.py", line 306, in async_device_update
    yield from self.hass.async_add_job(self.update)
  File "/usr/lib/python3.6/asyncio/futures.py", line 332, in __iter__
    yield self  # This tells Task to wait for completion.
  File "/usr/lib/python3.6/asyncio/tasks.py", line 250, in _wakeup
    future.result()
  File "/usr/lib/python3.6/asyncio/futures.py", line 245, in result
    raise self._exception
  File "/usr/lib/python3.6/concurrent/futures/thread.py", line 56, in run
    result = self.fn(*self.args, **self.kwargs)
  File "/usr/lib/python3.6/site-packages/homeassistant/components/media_player/spotify.py", line 172, in update
    player_devices = self._player.devices()
  File "/usr/lib/python3.6/site-packages/spotipy/client.py", line 848, in devices
    return self._get("me/player/devices")
  File "/usr/lib/python3.6/site-packages/spotipy/client.py", line 148, in _get
    return self._internal_call('GET', url, payload, kwargs)
  File "/usr/lib/python3.6/site-packages/spotipy/client.py", line 110, in _internal_call
    r = self._session.request(method, url, headers=headers, proxies=self.proxies, **args)
  File "/usr/lib/python3.6/site-packages/requests/sessions.py", line 508, in request
    resp = self.send(prep, **send_kwargs)
  File "/usr/lib/python3.6/site-packages/requests/sessions.py", line 618, in send
    r = adapter.send(request, **kwargs)
  File "/usr/lib/python3.6/site-packages/requests/adapters.py", line 508, in send
    raise ConnectionError(e, request=request)
requests.exceptions.ConnectionError: HTTPSConnectionPool(host='api.spotify.com', port=443): Max retries exceeded with url: /v1/me/player/devices (Caused by NewConnectionError('<urllib3.connection.VerifiedHTTPSConnection object at 0x72667930>: Failed to establish a new connection: [Errno -3] Try again',))
2017-12-24 10:27:45 ERROR (MainThread) [homeassistant.helpers.entity] Update for media_player.spotify fails
Traceback (most recent call last):
  File "/usr/lib/python3.6/site-packages/urllib3/connection.py", line 141, in _new_conn
    (self.host, self.port), self.timeout, **extra_kw)
  File "/usr/lib/python3.6/site-packages/urllib3/util/connection.py", line 60, in create_connection
    for res in socket.getaddrinfo(host, port, family, socket.SOCK_STREAM):
  File "/usr/lib/python3.6/socket.py", line 745, in getaddrinfo
    for res in _socket.getaddrinfo(host, port, family, type, proto, flags):
socket.gaierror: [Errno -3] Try again

During handling of the above exception, another exception occurred:

Traceback (most recent call last):
  File "/usr/lib/python3.6/site-packages/urllib3/connectionpool.py", line 601, in urlopen
    chunked=chunked)
  File "/usr/lib/python3.6/site-packages/urllib3/connectionpool.py", line 346, in _make_request
    self._validate_conn(conn)
  File "/usr/lib/python3.6/site-packages/urllib3/connectionpool.py", line 850, in _validate_conn
    conn.connect()
  File "/usr/lib/python3.6/site-packages/urllib3/connection.py", line 284, in connect
    conn = self._new_conn()
  File "/usr/lib/python3.6/site-packages/urllib3/connection.py", line 150, in _new_conn
    self, "Failed to establish a new connection: %s" % e)
urllib3.exceptions.NewConnectionError: <urllib3.connection.VerifiedHTTPSConnection object at 0x72648ad0>: Failed to establish a new connection: [Errno -3] Try again

During handling of the above exception, another exception occurred:

Traceback (most recent call last):
  File "/usr/lib/python3.6/site-packages/requests/adapters.py", line 440, in send
    timeout=timeout
  File "/usr/lib/python3.6/site-packages/urllib3/connectionpool.py", line 639, in urlopen
    _stacktrace=sys.exc_info()[2])
  File "/usr/lib/python3.6/site-packages/urllib3/util/retry.py", line 388, in increment
    raise MaxRetryError(_pool, url, error or ResponseError(cause))
urllib3.exceptions.MaxRetryError: HTTPSConnectionPool(host='api.spotify.com', port=443): Max retries exceeded with url: /v1/me/player/devices (Caused by NewConnectionError('<urllib3.connection.VerifiedHTTPSConnection object at 0x72648ad0>: Failed to establish a new connection: [Errno -3] Try again',))

During handling of the above exception, another exception occurred:

Traceback (most recent call last):
  File "/usr/lib/python3.6/site-packages/homeassistant/helpers/entity.py", line 199, in async_update_ha_state
    yield from self.async_device_update()
  File "/usr/lib/python3.6/site-packages/homeassistant/helpers/entity.py", line 306, in async_device_update
    yield from self.hass.async_add_job(self.update)
  File "/usr/lib/python3.6/asyncio/futures.py", line 332, in __iter__
    yield self  # This tells Task to wait for completion.
  File "/usr/lib/python3.6/asyncio/tasks.py", line 250, in _wakeup
    future.result()
  File "/usr/lib/python3.6/asyncio/futures.py", line 245, in result
    raise self._exception
  File "/usr/lib/python3.6/concurrent/futures/thread.py", line 56, in run
    result = self.fn(*self.args, **self.kwargs)
  File "/usr/lib/python3.6/site-packages/homeassistant/components/media_player/spotify.py", line 172, in update
    player_devices = self._player.devices()
  File "/usr/lib/python3.6/site-packages/spotipy/client.py", line 848, in devices
    return self._get("me/player/devices")
  File "/usr/lib/python3.6/site-packages/spotipy/client.py", line 148, in _get
    return self._internal_call('GET', url, payload, kwargs)
  File "/usr/lib/python3.6/site-packages/spotipy/client.py", line 110, in _internal_call
    r = self._session.request(method, url, headers=headers, proxies=self.proxies, **args)
  File "/usr/lib/python3.6/site-packages/requests/sessions.py", line 508, in request
    resp = self.send(prep, **send_kwargs)
  File "/usr/lib/python3.6/site-packages/requests/sessions.py", line 618, in send
    r = adapter.send(request, **kwargs)
  File "/usr/lib/python3.6/site-packages/requests/adapters.py", line 508, in send
    raise ConnectionError(e, request=request)
requests.exceptions.ConnectionError: HTTPSConnectionPool(host='api.spotify.com', port=443): Max retries exceeded with url: /v1/me/player/devices (Caused by NewConnectionError('<urllib3.connection.VerifiedHTTPSConnection object at 0x72648ad0>: Failed to establish a new connection: [Errno -3] Try again',))
2017-12-24 10:51:31 ERROR (MainThread) [homeassistant.helpers.entity] Update for media_player.spotify fails
Traceback (most recent call last):
  File "/usr/lib/python3.6/site-packages/urllib3/connection.py", line 141, in _new_conn
    (self.host, self.port), self.timeout, **extra_kw)
  File "/usr/lib/python3.6/site-packages/urllib3/util/connection.py", line 60, in create_connection
    for res in socket.getaddrinfo(host, port, family, socket.SOCK_STREAM):
  File "/usr/lib/python3.6/socket.py", line 745, in getaddrinfo
    for res in _socket.getaddrinfo(host, port, family, type, proto, flags):
socket.gaierror: [Errno -3] Try again

During handling of the above exception, another exception occurred:

Traceback (most recent call last):
  File "/usr/lib/python3.6/site-packages/urllib3/connectionpool.py", line 601, in urlopen
    chunked=chunked)
  File "/usr/lib/python3.6/site-packages/urllib3/connectionpool.py", line 346, in _make_request
    self._validate_conn(conn)
  File "/usr/lib/python3.6/site-packages/urllib3/connectionpool.py", line 850, in _validate_conn
    conn.connect()
  File "/usr/lib/python3.6/site-packages/urllib3/connection.py", line 284, in connect
    conn = self._new_conn()
  File "/usr/lib/python3.6/site-packages/urllib3/connection.py", line 150, in _new_conn
    self, "Failed to establish a new connection: %s" % e)
urllib3.exceptions.NewConnectionError: <urllib3.connection.VerifiedHTTPSConnection object at 0x72688e50>: Failed to establish a new connection: [Errno -3] Try again

During handling of the above exception, another exception occurred:

Traceback (most recent call last):
  File "/usr/lib/python3.6/site-packages/requests/adapters.py", line 440, in send
    timeout=timeout
  File "/usr/lib/python3.6/site-packages/urllib3/connectionpool.py", line 639, in urlopen
    _stacktrace=sys.exc_info()[2])
  File "/usr/lib/python3.6/site-packages/urllib3/util/retry.py", line 388, in increment
    raise MaxRetryError(_pool, url, error or ResponseError(cause))
urllib3.exceptions.MaxRetryError: HTTPSConnectionPool(host='api.spotify.com', port=443): Max retries exceeded with url: /v1/me/player/devices (Caused by NewConnectionError('<urllib3.connection.VerifiedHTTPSConnection object at 0x72688e50>: Failed to establish a new connection: [Errno -3] Try again',))

During handling of the above exception, another exception occurred:

Traceback (most recent call last):
  File "/usr/lib/python3.6/site-packages/homeassistant/helpers/entity.py", line 199, in async_update_ha_state
    yield from self.async_device_update()
  File "/usr/lib/python3.6/site-packages/homeassistant/helpers/entity.py", line 306, in async_device_update
    yield from self.hass.async_add_job(self.update)
  File "/usr/lib/python3.6/asyncio/futures.py", line 332, in __iter__
    yield self  # This tells Task to wait for completion.
  File "/usr/lib/python3.6/asyncio/tasks.py", line 250, in _wakeup
    future.result()
  File "/usr/lib/python3.6/asyncio/futures.py", line 245, in result
    raise self._exception
  File "/usr/lib/python3.6/concurrent/futures/thread.py", line 56, in run
    result = self.fn(*self.args, **self.kwargs)
  File "/usr/lib/python3.6/site-packages/homeassistant/components/media_player/spotify.py", line 172, in update
    player_devices = self._player.devices()
  File "/usr/lib/python3.6/site-packages/spotipy/client.py", line 848, in devices
    return self._get("me/player/devices")
  File "/usr/lib/python3.6/site-packages/spotipy/client.py", line 148, in _get
    return self._internal_call('GET', url, payload, kwargs)
  File "/usr/lib/python3.6/site-packages/spotipy/client.py", line 110, in _internal_call
    r = self._session.request(method, url, headers=headers, proxies=self.proxies, **args)
  File "/usr/lib/python3.6/site-packages/requests/sessions.py", line 508, in request
    resp = self.send(prep, **send_kwargs)
  File "/usr/lib/python3.6/site-packages/requests/sessions.py", line 618, in send
    r = adapter.send(request, **kwargs)
  File "/usr/lib/python3.6/site-packages/requests/adapters.py", line 508, in send
    raise ConnectionError(e, request=request)
requests.exceptions.ConnectionError: HTTPSConnectionPool(host='api.spotify.com', port=443): Max retries exceeded with url: /v1/me/player/devices (Caused by NewConnectionError('<urllib3.connection.VerifiedHTTPSConnection object at 0x72688e50>: Failed to establish a new connection: [Errno -3] Try again',))
2017-12-24 10:53:36 ERROR (MainThread) [homeassistant.helpers.entity] Update for media_player.spotify fails
Traceback (most recent call last):
  File "/usr/lib/python3.6/site-packages/urllib3/connection.py", line 141, in _new_conn
    (self.host, self.port), self.timeout, **extra_kw)
  File "/usr/lib/python3.6/site-packages/urllib3/util/connection.py", line 60, in create_connection
    for res in socket.getaddrinfo(host, port, family, socket.SOCK_STREAM):
  File "/usr/lib/python3.6/socket.py", line 745, in getaddrinfo
    for res in _socket.getaddrinfo(host, port, family, type, proto, flags):
socket.gaierror: [Errno -3] Try again

During handling of the above exception, another exception occurred:

Traceback (most recent call last):
  File "/usr/lib/python3.6/site-packages/urllib3/connectionpool.py", line 601, in urlopen
    chunked=chunked)
  File "/usr/lib/python3.6/site-packages/urllib3/connectionpool.py", line 346, in _make_request
    self._validate_conn(conn)
  File "/usr/lib/python3.6/site-packages/urllib3/connectionpool.py", line 850, in _validate_conn
    conn.connect()
  File "/usr/lib/python3.6/site-packages/urllib3/connection.py", line 284, in connect
    conn = self._new_conn()
  File "/usr/lib/python3.6/site-packages/urllib3/connection.py", line 150, in _new_conn
    self, "Failed to establish a new connection: %s" % e)
urllib3.exceptions.NewConnectionError: <urllib3.connection.VerifiedHTTPSConnection object at 0x726cc4d0>: Failed to establish a new connection: [Errno -3] Try again

During handling of the above exception, another exception occurred:

Traceback (most recent call last):
  File "/usr/lib/python3.6/site-packages/requests/adapters.py", line 440, in send
    timeout=timeout
  File "/usr/lib/python3.6/site-packages/urllib3/connectionpool.py", line 639, in urlopen
    _stacktrace=sys.exc_info()[2])
  File "/usr/lib/python3.6/site-packages/urllib3/util/retry.py", line 388, in increment
    raise MaxRetryError(_pool, url, error or ResponseError(cause))
urllib3.exceptions.MaxRetryError: HTTPSConnectionPool(host='api.spotify.com', port=443): Max retries exceeded with url: /v1/me/ (Caused by NewConnectionError('<urllib3.connection.VerifiedHTTPSConnection object at 0x726cc4d0>: Failed to establish a new connection: [Errno -3] Try again',))

During handling of the above exception, another exception occurred:

Traceback (most recent call last):
  File "/usr/lib/python3.6/site-packages/homeassistant/helpers/entity.py", line 199, in async_update_ha_state
    yield from self.async_device_update()
  File "/usr/lib/python3.6/site-packages/homeassistant/helpers/entity.py", line 306, in async_device_update
    yield from self.hass.async_add_job(self.update)
  File "/usr/lib/python3.6/asyncio/futures.py", line 332, in __iter__
    yield self  # This tells Task to wait for completion.
  File "/usr/lib/python3.6/asyncio/tasks.py", line 250, in _wakeup
    future.result()
  File "/usr/lib/python3.6/asyncio/futures.py", line 245, in result
    raise self._exception
  File "/usr/lib/python3.6/concurrent/futures/thread.py", line 56, in run
    result = self.fn(*self.args, **self.kwargs)
  File "/usr/lib/python3.6/site-packages/homeassistant/components/media_player/spotify.py", line 164, in update
    self.refresh_spotify_instance()
  File "/usr/lib/python3.6/site-packages/homeassistant/components/media_player/spotify.py", line 160, in refresh_spotify_instance
    self._user = self._player.me()
  File "/usr/lib/python3.6/site-packages/spotipy/client.py", line 568, in me
    return self._get('me/')
  File "/usr/lib/python3.6/site-packages/spotipy/client.py", line 148, in _get
    return self._internal_call('GET', url, payload, kwargs)
  File "/usr/lib/python3.6/site-packages/spotipy/client.py", line 110, in _internal_call
    r = self._session.request(method, url, headers=headers, proxies=self.proxies, **args)
  File "/usr/lib/python3.6/site-packages/requests/sessions.py", line 508, in request
    resp = self.send(prep, **send_kwargs)
  File "/usr/lib/python3.6/site-packages/requests/sessions.py", line 618, in send
    r = adapter.send(request, **kwargs)
  File "/usr/lib/python3.6/site-packages/requests/adapters.py", line 508, in send
    raise ConnectionError(e, request=request)
requests.exceptions.ConnectionError: HTTPSConnectionPool(host='api.spotify.com', port=443): Max retries exceeded with url: /v1/me/ (Caused by NewConnectionError('<urllib3.connection.VerifiedHTTPSConnection object at 0x726cc4d0>: Failed to establish a new connection: [Errno -3] Try again',))
2017-12-24 11:26:06 ERROR (MainThread) [homeassistant.helpers.entity] Update for media_player.spotify fails
Traceback (most recent call last):
  File "/usr/lib/python3.6/site-packages/urllib3/connection.py", line 141, in _new_conn
    (self.host, self.port), self.timeout, **extra_kw)
  File "/usr/lib/python3.6/site-packages/urllib3/util/connection.py", line 60, in create_connection
    for res in socket.getaddrinfo(host, port, family, socket.SOCK_STREAM):
  File "/usr/lib/python3.6/socket.py", line 745, in getaddrinfo
    for res in _socket.getaddrinfo(host, port, family, type, proto, flags):
socket.gaierror: [Errno -3] Try again

During handling of the above exception, another exception occurred:

Traceback (most recent call last):
  File "/usr/lib/python3.6/site-packages/urllib3/connectionpool.py", line 601, in urlopen
    chunked=chunked)
  File "/usr/lib/python3.6/site-packages/urllib3/connectionpool.py", line 346, in _make_request
    self._validate_conn(conn)
  File "/usr/lib/python3.6/site-packages/urllib3/connectionpool.py", line 850, in _validate_conn
    conn.connect()
  File "/usr/lib/python3.6/site-packages/urllib3/connection.py", line 284, in connect
    conn = self._new_conn()
  File "/usr/lib/python3.6/site-packages/urllib3/connection.py", line 150, in _new_conn
    self, "Failed to establish a new connection: %s" % e)
urllib3.exceptions.NewConnectionError: <urllib3.connection.VerifiedHTTPSConnection object at 0x726945d0>: Failed to establish a new connection: [Errno -3] Try again

During handling of the above exception, another exception occurred:

Traceback (most recent call last):
  File "/usr/lib/python3.6/site-packages/requests/adapters.py", line 440, in send
    timeout=timeout
  File "/usr/lib/python3.6/site-packages/urllib3/connectionpool.py", line 639, in urlopen
    _stacktrace=sys.exc_info()[2])
  File "/usr/lib/python3.6/site-packages/urllib3/util/retry.py", line 388, in increment
    raise MaxRetryError(_pool, url, error or ResponseError(cause))
urllib3.exceptions.MaxRetryError: HTTPSConnectionPool(host='api.spotify.com', port=443): Max retries exceeded with url: /v1/me/player/devices (Caused by NewConnectionError('<urllib3.connection.VerifiedHTTPSConnection object at 0x726945d0>: Failed to establish a new connection: [Errno -3] Try again',))

During handling of the above exception, another exception occurred:

Traceback (most recent call last):
  File "/usr/lib/python3.6/site-packages/homeassistant/helpers/entity.py", line 199, in async_update_ha_state
    yield from self.async_device_update()
  File "/usr/lib/python3.6/site-packages/homeassistant/helpers/entity.py", line 306, in async_device_update
    yield from self.hass.async_add_job(self.update)
  File "/usr/lib/python3.6/asyncio/futures.py", line 332, in __iter__
    yield self  # This tells Task to wait for completion.
  File "/usr/lib/python3.6/asyncio/tasks.py", line 250, in _wakeup
    future.result()
  File "/usr/lib/python3.6/asyncio/futures.py", line 245, in result
    raise self._exception
  File "/usr/lib/python3.6/concurrent/futures/thread.py", line 56, in run
    result = self.fn(*self.args, **self.kwargs)
  File "/usr/lib/python3.6/site-packages/homeassistant/components/media_player/spotify.py", line 172, in update
    player_devices = self._player.devices()
  File "/usr/lib/python3.6/site-packages/spotipy/client.py", line 848, in devices
    return self._get("me/player/devices")
  File "/usr/lib/python3.6/site-packages/spotipy/client.py", line 148, in _get
    return self._internal_call('GET', url, payload, kwargs)
  File "/usr/lib/python3.6/site-packages/spotipy/client.py", line 110, in _internal_call
    r = self._session.request(method, url, headers=headers, proxies=self.proxies, **args)
  File "/usr/lib/python3.6/site-packages/requests/sessions.py", line 508, in request
    resp = self.send(prep, **send_kwargs)
  File "/usr/lib/python3.6/site-packages/requests/sessions.py", line 618, in send
    r = adapter.send(request, **kwargs)
  File "/usr/lib/python3.6/site-packages/requests/adapters.py", line 508, in send
    raise ConnectionError(e, request=request)
requests.exceptions.ConnectionError: HTTPSConnectionPool(host='api.spotify.com', port=443): Max retries exceeded with url: /v1/me/player/devices (Caused by NewConnectionError('<urllib3.connection.VerifiedHTTPSConnection object at 0x726945d0>: Failed to establish a new connection: [Errno -3] Try again',))
2017-12-24 12:21:24 ERROR (MainThread) [homeassistant.helpers.entity] Update for media_player.spotify fails
Traceback (most recent call last):
  File "/usr/lib/python3.6/site-packages/urllib3/connection.py", line 141, in _new_conn
    (self.host, self.port), self.timeout, **extra_kw)
  File "/usr/lib/python3.6/site-packages/urllib3/util/connection.py", line 60, in create_connection
    for res in socket.getaddrinfo(host, port, family, socket.SOCK_STREAM):
  File "/usr/lib/python3.6/socket.py", line 745, in getaddrinfo
    for res in _socket.getaddrinfo(host, port, family, type, proto, flags):
socket.gaierror: [Errno -3] Try again

During handling of the above exception, another exception occurred:

Traceback (most recent call last):
  File "/usr/lib/python3.6/site-packages/urllib3/connectionpool.py", line 601, in urlopen
    chunked=chunked)
  File "/usr/lib/python3.6/site-packages/urllib3/connectionpool.py", line 346, in _make_request
    self._validate_conn(conn)
  File "/usr/lib/python3.6/site-packages/urllib3/connectionpool.py", line 850, in _validate_conn
    conn.connect()
  File "/usr/lib/python3.6/site-packages/urllib3/connection.py", line 284, in connect
    conn = self._new_conn()
  File "/usr/lib/python3.6/site-packages/urllib3/connection.py", line 150, in _new_conn
    self, "Failed to establish a new connection: %s" % e)
urllib3.exceptions.NewConnectionError: <urllib3.connection.VerifiedHTTPSConnection object at 0x726fea30>: Failed to establish a new connection: [Errno -3] Try again

During handling of the above exception, another exception occurred:

Traceback (most recent call last):
  File "/usr/lib/python3.6/site-packages/requests/adapters.py", line 440, in send
    timeout=timeout
  File "/usr/lib/python3.6/site-packages/urllib3/connectionpool.py", line 639, in urlopen
    _stacktrace=sys.exc_info()[2])
  File "/usr/lib/python3.6/site-packages/urllib3/util/retry.py", line 388, in increment
    raise MaxRetryError(_pool, url, error or ResponseError(cause))
urllib3.exceptions.MaxRetryError: HTTPSConnectionPool(host='api.spotify.com', port=443): Max retries exceeded with url: /v1/me/player (Caused by NewConnectionError('<urllib3.connection.VerifiedHTTPSConnection object at 0x726fea30>: Failed to establish a new connection: [Errno -3] Try again',))

During handling of the above exception, another exception occurred:

Traceback (most recent call last):
  File "/usr/lib/python3.6/site-packages/homeassistant/helpers/entity.py", line 199, in async_update_ha_state
    yield from self.async_device_update()
  File "/usr/lib/python3.6/site-packages/homeassistant/helpers/entity.py", line 306, in async_device_update
    yield from self.hass.async_add_job(self.update)
  File "/usr/lib/python3.6/asyncio/futures.py", line 332, in __iter__
    yield self  # This tells Task to wait for completion.
  File "/usr/lib/python3.6/asyncio/tasks.py", line 250, in _wakeup
    future.result()
  File "/usr/lib/python3.6/asyncio/futures.py", line 245, in result
    raise self._exception
  File "/usr/lib/python3.6/concurrent/futures/thread.py", line 56, in run
    result = self.fn(*self.args, **self.kwargs)
  File "/usr/lib/python3.6/site-packages/homeassistant/components/media_player/spotify.py", line 186, in update
    current = self._player.current_playback()
  File "/usr/lib/python3.6/site-packages/spotipy/client.py", line 856, in current_playback
    return self._get("me/player", market = market)
  File "/usr/lib/python3.6/site-packages/spotipy/client.py", line 148, in _get
    return self._internal_call('GET', url, payload, kwargs)
  File "/usr/lib/python3.6/site-packages/spotipy/client.py", line 110, in _internal_call
    r = self._session.request(method, url, headers=headers, proxies=self.proxies, **args)
  File "/usr/lib/python3.6/site-packages/requests/sessions.py", line 508, in request
    resp = self.send(prep, **send_kwargs)
  File "/usr/lib/python3.6/site-packages/requests/sessions.py", line 618, in send
    r = adapter.send(request, **kwargs)
  File "/usr/lib/python3.6/site-packages/requests/adapters.py", line 508, in send
    raise ConnectionError(e, request=request)
requests.exceptions.ConnectionError: HTTPSConnectionPool(host='api.spotify.com', port=443): Max retries exceeded with url: /v1/me/player (Caused by NewConnectionError('<urllib3.connection.VerifiedHTTPSConnection object at 0x726fea30>: Failed to establish a new connection: [Errno -3] Try again',))
2017-12-24 12:33:16 ERROR (MainThread) [homeassistant.helpers.entity] Update for media_player.spotify fails
Traceback (most recent call last):
  File "/usr/lib/python3.6/site-packages/urllib3/connection.py", line 141, in _new_conn
    (self.host, self.port), self.timeout, **extra_kw)
  File "/usr/lib/python3.6/site-packages/urllib3/util/connection.py", line 60, in create_connection
    for res in socket.getaddrinfo(host, port, family, socket.SOCK_STREAM):
  File "/usr/lib/python3.6/socket.py", line 745, in getaddrinfo
    for res in _socket.getaddrinfo(host, port, family, type, proto, flags):
socket.gaierror: [Errno -3] Try again

During handling of the above exception, another exception occurred:

Traceback (most recent call last):
  File "/usr/lib/python3.6/site-packages/urllib3/connectionpool.py", line 601, in urlopen
    chunked=chunked)
  File "/usr/lib/python3.6/site-packages/urllib3/connectionpool.py", line 346, in _make_request
    self._validate_conn(conn)
  File "/usr/lib/python3.6/site-packages/urllib3/connectionpool.py", line 850, in _validate_conn
    conn.connect()
  File "/usr/lib/python3.6/site-packages/urllib3/connection.py", line 284, in connect
    conn = self._new_conn()
  File "/usr/lib/python3.6/site-packages/urllib3/connection.py", line 150, in _new_conn
    self, "Failed to establish a new connection: %s" % e)
urllib3.exceptions.NewConnectionError: <urllib3.connection.VerifiedHTTPSConnection object at 0x6fdfa0d0>: Failed to establish a new connection: [Errno -3] Try again

During handling of the above exception, another exception occurred:

Traceback (most recent call last):
  File "/usr/lib/python3.6/site-packages/requests/adapters.py", line 440, in send
    timeout=timeout
  File "/usr/lib/python3.6/site-packages/urllib3/connectionpool.py", line 639, in urlopen
    _stacktrace=sys.exc_info()[2])
  File "/usr/lib/python3.6/site-packages/urllib3/util/retry.py", line 388, in increment
    raise MaxRetryError(_pool, url, error or ResponseError(cause))
urllib3.exceptions.MaxRetryError: HTTPSConnectionPool(host='api.spotify.com', port=443): Max retries exceeded with url: /v1/me/player/devices (Caused by NewConnectionError('<urllib3.connection.VerifiedHTTPSConnection object at 0x6fdfa0d0>: Failed to establish a new connection: [Errno -3] Try again',))

During handling of the above exception, another exception occurred:

Traceback (most recent call last):
  File "/usr/lib/python3.6/site-packages/homeassistant/helpers/entity.py", line 199, in async_update_ha_state
    yield from self.async_device_update()
  File "/usr/lib/python3.6/site-packages/homeassistant/helpers/entity.py", line 306, in async_device_update
    yield from self.hass.async_add_job(self.update)
  File "/usr/lib/python3.6/asyncio/futures.py", line 332, in __iter__
    yield self  # This tells Task to wait for completion.
  File "/usr/lib/python3.6/asyncio/tasks.py", line 250, in _wakeup
    future.result()
  File "/usr/lib/python3.6/asyncio/futures.py", line 245, in result
    raise self._exception
  File "/usr/lib/python3.6/concurrent/futures/thread.py", line 56, in run
    result = self.fn(*self.args, **self.kwargs)
  File "/usr/lib/python3.6/site-packages/homeassistant/components/media_player/spotify.py", line 172, in update
    player_devices = self._player.devices()
  File "/usr/lib/python3.6/site-packages/spotipy/client.py", line 848, in devices
    return self._get("me/player/devices")
  File "/usr/lib/python3.6/site-packages/spotipy/client.py", line 148, in _get
    return self._internal_call('GET', url, payload, kwargs)
  File "/usr/lib/python3.6/site-packages/spotipy/client.py", line 110, in _internal_call
    r = self._session.request(method, url, headers=headers, proxies=self.proxies, **args)
  File "/usr/lib/python3.6/site-packages/requests/sessions.py", line 508, in request
    resp = self.send(prep, **send_kwargs)
  File "/usr/lib/python3.6/site-packages/requests/sessions.py", line 618, in send
    r = adapter.send(request, **kwargs)
  File "/usr/lib/python3.6/site-packages/requests/adapters.py", line 508, in send
    raise ConnectionError(e, request=request)
requests.exceptions.ConnectionError: HTTPSConnectionPool(host='api.spotify.com', port=443): Max retries exceeded with url: /v1/me/player/devices (Caused by NewConnectionError('<urllib3.connection.VerifiedHTTPSConnection object at 0x6fdfa0d0>: Failed to establish a new connection: [Errno -3] Try again',))
2017-12-24 13:13:04 ERROR (MainThread) [homeassistant.helpers.entity] Update for media_player.spotify fails
Traceback (most recent call last):
  File "/usr/lib/python3.6/site-packages/urllib3/connection.py", line 141, in _new_conn
    (self.host, self.port), self.timeout, **extra_kw)
  File "/usr/lib/python3.6/site-packages/urllib3/util/connection.py", line 60, in create_connection
    for res in socket.getaddrinfo(host, port, family, socket.SOCK_STREAM):
  File "/usr/lib/python3.6/socket.py", line 745, in getaddrinfo
    for res in _socket.getaddrinfo(host, port, family, type, proto, flags):
socket.gaierror: [Errno -3] Try again

During handling of the above exception, another exception occurred:

Traceback (most recent call last):
  File "/usr/lib/python3.6/site-packages/urllib3/connectionpool.py", line 601, in urlopen
    chunked=chunked)
  File "/usr/lib/python3.6/site-packages/urllib3/connectionpool.py", line 346, in _make_request
    self._validate_conn(conn)
  File "/usr/lib/python3.6/site-packages/urllib3/connectionpool.py", line 850, in _validate_conn
    conn.connect()
  File "/usr/lib/python3.6/site-packages/urllib3/connection.py", line 284, in connect
    conn = self._new_conn()
  File "/usr/lib/python3.6/site-packages/urllib3/connection.py", line 150, in _new_conn
    self, "Failed to establish a new connection: %s" % e)
urllib3.exceptions.NewConnectionError: <urllib3.connection.VerifiedHTTPSConnection object at 0x72667d70>: Failed to establish a new connection: [Errno -3] Try again

During handling of the above exception, another exception occurred:

Traceback (most recent call last):
  File "/usr/lib/python3.6/site-packages/requests/adapters.py", line 440, in send
    timeout=timeout
  File "/usr/lib/python3.6/site-packages/urllib3/connectionpool.py", line 639, in urlopen
    _stacktrace=sys.exc_info()[2])
  File "/usr/lib/python3.6/site-packages/urllib3/util/retry.py", line 388, in increment
    raise MaxRetryError(_pool, url, error or ResponseError(cause))
urllib3.exceptions.MaxRetryError: HTTPSConnectionPool(host='api.spotify.com', port=443): Max retries exceeded with url: /v1/me/player (Caused by NewConnectionError('<urllib3.connection.VerifiedHTTPSConnection object at 0x72667d70>: Failed to establish a new connection: [Errno -3] Try again',))

During handling of the above exception, another exception occurred:

Traceback (most recent call last):
  File "/usr/lib/python3.6/site-packages/homeassistant/helpers/entity.py", line 199, in async_update_ha_state
    yield from self.async_device_update()
  File "/usr/lib/python3.6/site-packages/homeassistant/helpers/entity.py", line 306, in async_device_update
    yield from self.hass.async_add_job(self.update)
  File "/usr/lib/python3.6/asyncio/futures.py", line 332, in __iter__
    yield self  # This tells Task to wait for completion.
  File "/usr/lib/python3.6/asyncio/tasks.py", line 250, in _wakeup
    future.result()
  File "/usr/lib/python3.6/asyncio/futures.py", line 245, in result
    raise self._exception
  File "/usr/lib/python3.6/concurrent/futures/thread.py", line 56, in run
    result = self.fn(*self.args, **self.kwargs)
  File "/usr/lib/python3.6/site-packages/homeassistant/components/media_player/spotify.py", line 186, in update
    current = self._player.current_playback()
  File "/usr/lib/python3.6/site-packages/spotipy/client.py", line 856, in current_playback
    return self._get("me/player", market = market)
  File "/usr/lib/python3.6/site-packages/spotipy/client.py", line 148, in _get
    return self._internal_call('GET', url, payload, kwargs)
  File "/usr/lib/python3.6/site-packages/spotipy/client.py", line 110, in _internal_call
    r = self._session.request(method, url, headers=headers, proxies=self.proxies, **args)
  File "/usr/lib/python3.6/site-packages/requests/sessions.py", line 508, in request
    resp = self.send(prep, **send_kwargs)
  File "/usr/lib/python3.6/site-packages/requests/sessions.py", line 618, in send
    r = adapter.send(request, **kwargs)
  File "/usr/lib/python3.6/site-packages/requests/adapters.py", line 508, in send
    raise ConnectionError(e, request=request)
requests.exceptions.ConnectionError: HTTPSConnectionPool(host='api.spotify.com', port=443): Max retries exceeded with url: /v1/me/player (Caused by NewConnectionError('<urllib3.connection.VerifiedHTTPSConnection object at 0x72667d70>: Failed to establish a new connection: [Errno -3] Try again',))
2017-12-24 13:28:00 WARNING (MainThread) [haffmpeg.tools] Timeout reading image.
2017-12-24 13:28:06 WARNING (MainThread) [haffmpeg.tools] Timeout reading image.
2017-12-24 13:28:16 WARNING (MainThread) [haffmpeg.tools] Timeout reading image.
2017-12-24 13:28:27 WARNING (MainThread) [haffmpeg.tools] Timeout reading image.
2017-12-24 13:28:36 WARNING (MainThread) [haffmpeg.tools] Timeout reading image.
2017-12-24 13:28:46 WARNING (MainThread) [haffmpeg.tools] Timeout reading image.
2017-12-24 13:28:56 WARNING (MainThread) [haffmpeg.tools] Timeout reading image.
2017-12-24 13:29:06 WARNING (MainThread) [haffmpeg.tools] Timeout reading image.
2017-12-24 13:29:14 WARNING (Thread-4) [pychromecast.socket_client] Heartbeat timeout, resetting connection
2017-12-24 13:29:16 WARNING (MainThread) [haffmpeg.tools] Timeout reading image.
2017-12-24 13:29:26 WARNING (MainThread) [haffmpeg.tools] Timeout reading image.
2017-12-24 13:29:36 WARNING (MainThread) [haffmpeg.tools] Timeout reading image.
2017-12-24 13:29:44 ERROR (Thread-4) [pychromecast.socket_client] Failed to connect, retrying in 5.0s
2017-12-24 13:29:46 WARNING (MainThread) [haffmpeg.tools] Timeout reading image.
2017-12-24 13:29:46 WARNING (MainThread) [haffmpeg.tools] Timeout reading image.
2017-12-24 13:29:56 WARNING (MainThread) [haffmpeg.tools] Timeout reading image.
2017-12-24 13:30:06 WARNING (MainThread) [haffmpeg.tools] Timeout reading image.
2017-12-24 13:30:16 WARNING (MainThread) [haffmpeg.tools] Timeout reading image.
2017-12-24 13:30:26 WARNING (MainThread) [haffmpeg.tools] Timeout reading image.
2017-12-24 13:30:36 WARNING (MainThread) [haffmpeg.tools] Timeout reading image.
2017-12-24 13:30:46 WARNING (MainThread) [haffmpeg.tools] Timeout reading image.
2017-12-24 13:30:56 WARNING (MainThread) [haffmpeg.tools] Timeout reading image.
2017-12-24 13:31:06 WARNING (MainThread) [haffmpeg.tools] Timeout reading image.
2017-12-24 13:31:16 WARNING (MainThread) [haffmpeg.tools] Timeout reading image.
2017-12-24 13:31:26 WARNING (MainThread) [haffmpeg.tools] Timeout reading image.
2017-12-24 13:31:36 WARNING (MainThread) [haffmpeg.tools] Timeout reading image.
2017-12-24 13:31:46 WARNING (MainThread) [haffmpeg.tools] Timeout reading image.
2017-12-24 13:31:56 WARNING (MainThread) [haffmpeg.tools] Timeout reading image.
2017-12-24 13:32:06 WARNING (MainThread) [haffmpeg.tools] Timeout reading image.
2017-12-24 13:32:16 WARNING (MainThread) [haffmpeg.tools] Timeout reading image.
2017-12-24 13:32:26 WARNING (MainThread) [haffmpeg.tools] Timeout reading image.
2017-12-24 13:32:36 WARNING (MainThread) [haffmpeg.tools] Timeout reading image.
2017-12-24 13:32:46 WARNING (MainThread) [haffmpeg.tools] Timeout reading image.
2017-12-24 13:32:56 WARNING (MainThread) [haffmpeg.tools] Timeout reading image.
2017-12-24 13:33:06 WARNING (MainThread) [haffmpeg.tools] Timeout reading image.
2017-12-24 13:33:16 WARNING (MainThread) [haffmpeg.tools] Timeout reading image.
2017-12-24 13:33:26 WARNING (MainThread) [haffmpeg.tools] Timeout reading image.
2017-12-24 13:33:36 WARNING (MainThread) [haffmpeg.tools] Timeout reading image.
2017-12-24 13:33:46 WARNING (MainThread) [haffmpeg.tools] Timeout reading image.
2017-12-24 13:33:56 WARNING (MainThread) [haffmpeg.tools] Timeout reading image.
2017-12-24 13:34:06 WARNING (MainThread) [haffmpeg.tools] Timeout reading image.
2017-12-24 13:34:16 WARNING (MainThread) [haffmpeg.tools] Timeout reading image.
2017-12-24 13:34:26 WARNING (MainThread) [haffmpeg.tools] Timeout reading image.
2017-12-24 13:34:36 WARNING (MainThread) [haffmpeg.tools] Timeout reading image.
2017-12-24 13:34:46 WARNING (MainThread) [haffmpeg.tools] Timeout reading image.
2017-12-24 13:34:47 WARNING (MainThread) [haffmpeg.tools] Timeout reading image.
2017-12-24 13:34:56 WARNING (MainThread) [haffmpeg.tools] Timeout reading image.
2017-12-24 13:35:06 WARNING (MainThread) [haffmpeg.tools] Timeout reading image.
2017-12-24 13:35:16 WARNING (MainThread) [haffmpeg.tools] Timeout reading image.
2017-12-24 13:35:26 WARNING (MainThread) [haffmpeg.tools] Timeout reading image.
2017-12-24 13:35:36 WARNING (MainThread) [haffmpeg.tools] Timeout reading image.
2017-12-24 13:35:46 WARNING (MainThread) [haffmpeg.tools] Timeout reading image.
2017-12-24 13:35:56 WARNING (MainThread) [haffmpeg.tools] Timeout reading image.
2017-12-24 13:36:06 WARNING (MainThread) [haffmpeg.tools] Timeout reading image.
2017-12-24 13:36:16 WARNING (MainThread) [haffmpeg.tools] Timeout reading image.
2017-12-24 13:36:26 WARNING (MainThread) [haffmpeg.tools] Timeout reading image.
2017-12-24 13:36:36 WARNING (MainThread) [haffmpeg.tools] Timeout reading image.
2017-12-24 13:36:46 WARNING (MainThread) [haffmpeg.tools] Timeout reading image.
2017-12-24 13:36:56 WARNING (MainThread) [haffmpeg.tools] Timeout reading image.
2017-12-24 13:37:06 WARNING (MainThread) [haffmpeg.tools] Timeout reading image.
2017-12-24 13:37:16 WARNING (MainThread) [haffmpeg.tools] Timeout reading image.
2017-12-24 13:37:26 WARNING (MainThread) [haffmpeg.tools] Timeout reading image.
2017-12-24 13:37:36 WARNING (MainThread) [haffmpeg.tools] Timeout reading image.
2017-12-24 13:37:46 WARNING (MainThread) [haffmpeg.tools] Timeout reading image.
2017-12-24 13:37:56 WARNING (MainThread) [haffmpeg.tools] Timeout reading image.
2017-12-24 13:38:06 WARNING (MainThread) [haffmpeg.tools] Timeout reading image.
2017-12-24 13:38:16 WARNING (MainThread) [haffmpeg.tools] Timeout reading image.
2017-12-24 13:38:26 WARNING (MainThread) [haffmpeg.tools] Timeout reading image.
2017-12-24 13:38:36 WARNING (MainThread) [haffmpeg.tools] Timeout reading image.
2017-12-24 13:38:46 WARNING (MainThread) [haffmpeg.tools] Timeout reading image.
2017-12-24 13:38:56 WARNING (MainThread) [haffmpeg.tools] Timeout reading image.
2017-12-24 13:39:06 WARNING (MainThread) [haffmpeg.tools] Timeout reading image.
2017-12-24 13:39:16 WARNING (MainThread) [haffmpeg.tools] Timeout reading image.
2017-12-24 13:39:26 WARNING (MainThread) [haffmpeg.tools] Timeout reading image.
2017-12-24 13:39:36 WARNING (MainThread) [haffmpeg.tools] Timeout reading image.
2017-12-24 13:39:46 WARNING (MainThread) [haffmpeg.tools] Timeout reading image.
2017-12-24 13:39:56 WARNING (MainThread) [haffmpeg.tools] Timeout reading image.
2017-12-24 13:40:06 WARNING (MainThread) [haffmpeg.tools] Timeout reading image.
2017-12-24 13:40:16 WARNING (MainThread) [haffmpeg.tools] Timeout reading image.
2017-12-24 13:40:26 WARNING (MainThread) [haffmpeg.tools] Timeout reading image.
2017-12-24 13:40:36 WARNING (MainThread) [haffmpeg.tools] Timeout reading image.
2017-12-24 13:40:46 WARNING (MainThread) [haffmpeg.tools] Timeout reading image.
2017-12-24 13:40:51 ERROR (MainThread) [homeassistant.helpers.entity] Update for media_player.spotify fails
Traceback (most recent call last):
  File "/usr/lib/python3.6/site-packages/urllib3/util/ssl_.py", line 313, in ssl_wrap_socket
    context.load_verify_locations(ca_certs, ca_cert_dir)
OSError: [Errno 9] Bad file descriptor

During handling of the above exception, another exception occurred:

Traceback (most recent call last):
  File "/usr/lib/python3.6/site-packages/urllib3/connectionpool.py", line 601, in urlopen
    chunked=chunked)
  File "/usr/lib/python3.6/site-packages/urllib3/connectionpool.py", line 346, in _make_request
    self._validate_conn(conn)
  File "/usr/lib/python3.6/site-packages/urllib3/connectionpool.py", line 850, in _validate_conn
    conn.connect()
  File "/usr/lib/python3.6/site-packages/urllib3/connection.py", line 326, in connect
    ssl_context=context)
  File "/usr/lib/python3.6/site-packages/urllib3/util/ssl_.py", line 315, in ssl_wrap_socket
    raise SSLError(e)
urllib3.exceptions.SSLError: [Errno 9] Bad file descriptor

During handling of the above exception, another exception occurred:

Traceback (most recent call last):
  File "/usr/lib/python3.6/site-packages/requests/adapters.py", line 440, in send
    timeout=timeout
  File "/usr/lib/python3.6/site-packages/urllib3/connectionpool.py", line 639, in urlopen
    _stacktrace=sys.exc_info()[2])
  File "/usr/lib/python3.6/site-packages/urllib3/util/retry.py", line 388, in increment
    raise MaxRetryError(_pool, url, error or ResponseError(cause))
urllib3.exceptions.MaxRetryError: HTTPSConnectionPool(host='api.spotify.com', port=443): Max retries exceeded with url: /v1/me/player (Caused by SSLError(OSError(9, 'Bad file descriptor'),))

During handling of the above exception, another exception occurred:

Traceback (most recent call last):
  File "/usr/lib/python3.6/site-packages/homeassistant/helpers/entity.py", line 199, in async_update_ha_state
    yield from self.async_device_update()
  File "/usr/lib/python3.6/site-packages/homeassistant/helpers/entity.py", line 306, in async_device_update
    yield from self.hass.async_add_job(self.update)
  File "/usr/lib/python3.6/asyncio/futures.py", line 332, in __iter__
    yield self  # This tells Task to wait for completion.
  File "/usr/lib/python3.6/asyncio/tasks.py", line 250, in _wakeup
    future.result()
  File "/usr/lib/python3.6/asyncio/futures.py", line 245, in result
    raise self._exception
  File "/usr/lib/python3.6/concurrent/futures/thread.py", line 56, in run
    result = self.fn(*self.args, **self.kwargs)
  File "/usr/lib/python3.6/site-packages/homeassistant/components/media_player/spotify.py", line 186, in update
    current = self._player.current_playback()
  File "/usr/lib/python3.6/site-packages/spotipy/client.py", line 856, in current_playback
    return self._get("me/player", market = market)
  File "/usr/lib/python3.6/site-packages/spotipy/client.py", line 148, in _get
    return self._internal_call('GET', url, payload, kwargs)
  File "/usr/lib/python3.6/site-packages/spotipy/client.py", line 110, in _internal_call
    r = self._session.request(method, url, headers=headers, proxies=self.proxies, **args)
  File "/usr/lib/python3.6/site-packages/requests/sessions.py", line 508, in request
    resp = self.send(prep, **send_kwargs)
  File "/usr/lib/python3.6/site-packages/requests/sessions.py", line 618, in send
    r = adapter.send(request, **kwargs)
  File "/usr/lib/python3.6/site-packages/requests/adapters.py", line 506, in send
    raise SSLError(e, request=request)
requests.exceptions.SSLError: HTTPSConnectionPool(host='api.spotify.com', port=443): Max retries exceeded with url: /v1/me/player (Caused by SSLError(OSError(9, 'Bad file descriptor'),))
2017-12-24 13:40:56 WARNING (MainThread) [haffmpeg.tools] Timeout reading image.
2017-12-24 13:41:06 WARNING (MainThread) [haffmpeg.tools] Timeout reading image.
2017-12-24 13:41:16 WARNING (MainThread) [haffmpeg.tools] Timeout reading image.
2017-12-24 13:41:26 WARNING (MainThread) [haffmpeg.tools] Timeout reading image.
2017-12-24 13:41:36 WARNING (MainThread) [haffmpeg.tools] Timeout reading image.
2017-12-24 13:41:46 WARNING (MainThread) [haffmpeg.tools] Timeout reading image.
2017-12-24 13:41:56 WARNING (MainThread) [haffmpeg.tools] Timeout reading image.
2017-12-24 13:42:06 WARNING (MainThread) [haffmpeg.tools] Timeout reading image.
2017-12-24 13:42:16 WARNING (MainThread) [haffmpeg.tools] Timeout reading image.
2017-12-24 13:42:26 WARNING (MainThread) [haffmpeg.tools] Timeout reading image.
2017-12-24 13:42:36 WARNING (MainThread) [haffmpeg.tools] Timeout reading image.
2017-12-24 13:42:46 WARNING (MainThread) [haffmpeg.tools] Timeout reading image.
2017-12-24 13:42:56 WARNING (MainThread) [haffmpeg.tools] Timeout reading image.
2017-12-24 13:43:06 WARNING (MainThread) [haffmpeg.tools] Timeout reading image.
2017-12-24 13:43:16 WARNING (MainThread) [haffmpeg.tools] Timeout reading image.
2017-12-24 13:43:26 WARNING (MainThread) [haffmpeg.tools] Timeout reading image.
2017-12-24 13:43:36 WARNING (MainThread) [haffmpeg.tools] Timeout reading image.
2017-12-24 13:43:46 WARNING (MainThread) [haffmpeg.tools] Timeout reading image.
2017-12-24 13:43:56 WARNING (MainThread) [haffmpeg.tools] Timeout reading image.
2017-12-24 13:44:06 WARNING (MainThread) [haffmpeg.tools] Timeout reading image.
2017-12-24 13:44:11 WARNING (MainThread) [homeassistant.components.cloud.iot] Connection closed: Connection cancelled.
