2018-04-11 23:11:21 WARNING (MainThread) [homeassistant.setup] Setup of input_number is taking over 10 seconds.
2018-04-11 23:11:23 ERROR (SyncWorker_17) [homeassistant.components.sensor.rest] Error fetching data: <PreparedRequest [POST]>
2018-04-11 23:11:23 WARNING (MainThread) [homeassistant.setup] Setup of input_boolean is taking over 10 seconds.
2018-04-11 23:11:23 WARNING (MainThread) [homeassistant.setup] Setup of input_select is taking over 10 seconds.
2018-04-11 23:11:26 WARNING (MainThread) [homeassistant.setup] Setup of input_text is taking over 10 seconds.
2018-04-11 23:11:26 WARNING (MainThread) [homeassistant.setup] Setup of input_datetime is taking over 10 seconds.
2018-04-11 23:11:26 WARNING (MainThread) [homeassistant.components.sensor] Setup of platform command_line is taking over 10 seconds.
2018-04-11 23:11:27 WARNING (MainThread) [homeassistant.components.binary_sensor] Setup of platform ping is taking over 10 seconds.
2018-04-11 23:12:12 WARNING (MainThread) [homeassistant.components.media_player] Setup of platform spotify is taking over 10 seconds.
2018-04-11 23:12:31 ERROR (MainThread) [homeassistant.core] Error doing job: Future exception was never retrieved
Traceback (most recent call last):
  File "/usr/lib/python3.6/site-packages/urllib3/connection.py", line 141, in _new_conn
    (self.host, self.port), self.timeout, **extra_kw)
  File "/usr/lib/python3.6/site-packages/urllib3/util/connection.py", line 60, in create_connection
    for res in socket.getaddrinfo(host, port, family, socket.SOCK_STREAM):
  File "/usr/lib/python3.6/socket.py", line 745, in getaddrinfo
    for res in _socket.getaddrinfo(host, port, family, type, proto, flags):
socket.gaierror: [Errno -3] Try again

During handling of the above exception, another exception occurred:

Traceback (most recent call last):
  File "/usr/lib/python3.6/site-packages/urllib3/connectionpool.py", line 601, in urlopen
    chunked=chunked)
  File "/usr/lib/python3.6/site-packages/urllib3/connectionpool.py", line 346, in _make_request
    self._validate_conn(conn)
  File "/usr/lib/python3.6/site-packages/urllib3/connectionpool.py", line 850, in _validate_conn
    conn.connect()
  File "/usr/lib/python3.6/site-packages/urllib3/connection.py", line 284, in connect
    conn = self._new_conn()
  File "/usr/lib/python3.6/site-packages/urllib3/connection.py", line 150, in _new_conn
    self, "Failed to establish a new connection: %s" % e)
urllib3.exceptions.NewConnectionError: <urllib3.connection.VerifiedHTTPSConnection object at 0x74766f90>: Failed to establish a new connection: [Errno -3] Try again

During handling of the above exception, another exception occurred:

Traceback (most recent call last):
  File "/usr/lib/python3.6/site-packages/requests/adapters.py", line 440, in send
    timeout=timeout
  File "/usr/lib/python3.6/site-packages/urllib3/connectionpool.py", line 639, in urlopen
    _stacktrace=sys.exc_info()[2])
  File "/usr/lib/python3.6/site-packages/urllib3/util/retry.py", line 388, in increment
    raise MaxRetryError(_pool, url, error or ResponseError(cause))
urllib3.exceptions.MaxRetryError: HTTPSConnectionPool(host='maps.googleapis.com', port=443): Max retries exceeded with url: /maps/api/distancematrix/json?departure_time=now&destinations=R.+Prof.+Ulisses+Vieira%2C+2809+-+Santa+Quiteria%2C+Curitiba+-+PR%2C+80310-120&mode=driving&origins=-25.4517535%2C-49.3433857&units=metric&key=AIzaSyDqHMdgfqGyEvYvke640j5BF2ejRrLOMCM (Caused by NewConnectionError('<urllib3.connection.VerifiedHTTPSConnection object at 0x74766f90>: Failed to establish a new connection: [Errno -3] Try again',))

During handling of the above exception, another exception occurred:

Traceback (most recent call last):
  File "/usr/lib/python3.6/site-packages/googlemaps/client.py", line 229, in _request
    **final_requests_kwargs)
  File "/usr/lib/python3.6/site-packages/requests/sessions.py", line 521, in get
    return self.request('GET', url, **kwargs)
  File "/usr/lib/python3.6/site-packages/requests/sessions.py", line 508, in request
    resp = self.send(prep, **send_kwargs)
  File "/usr/lib/python3.6/site-packages/requests/sessions.py", line 618, in send
    r = adapter.send(request, **kwargs)
  File "/usr/lib/python3.6/site-packages/requests/adapters.py", line 508, in send
    raise ConnectionError(e, request=request)
requests.exceptions.ConnectionError: HTTPSConnectionPool(host='maps.googleapis.com', port=443): Max retries exceeded with url: /maps/api/distancematrix/json?departure_time=now&destinations=R.+Prof.+Ulisses+Vieira%2C+2809+-+Santa+Quiteria%2C+Curitiba+-+PR%2C+80310-120&mode=driving&origins=-25.4517535%2C-49.3433857&units=metric&key=AIzaSyDqHMdgfqGyEvYvke640j5BF2ejRrLOMCM (Caused by NewConnectionError('<urllib3.connection.VerifiedHTTPSConnection object at 0x74766f90>: Failed to establish a new connection: [Errno -3] Try again',))

During handling of the above exception, another exception occurred:

Traceback (most recent call last):
  File "/usr/lib/python3.6/concurrent/futures/thread.py", line 56, in run
    result = self.fn(*self.args, **self.kwargs)
  File "/usr/lib/python3.6/site-packages/homeassistant/components/sensor/google_travel_time.py", line 112, in run_setup
    hass, name, api_key, origin, destination, options)
  File "/usr/lib/python3.6/site-packages/homeassistant/components/sensor/google_travel_time.py", line 147, in __init__
    self.update()
  File "/usr/lib/python3.6/site-packages/homeassistant/util/__init__.py", line 319, in wrapper
    result = method(*args, **kwargs)
  File "/usr/lib/python3.6/site-packages/homeassistant/components/sensor/google_travel_time.py", line 228, in update
    self._origin, self._destination, **options_copy)
  File "/usr/lib/python3.6/site-packages/googlemaps/client.py", line 356, in wrapper
    result = func(*args, **kwargs)
  File "/usr/lib/python3.6/site-packages/googlemaps/distance_matrix.py", line 130, in distance_matrix
    return client._request("/maps/api/distancematrix/json", params)
  File "/usr/lib/python3.6/site-packages/googlemaps/client.py", line 233, in _request
    raise googlemaps.exceptions.TransportError(e)
googlemaps.exceptions.TransportError: HTTPSConnectionPool(host='maps.googleapis.com', port=443): Max retries exceeded with url: /maps/api/distancematrix/json?departure_time=now&destinations=R.+Prof.+Ulisses+Vieira%2C+2809+-+Santa+Quiteria%2C+Curitiba+-+PR%2C+80310-120&mode=driving&origins=-25.4517535%2C-49.3433857&units=metric&key=AIzaSyDqHMdgfqGyEvYvke640j5BF2ejRrLOMCM (Caused by NewConnectionError('<urllib3.connection.VerifiedHTTPSConnection object at 0x74766f90>: Failed to establish a new connection: [Errno -3] Try again',))
2018-04-11 23:12:31 ERROR (SyncWorker_11) [homeassistant.components.sensor.rest] Error fetching data: <PreparedRequest [GET]>
2018-04-11 23:12:32 WARNING (SyncWorker_16) [telegram.vendor.ptb_urllib3.urllib3.connectionpool] Retrying (Retry(total=2, connect=None, read=None, redirect=None)) after connection broken by 'NewConnectionError('<telegram.vendor.ptb_urllib3.urllib3.connection.VerifiedHTTPSConnection object at 0x6d962390>: Failed to establish a new connection: [Errno -3] Try again',)': /bot362729958:AAEovrEKEa88VlU5iC6Mbm7A2_pZJUf5brI/sendMessage
2018-04-11 23:12:32 ERROR (MainThread) [homeassistant.core] Error doing job: Future exception was never retrieved
Traceback (most recent call last):
  File "/usr/lib/python3.6/site-packages/urllib3/connection.py", line 141, in _new_conn
    (self.host, self.port), self.timeout, **extra_kw)
  File "/usr/lib/python3.6/site-packages/urllib3/util/connection.py", line 60, in create_connection
    for res in socket.getaddrinfo(host, port, family, socket.SOCK_STREAM):
  File "/usr/lib/python3.6/socket.py", line 745, in getaddrinfo
    for res in _socket.getaddrinfo(host, port, family, type, proto, flags):
socket.gaierror: [Errno -3] Try again

During handling of the above exception, another exception occurred:

Traceback (most recent call last):
  File "/usr/lib/python3.6/site-packages/urllib3/connectionpool.py", line 601, in urlopen
    chunked=chunked)
  File "/usr/lib/python3.6/site-packages/urllib3/connectionpool.py", line 346, in _make_request
    self._validate_conn(conn)
  File "/usr/lib/python3.6/site-packages/urllib3/connectionpool.py", line 850, in _validate_conn
    conn.connect()
  File "/usr/lib/python3.6/site-packages/urllib3/connection.py", line 284, in connect
    conn = self._new_conn()
  File "/usr/lib/python3.6/site-packages/urllib3/connection.py", line 150, in _new_conn
    self, "Failed to establish a new connection: %s" % e)
urllib3.exceptions.NewConnectionError: <urllib3.connection.VerifiedHTTPSConnection object at 0x74766310>: Failed to establish a new connection: [Errno -3] Try again

During handling of the above exception, another exception occurred:

Traceback (most recent call last):
  File "/usr/lib/python3.6/site-packages/requests/adapters.py", line 440, in send
    timeout=timeout
  File "/usr/lib/python3.6/site-packages/urllib3/connectionpool.py", line 639, in urlopen
    _stacktrace=sys.exc_info()[2])
  File "/usr/lib/python3.6/site-packages/urllib3/util/retry.py", line 388, in increment
    raise MaxRetryError(_pool, url, error or ResponseError(cause))
urllib3.exceptions.MaxRetryError: HTTPSConnectionPool(host='maps.googleapis.com', port=443): Max retries exceeded with url: /maps/api/distancematrix/json?departure_time=now&destinations=unknown&mode=driving&origins=-25.4517535%2C-49.3433857&units=metric&key=AIzaSyDqHMdgfqGyEvYvke640j5BF2ejRrLOMCM (Caused by NewConnectionError('<urllib3.connection.VerifiedHTTPSConnection object at 0x74766310>: Failed to establish a new connection: [Errno -3] Try again',))

During handling of the above exception, another exception occurred:

Traceback (most recent call last):
  File "/usr/lib/python3.6/site-packages/googlemaps/client.py", line 229, in _request
    **final_requests_kwargs)
  File "/usr/lib/python3.6/site-packages/requests/sessions.py", line 521, in get
    return self.request('GET', url, **kwargs)
  File "/usr/lib/python3.6/site-packages/requests/sessions.py", line 508, in request
    resp = self.send(prep, **send_kwargs)
  File "/usr/lib/python3.6/site-packages/requests/sessions.py", line 618, in send
    r = adapter.send(request, **kwargs)
  File "/usr/lib/python3.6/site-packages/requests/adapters.py", line 508, in send
    raise ConnectionError(e, request=request)
requests.exceptions.ConnectionError: HTTPSConnectionPool(host='maps.googleapis.com', port=443): Max retries exceeded with url: /maps/api/distancematrix/json?departure_time=now&destinations=unknown&mode=driving&origins=-25.4517535%2C-49.3433857&units=metric&key=AIzaSyDqHMdgfqGyEvYvke640j5BF2ejRrLOMCM (Caused by NewConnectionError('<urllib3.connection.VerifiedHTTPSConnection object at 0x74766310>: Failed to establish a new connection: [Errno -3] Try again',))

During handling of the above exception, another exception occurred:

Traceback (most recent call last):
  File "/usr/lib/python3.6/concurrent/futures/thread.py", line 56, in run
    result = self.fn(*self.args, **self.kwargs)
  File "/usr/lib/python3.6/site-packages/homeassistant/components/sensor/google_travel_time.py", line 112, in run_setup
    hass, name, api_key, origin, destination, options)
  File "/usr/lib/python3.6/site-packages/homeassistant/components/sensor/google_travel_time.py", line 147, in __init__
    self.update()
  File "/usr/lib/python3.6/site-packages/homeassistant/util/__init__.py", line 319, in wrapper
    result = method(*args, **kwargs)
  File "/usr/lib/python3.6/site-packages/homeassistant/components/sensor/google_travel_time.py", line 228, in update
    self._origin, self._destination, **options_copy)
  File "/usr/lib/python3.6/site-packages/googlemaps/client.py", line 356, in wrapper
    result = func(*args, **kwargs)
  File "/usr/lib/python3.6/site-packages/googlemaps/distance_matrix.py", line 130, in distance_matrix
    return client._request("/maps/api/distancematrix/json", params)
  File "/usr/lib/python3.6/site-packages/googlemaps/client.py", line 233, in _request
    raise googlemaps.exceptions.TransportError(e)
googlemaps.exceptions.TransportError: HTTPSConnectionPool(host='maps.googleapis.com', port=443): Max retries exceeded with url: /maps/api/distancematrix/json?departure_time=now&destinations=unknown&mode=driving&origins=-25.4517535%2C-49.3433857&units=metric&key=AIzaSyDqHMdgfqGyEvYvke640j5BF2ejRrLOMCM (Caused by NewConnectionError('<urllib3.connection.VerifiedHTTPSConnection object at 0x74766310>: Failed to establish a new connection: [Errno -3] Try again',))
2018-04-11 23:12:32 ERROR (SyncWorker_1) [homeassistant.components.sensor.command_line] Command failed: curl --data "key=trnsl.1.1.20180312T184049Z.25ec68dcb8cdd93c.e8313f4eb494259e59ca6a6efd1c03e42e81d8a6&lang=en-pt&text=Rain on Sunday and Monday, with high temperatures peaking at 26°C on Friday." https://translate.yandex.net/api/v1.5/tr.json/translate
2018-04-11 23:12:32 ERROR (MainThread) [homeassistant.core] Error doing job: Future exception was never retrieved
Traceback (most recent call last):
  File "/usr/lib/python3.6/site-packages/urllib3/connection.py", line 141, in _new_conn
    (self.host, self.port), self.timeout, **extra_kw)
  File "/usr/lib/python3.6/site-packages/urllib3/util/connection.py", line 60, in create_connection
    for res in socket.getaddrinfo(host, port, family, socket.SOCK_STREAM):
  File "/usr/lib/python3.6/socket.py", line 745, in getaddrinfo
    for res in _socket.getaddrinfo(host, port, family, type, proto, flags):
socket.gaierror: [Errno -3] Try again

During handling of the above exception, another exception occurred:

Traceback (most recent call last):
  File "/usr/lib/python3.6/site-packages/urllib3/connectionpool.py", line 601, in urlopen
    chunked=chunked)
  File "/usr/lib/python3.6/site-packages/urllib3/connectionpool.py", line 346, in _make_request
    self._validate_conn(conn)
  File "/usr/lib/python3.6/site-packages/urllib3/connectionpool.py", line 850, in _validate_conn
    conn.connect()
  File "/usr/lib/python3.6/site-packages/urllib3/connection.py", line 284, in connect
    conn = self._new_conn()
  File "/usr/lib/python3.6/site-packages/urllib3/connection.py", line 150, in _new_conn
    self, "Failed to establish a new connection: %s" % e)
urllib3.exceptions.NewConnectionError: <urllib3.connection.VerifiedHTTPSConnection object at 0x74766fb0>: Failed to establish a new connection: [Errno -3] Try again

During handling of the above exception, another exception occurred:

Traceback (most recent call last):
  File "/usr/lib/python3.6/site-packages/requests/adapters.py", line 440, in send
    timeout=timeout
  File "/usr/lib/python3.6/site-packages/urllib3/connectionpool.py", line 639, in urlopen
    _stacktrace=sys.exc_info()[2])
  File "/usr/lib/python3.6/site-packages/urllib3/util/retry.py", line 388, in increment
    raise MaxRetryError(_pool, url, error or ResponseError(cause))
urllib3.exceptions.MaxRetryError: HTTPSConnectionPool(host='maps.googleapis.com', port=443): Max retries exceeded with url: /maps/api/distancematrix/json?departure_time=now&destinations=R.+Pedro+Carlesso%2C+63+-+Cidade+Industrial%2C+Curitiba+-+PR&mode=driving&origins=-25.4517535%2C-49.3433857&units=metric&key=AIzaSyDqHMdgfqGyEvYvke640j5BF2ejRrLOMCM (Caused by NewConnectionError('<urllib3.connection.VerifiedHTTPSConnection object at 0x74766fb0>: Failed to establish a new connection: [Errno -3] Try again',))

During handling of the above exception, another exception occurred:

Traceback (most recent call last):
  File "/usr/lib/python3.6/site-packages/googlemaps/client.py", line 229, in _request
    **final_requests_kwargs)
  File "/usr/lib/python3.6/site-packages/requests/sessions.py", line 521, in get
    return self.request('GET', url, **kwargs)
  File "/usr/lib/python3.6/site-packages/requests/sessions.py", line 508, in request
    resp = self.send(prep, **send_kwargs)
  File "/usr/lib/python3.6/site-packages/requests/sessions.py", line 618, in send
    r = adapter.send(request, **kwargs)
  File "/usr/lib/python3.6/site-packages/requests/adapters.py", line 508, in send
    raise ConnectionError(e, request=request)
requests.exceptions.ConnectionError: HTTPSConnectionPool(host='maps.googleapis.com', port=443): Max retries exceeded with url: /maps/api/distancematrix/json?departure_time=now&destinations=R.+Pedro+Carlesso%2C+63+-+Cidade+Industrial%2C+Curitiba+-+PR&mode=driving&origins=-25.4517535%2C-49.3433857&units=metric&key=AIzaSyDqHMdgfqGyEvYvke640j5BF2ejRrLOMCM (Caused by NewConnectionError('<urllib3.connection.VerifiedHTTPSConnection object at 0x74766fb0>: Failed to establish a new connection: [Errno -3] Try again',))

During handling of the above exception, another exception occurred:

Traceback (most recent call last):
  File "/usr/lib/python3.6/concurrent/futures/thread.py", line 56, in run
    result = self.fn(*self.args, **self.kwargs)
  File "/usr/lib/python3.6/site-packages/homeassistant/components/sensor/google_travel_time.py", line 112, in run_setup
    hass, name, api_key, origin, destination, options)
  File "/usr/lib/python3.6/site-packages/homeassistant/components/sensor/google_travel_time.py", line 147, in __init__
    self.update()
  File "/usr/lib/python3.6/site-packages/homeassistant/util/__init__.py", line 319, in wrapper
    result = method(*args, **kwargs)
  File "/usr/lib/python3.6/site-packages/homeassistant/components/sensor/google_travel_time.py", line 228, in update
    self._origin, self._destination, **options_copy)
  File "/usr/lib/python3.6/site-packages/googlemaps/client.py", line 356, in wrapper
    result = func(*args, **kwargs)
  File "/usr/lib/python3.6/site-packages/googlemaps/distance_matrix.py", line 130, in distance_matrix
    return client._request("/maps/api/distancematrix/json", params)
  File "/usr/lib/python3.6/site-packages/googlemaps/client.py", line 233, in _request
    raise googlemaps.exceptions.TransportError(e)
googlemaps.exceptions.TransportError: HTTPSConnectionPool(host='maps.googleapis.com', port=443): Max retries exceeded with url: /maps/api/distancematrix/json?departure_time=now&destinations=R.+Pedro+Carlesso%2C+63+-+Cidade+Industrial%2C+Curitiba+-+PR&mode=driving&origins=-25.4517535%2C-49.3433857&units=metric&key=AIzaSyDqHMdgfqGyEvYvke640j5BF2ejRrLOMCM (Caused by NewConnectionError('<urllib3.connection.VerifiedHTTPSConnection object at 0x74766fb0>: Failed to establish a new connection: [Errno -3] Try again',))
2018-04-11 23:12:35 ERROR (SyncWorker_5) [homeassistant.core] Error doing job: Task was destroyed but it is pending!
2018-04-11 23:12:47 ERROR (MainThread) [homeassistant.core] Timer got out of sync. Resetting
2018-04-11 23:15:33 ERROR (SyncWorker_11) [homeassistant.components.sensor.rest] Error fetching data: <PreparedRequest [GET]>
